Workbook

Sheet analysis
A1: {=MID(CELL("filename"),SEARCH("[",CELL("filename"))+1,SEARCH("]",CELL("filename"))-SEARCH("[",CELL("filename"))-1)} -> 03 codeTables_QECC.xlsx
A3: Family Size | B3: =COUNT(AB:AB) -> 121 | C3: nMax | D3: =MAX(B68:B300) -> 123 | E3: nMin | F3: =MIN(B68:B300) -> 3 | G3: dMinSum | H3: =SUM(C68:C300) -> 1466 | M3: MaxTime | N3: =8*60*60 -> 28800
M4: Exact nMax | N4: 80 | O4: Exact Family | P4: =COUNTIFS(B68:B195,"<="&$N$4) -> 78
A5: Heuristic Methods | M5: Exact Methods
B6: m4riRW | C6: QDistRndMW | D6: QDistEvol | E6: BP-OSD | F6: GEStim | G6: CCStim | H6: UEStim | N6: Gurobi | O6: MIP-SCIP | P6: CLISAT | Q6: m4riCC | R6: Magma
A7: Result Returned | B7: =SUM(BI:BI) -> 121 | C7: =SUM(BJ:BJ) -> 121 | D7: =SUM(BK:BK) -> 121 | E7: =SUM(BL:BL) -> 121 | F7: =SUM(BM:BM) -> 9 | G7: =SUM(BN:BN) -> 11 | H7: =SUM(BO:BO) -> 47 | J7: #,##0 | M7: Result Returned | N7: =SUMIFS(BD:BD,$B:$B,"<="&$N$4) -> 78 | O7: =SUMIFS(BE:BE,$B:$B,"<="&$N$4) -> 78 | P7: =SUMIFS(BF:BF,$B:$B,"<="&$N$4) -> 78 | Q7: =SUMIFS(BG:BG,$B:$B,"<="&$N$4) -> 33 | R7: =SUMIFS(BH:BH,$B:$B,"<="&$N$4) -> 78 | S7: #,##0
A8: No Result | B8: =$B$3-B7 -> 0 | C8: =$B$3-C7 -> 0 | D8: =$B$3-D7 -> 0 | E8: =$B$3-E7 -> 0 | F8: =$B$3-F7 -> 112 | G8: =$B$3-G7 -> 110 | H8: =$B$3-H7 -> 74 | J8: #,##0 | M8: Completed < MaxTime | N8: =SUMIFS(AM:AM,$B:$B,"<="&$N$4) -> 46 | O8: =SUMIFS(AN:AN,$B:$B,"<="&$N$4) -> 40 | P8: =SUMIFS(AO:AO,$B:$B,"<="&$N$4) -> 39 | Q8: =SUMIFS(AP:AP,$B:$B,"<="&$N$4) -> 33 | R8: =SUMIFS(AQ:AQ,$B:$B,"<="&$N$4) -> 56 | S8: #,##0
A9: At lowest distance | B9: =SUM(CQ:CQ) -> 106 | C9: =SUM(CR:CR) -> 103 | D9: =SUM(CS:CS) -> 109 | E9: =SUM(CT:CT) -> 62 | F9: =SUM(CU:CU) -> 9 | G9: =SUM(CV:CV) -> 11 | H9: =SUM(CW:CW) -> 38 | J9: #,##0;; | M9: Completed > MaxTime | N9: =N7-N8 -> 32 | O9: =O7-O8 -> 38 | P9: =P7-P8 -> 39 | Q9: =Q7-Q8 -> 0 | R9: =R7-R8 -> 22 | S9: #,##0
A10: Overall Success Rate | B10: =B9/$B$3 -> 0.87603306 | C10: =C9/$B$3 -> 0.85123967 | D10: =D9/$B$3 -> 0.90082645 | E10: =E9/$B$3 -> 0.51239669 | F10: =F9/$B$3 -> 0.074380165 | G10: =G9/$B$3 -> 0.090909091 | H10: =H9/$B$3 -> 0.31404959 | J10: 0.0%;; | M10: No Result | N10: =$P$4-N7 -> 0 | O10: =$P$4-O7 -> 0 | P10: =$P$4-P7 -> 0 | Q10: =$P$4-Q7 -> 45 | R10: =$P$4-R7 -> 0 | S10: #,##0
A11: Total Time (s) | B11: =SUM(DH:DH) -> 208.53508 | C11: =SUM(DI:DI) -> 3572.9461 | D11: =SUM(DJ:DJ) -> 1312.9149 | E11: =SUM(DK:DK) -> 63088.397 | F11: =SUM(DL:DL) -> 3.5414486 | G11: =SUM(DM:DM) -> 3.8452323 | H11: =SUM(DN:DN) -> 62.377662 | J11: 0.0E+00;; | M11: At lowest distance | N11: =SUMIFS(CL:CL,$B:$B,"<="&$N$4) -> 67 | O11: =SUMIFS(CM:CM,$B:$B,"<="&$N$4) -> 67 | P11: =SUMIFS(CN:CN,$B:$B,"<="&$N$4) -> 49 | Q11: =SUMIFS(CO:CO,$B:$B,"<="&$N$4) -> 33 | R11: =SUMIFS(CP:CP,$B:$B,"<="&$N$4) -> 77 | S11: #,##0
A12: Trials | C12: =SUM(FH:FH) -> 1210000 | D12: =SUM(FI:FI) -> 1210000 | E12: =SUM(FJ:FJ) -> 1210000 | F12: =SUM(FK:FK) -> 121 | G12: =SUM(FL:FL) -> 121 | H12: =SUM(FM:FM) -> 935 | J12: #,##0 | M12: Overall success rate | N12: =N11/$P$4 -> 0.85897436 | O12: =O11/$P$4 -> 0.85897436 | P12: =P11/$P$4 -> 0.62820513 | Q12: =Q11/$P$4 -> 0.42307692 | R12: =R11/$P$4 -> 0.98717949 | S12: 0.0%;;
A13: Trials at lowest distance | C13: =SUM(DZ:DZ) -> 322477 | D13: =SUM(EA:EA) -> 543925 | E13: =SUM(EB:EB) -> 242798 | F13: =SUM(EC:EC) -> 9 | G13: =SUM(ED:ED) -> 11 | H13: =SUM(EE:EE) -> 74 | J13: #,##0;; | M13: Total Time | N13: =SUMIFS(DC:DC,$B:$B,"<="&$N$4)+N16*$N$3 -> 978906.75 | O13: =SUMIFS(DD:DD,$B:$B,"<="&$N$4)+O16*$N$3 -> 1173723.5 | P13: =SUMIFS(DE:DE,$B:$B,"<="&$N$4)+P16*$N$3 -> 1221977.7 | Q13: =SUMIFS(DF:DF,$B:$B,"<="&$N$4)+Q16*$N$3 -> 1325022 | R13: =SUMIFS(DG:DG,$B:$B,"<="&$N$4)+R16*$N$3 -> 692540.08 | S13: 0.0E+00;;
A14: Trial Success Rate | C14: =C13/C12 -> 0.26650992 | D14: =D13/D12 -> 0.44952479 | E14: =E13/E12 -> 0.2006595 | F14: =F13/F12 -> 0.074380165 | G14: =G13/G12 -> 0.090909091 | H14: =H13/H12 -> 0.079144385 | J14: 0.0%;; | M14: Time/Trial | N14: =N13/$P$4 -> 12550.087 | O14: =O13/$P$4 -> 15047.737 | P14: =P13/$P$4 -> 15666.381 | Q14: =Q13/$P$4 -> 16987.461 | R14: =R13/$P$4 -> 8878.7189 | S14: 0.0E+00;;
A15: Time/Trial | C15: =IF(C12,C11/C12,"") -> 0.002952848 | D15: =IF(D12,D11/D12,"") -> 0.0010850537 | E15: =IF(E12,E11/E12,"") -> 0.052139171 | F15: =IF(F12,F11/F12,"") -> 0.02926817 | G15: =IF(G12,G11/G12,"") -> 0.031778779 | H15: =IF(H12,H11/H12,"") -> 0.066714077 | J15: 0.0E+00;; | M15: Time/Successful Trial | N15: =IF(N11,N13/N11,"") -> 14610.549 | O15: =IF(O11,O13/O11,"") -> 17518.261 | P15: =IF(P11,P13/P11,"") -> 24938.321 | Q15: =IF(Q11,Q13/Q11,"") -> 40152.182 | R15: =IF(R11,R13/R11,"") -> 8994.027 | S15: 0.0E+00;; | U15: =IF(U12,U14/U12,"")
A16: Time/Successful Trial | C16: =IF(C13,C11/C13,"") -> 0.011079693 | D16: =IF(D13,D11/D13,"") -> 0.0024137794 | E16: =IF(E13,E11/E13,"") -> 0.25983903 | F16: =IF(F13,F11/F13,"") -> 0.39349429 | G16: =IF(G13,G11/G13,"") -> 0.34956657 | H16: =IF(H13,H11/H13,"") -> 0.84294138 | J16: 0.0E+00;; | M16: not completed | N16: =COUNTIFS(DC:DC,"=0",$B:$B,"<="&$N$4) -> 0 | O16: =COUNTIFS(DD:DD,"=0",$B:$B,"<="&$N$4) -> 0 | P16: =COUNTIFS(DE:DE,"=0",$B:$B,"<="&$N$4) -> 0 | Q16: =COUNTIFS(DF:DF,"=0",$B:$B,"<="&$N$4) -> 0 | R16: =COUNTIFS(DG:DG,"=0",$B:$B,"<="&$N$4) -> 0
A17: not completed | B17: =COUNTIFS(DH:DH,"=0") -> 0 | C17: =COUNTIFS(DI:DI,"=0") -> 0 | D17: =COUNTIFS(DJ:DJ,"=0") -> 0 | E17: =COUNTIFS(DK:DK,"=0") -> 0 | F17: =COUNTIFS(DL:DL,"=0") -> 0 | G17: =COUNTIFS(DM:DM,"=0") -> 0 | H17: =COUNTIFS(DN:DN,"=0") -> 0 | M17: nMax completed | N17: =_xlfn.MAXIFS($B67:$B267,DC67:DC267,"<>0",$B67:$B267,"<="&$N$4) -> 80 | O17: =_xlfn.MAXIFS($B67:$B267,DD67:DD267,"<>0",$B67:$B267,"<="&$N$4) -> 80 | P17: =_xlfn.MAXIFS($B67:$B267,DE67:DE267,"<>0",$B67:$B267,"<="&$N$4) -> 80 | Q17: =_xlfn.MAXIFS($B67:$B267,DF67:DF267,"<>0",$B67:$B267,"<="&$N$4) -> 80 | R17: =_xlfn.MAXIFS($B67:$B267,DG67:DG267,"<>0",$B67:$B267,"<="&$N$4) -> 80
A18: Avg Delta d | B18: =(SUM(BZ68:BZ300)-$H$3)/$H$3 -> 0.018417462 | C18: =(SUM(CA68:CA300)-$H$3)/$H$3 -> 0.022510232 | D18: =(SUM(CB68:CB300)-$H$3)/$H$3 -> 0.010914052 | E18: =(SUM(CC68:CC300)-$H$3)/$H$3 -> 0.1377899 | F18: =(SUM(CD68:CD300)-$H$3)/$H$3 -> 4.1705321 | G18: =(SUM(CE68:CE300)-$H$3)/$H$3 -> 4.1548431 | H18: =(SUM(CF68:CF300)-$H$3)/$H$3 -> 3.5675307
A19: Chart Dataset: | B19: QDistRndMW
A21: Exact - Processing Time/Succ Trial | E21: Heuristic - Processing Time/Succ Trial | J21: Heuristic - Success Rate per Trial | P21: Heuristic - Average Delta d
FX34: =IF(FU34,FT34/FU34,"")
FX35: =IF(FU35,FT35/FU35,"")
FX36: =IF(FU36,FT36/FU36,"")
FX37: =IF(FU37,FT37/FU37,"")
FX38: =IF(FU38,FT38/FU38,"")
A43: \begin{center} | M43: \begin{center}
A44: \begin{tabular}{ |l| | B44: r| | C44: r| | D44: r| | E44: r| | F44: r| | G44: r| | H44: r| | I44: } | J44: \hline | M44: \begin{tabular}{ |l| | N44: r| | O44: r| | P44: r| | Q44: r| | R44: r| | S44: } | T44: \hline
A45: =A2&" &" -> & | B45: ="\textbf{"&B6&"}"&IF(C45="\\",""," &") -> \textbf{m4riRW} & | C45: ="\textbf{"&C6&"}"&IF(D45="\\",""," &") -> \textbf{QDistRndMW} & | D45: ="\textbf{"&D6&"}"&IF(E45="\\",""," &") -> \textbf{QDistEvol} & | E45: ="\textbf{"&E6&"}"&IF(F45="\\",""," &") -> \textbf{BP-OSD} & | F45: ="\textbf{"&F6&"}"&IF(G45="\\",""," &") -> \textbf{GEStim} & | G45: ="\textbf{"&G6&"}"&IF(H45="\\",""," &") -> \textbf{CCStim} & | H45: ="\textbf{"&H6&"}"&IF(I45="\\",""," &") -> \textbf{UEStim} | I45: \\ | J45: \hline | M45: =M2&" &" -> & | N45: ="\textbf{"&N6&"}"&IF(O45="\\",""," &") -> \textbf{Gurobi} & | O45: ="\textbf{"&O6&"}"&IF(P45="\\",""," &") -> \textbf{MIP-SCIP} & | P45: ="\textbf{"&P6&"}"&IF(Q45="\\",""," &") -> \textbf{CLISAT} & | Q45: ="\textbf{"&Q6&"}"&IF(R45="\\",""," &") -> \textbf{m4riCC} & | R45: ="\textbf{"&R6&"}"&IF(S45="\\",""," &") -> \textbf{Magma} | S45: \\ | T45: \hline
A46: ="\textbf{"&A7&"} &" -> \textbf{Result Returned} & | B46: =SUBSTITUTE(TEXT(B7,$J7)&IF(C46="\\",""," &"),"%","\%") -> 121 & | C46: =SUBSTITUTE(TEXT(C7,$J7)&IF(D46="\\",""," &"),"%","\%") -> 121 & | D46: =SUBSTITUTE(TEXT(D7,$J7)&IF(E46="\\",""," &"),"%","\%") -> 121 & | E46: =SUBSTITUTE(TEXT(E7,$J7)&IF(F46="\\",""," &"),"%","\%") -> 121 & | F46: =SUBSTITUTE(TEXT(F7,$J7)&IF(G46="\\",""," &"),"%","\%") -> 9 & | G46: =SUBSTITUTE(TEXT(G7,$J7)&IF(H46="\\",""," &"),"%","\%") -> 11 & | H46: =SUBSTITUTE(TEXT(H7,$J7)&IF(I46="\\",""," &"),"%","\%") -> 47 | I46: \\ | M46: ="\textbf{"&M7&"} &" -> \textbf{Result Returned} & | N46: =SUBSTITUTE(TEXT(N7,$S7)&IF(O46="\\",""," &"),"%","\%") -> 78 & | O46: =SUBSTITUTE(TEXT(O7,$S7)&IF(P46="\\",""," &"),"%","\%") -> 78 & | P46: =SUBSTITUTE(TEXT(P7,$S7)&IF(Q46="\\",""," &"),"%","\%") -> 78 & | Q46: =SUBSTITUTE(TEXT(Q7,$S7)&IF(R46="\\",""," &"),"%","\%") -> 33 & | R46: =SUBSTITUTE(TEXT(R7,$S7)&IF(S46="\\",""," &"),"%","\%") -> 78 | S46: \\
A47: ="\textbf{"&A8&"} &" -> \textbf{No Result} & | B47: =SUBSTITUTE(TEXT(B8,$J8)&IF(C47="\\",""," &"),"%","\%") -> 0 & | C47: =SUBSTITUTE(TEXT(C8,$J8)&IF(D47="\\",""," &"),"%","\%") -> 0 & | D47: =SUBSTITUTE(TEXT(D8,$J8)&IF(E47="\\",""," &"),"%","\%") -> 0 & | E47: =SUBSTITUTE(TEXT(E8,$J8)&IF(F47="\\",""," &"),"%","\%") -> 0 & | F47: =SUBSTITUTE(TEXT(F8,$J8)&IF(G47="\\",""," &"),"%","\%") -> 112 & | G47: =SUBSTITUTE(TEXT(G8,$J8)&IF(H47="\\",""," &"),"%","\%") -> 110 & | H47: =SUBSTITUTE(TEXT(H8,$J8)&IF(I47="\\",""," &"),"%","\%") -> 74 | I47: \\ | M47: ="\textbf{"&M8&"} &" -> \textbf{Completed < MaxTime} & | N47: =SUBSTITUTE(TEXT(N8,$S8)&IF(O47="\\",""," &"),"%","\%") -> 46 & | O47: =SUBSTITUTE(TEXT(O8,$S8)&IF(P47="\\",""," &"),"%","\%") -> 40 & | P47: =SUBSTITUTE(TEXT(P8,$S8)&IF(Q47="\\",""," &"),"%","\%") -> 39 & | Q47: =SUBSTITUTE(TEXT(Q8,$S8)&IF(R47="\\",""," &"),"%","\%") -> 33 & | R47: =SUBSTITUTE(TEXT(R8,$S8)&IF(S47="\\",""," &"),"%","\%") -> 56 | S47: \\
A48: ="\textbf{"&A9&"} &" -> \textbf{At lowest distance} & | B48: =SUBSTITUTE(TEXT(B9,$J9)&IF(C48="\\",""," &"),"%","\%") -> 106 & | C48: =SUBSTITUTE(TEXT(C9,$J9)&IF(D48="\\",""," &"),"%","\%") -> 103 & | D48: =SUBSTITUTE(TEXT(D9,$J9)&IF(E48="\\",""," &"),"%","\%") -> 109 & | E48: =SUBSTITUTE(TEXT(E9,$J9)&IF(F48="\\",""," &"),"%","\%") -> 62 & | F48: =SUBSTITUTE(TEXT(F9,$J9)&IF(G48="\\",""," &"),"%","\%") -> 9 & | G48: =SUBSTITUTE(TEXT(G9,$J9)&IF(H48="\\",""," &"),"%","\%") -> 11 & | H48: =SUBSTITUTE(TEXT(H9,$J9)&IF(I48="\\",""," &"),"%","\%") -> 38 | I48: \\ | M48: ="\textbf{"&M9&"} &" -> \textbf{Completed > MaxTime} & | N48: =SUBSTITUTE(TEXT(N9,$S9)&IF(O48="\\",""," &"),"%","\%") -> 32 & | O48: =SUBSTITUTE(TEXT(O9,$S9)&IF(P48="\\",""," &"),"%","\%") -> 38 & | P48: =SUBSTITUTE(TEXT(P9,$S9)&IF(Q48="\\",""," &"),"%","\%") -> 39 & | Q48: =SUBSTITUTE(TEXT(Q9,$S9)&IF(R48="\\",""," &"),"%","\%") -> 0 & | R48: =SUBSTITUTE(TEXT(R9,$S9)&IF(S48="\\",""," &"),"%","\%") -> 22 | S48: \\
A49: ="\textbf{"&A10&"} &" -> \textbf{Overall Success Rate} & | B49: =SUBSTITUTE(TEXT(B10,$J10)&IF(C49="\\",""," &"),"%","\%") -> 87.6\% & | C49: =SUBSTITUTE(TEXT(C10,$J10)&IF(D49="\\",""," &"),"%","\%") -> 85.1\% & | D49: =SUBSTITUTE(TEXT(D10,$J10)&IF(E49="\\",""," &"),"%","\%") -> 90.1\% & | E49: =SUBSTITUTE(TEXT(E10,$J10)&IF(F49="\\",""," &"),"%","\%") -> 51.2\% & | F49: =SUBSTITUTE(TEXT(F10,$J10)&IF(G49="\\",""," &"),"%","\%") -> 7.4\% & | G49: =SUBSTITUTE(TEXT(G10,$J10)&IF(H49="\\",""," &"),"%","\%") -> 9.1\% & | H49: =SUBSTITUTE(TEXT(H10,$J10)&IF(I49="\\",""," &"),"%","\%") -> 31.4\% | I49: \\ | J49: \hline | M49: ="\textbf{"&M10&"} &" -> \textbf{No Result} & | N49: =SUBSTITUTE(TEXT(N10,$S10)&IF(O49="\\",""," &"),"%","\%") -> 0 & | O49: =SUBSTITUTE(TEXT(O10,$S10)&IF(P49="\\",""," &"),"%","\%") -> 0 & | P49: =SUBSTITUTE(TEXT(P10,$S10)&IF(Q49="\\",""," &"),"%","\%") -> 0 & | Q49: =SUBSTITUTE(TEXT(Q10,$S10)&IF(R49="\\",""," &"),"%","\%") -> 45 & | R49: =SUBSTITUTE(TEXT(R10,$S10)&IF(S49="\\",""," &"),"%","\%") -> 0 | S49: \\
A50: ="\textbf{"&A11&"} &" -> \textbf{Total Time (s)} & | B50: =SUBSTITUTE(TEXT(B11,$J11)&IF(C50="\\",""," &"),"%","\%") -> 2.1E+02 & | C50: =SUBSTITUTE(TEXT(C11,$J11)&IF(D50="\\",""," &"),"%","\%") -> 3.6E+03 & | D50: =SUBSTITUTE(TEXT(D11,$J11)&IF(E50="\\",""," &"),"%","\%") -> 1.3E+03 & | E50: =SUBSTITUTE(TEXT(E11,$J11)&IF(F50="\\",""," &"),"%","\%") -> 6.3E+04 & | F50: =SUBSTITUTE(TEXT(F11,$J11)&IF(G50="\\",""," &"),"%","\%") -> 3.5E+00 & | G50: =SUBSTITUTE(TEXT(G11,$J11)&IF(H50="\\",""," &"),"%","\%") -> 3.8E+00 & | H50: =SUBSTITUTE(TEXT(H11,$J11)&IF(I50="\\",""," &"),"%","\%") -> 6.2E+01 | I50: \\ | M50: ="\textbf{"&M11&"} &" -> \textbf{At lowest distance} & | N50: =SUBSTITUTE(TEXT(N11,$S11)&IF(O50="\\",""," &"),"%","\%") -> 67 & | O50: =SUBSTITUTE(TEXT(O11,$S11)&IF(P50="\\",""," &"),"%","\%") -> 67 & | P50: =SUBSTITUTE(TEXT(P11,$S11)&IF(Q50="\\",""," &"),"%","\%") -> 49 & | Q50: =SUBSTITUTE(TEXT(Q11,$S11)&IF(R50="\\",""," &"),"%","\%") -> 33 & | R50: =SUBSTITUTE(TEXT(R11,$S11)&IF(S50="\\",""," &"),"%","\%") -> 77 | S50: \\
A51: ="\textbf{"&A12&"} &" -> \textbf{Trials} & | B51: =SUBSTITUTE(TEXT(B12,$J12)&IF(C51="\\",""," &"),"%","\%") -> 0 & | C51: =SUBSTITUTE(TEXT(C12,$J12)&IF(D51="\\",""," &"),"%","\%") -> 1,210,000 & | D51: =SUBSTITUTE(TEXT(D12,$J12)&IF(E51="\\",""," &"),"%","\%") -> 1,210,000 & | E51: =SUBSTITUTE(TEXT(E12,$J12)&IF(F51="\\",""," &"),"%","\%") -> 1,210,000 & | F51: =SUBSTITUTE(TEXT(F12,$J12)&IF(G51="\\",""," &"),"%","\%") -> 121 & | G51: =SUBSTITUTE(TEXT(G12,$J12)&IF(H51="\\",""," &"),"%","\%") -> 121 & | H51: =SUBSTITUTE(TEXT(H12,$J12)&IF(I51="\\",""," &"),"%","\%") -> 935 | I51: \\ | M51: ="\textbf{"&M12&"} &" -> \textbf{Overall success rate} & | N51: =SUBSTITUTE(TEXT(N12,$S12)&IF(O51="\\",""," &"),"%","\%") -> 85.9\% & | O51: =SUBSTITUTE(TEXT(O12,$S12)&IF(P51="\\",""," &"),"%","\%") -> 85.9\% & | P51: =SUBSTITUTE(TEXT(P12,$S12)&IF(Q51="\\",""," &"),"%","\%") -> 62.8\% & | Q51: =SUBSTITUTE(TEXT(Q12,$S12)&IF(R51="\\",""," &"),"%","\%") -> 42.3\% & | R51: =SUBSTITUTE(TEXT(R12,$S12)&IF(S51="\\",""," &"),"%","\%") -> 98.7\% | S51: \\ | T51: \hline
A52: ="\textbf{"&A13&"} &" -> \textbf{Trials at lowest distance} & | B52: =SUBSTITUTE(TEXT(B13,$J13)&IF(C52="\\",""," &"),"%","\%") -> & | C52: =SUBSTITUTE(TEXT(C13,$J13)&IF(D52="\\",""," &"),"%","\%") -> 322,477 & | D52: =SUBSTITUTE(TEXT(D13,$J13)&IF(E52="\\",""," &"),"%","\%") -> 543,925 & | E52: =SUBSTITUTE(TEXT(E13,$J13)&IF(F52="\\",""," &"),"%","\%") -> 242,798 & | F52: =SUBSTITUTE(TEXT(F13,$J13)&IF(G52="\\",""," &"),"%","\%") -> 9 & | G52: =SUBSTITUTE(TEXT(G13,$J13)&IF(H52="\\",""," &"),"%","\%") -> 11 & | H52: =SUBSTITUTE(TEXT(H13,$J13)&IF(I52="\\",""," &"),"%","\%") -> 74 | I52: \\ | M52: ="\textbf{"&M13&"} &" -> \textbf{Total Time} & | N52: =SUBSTITUTE(TEXT(N13,$S13)&IF(O52="\\",""," &"),"%","\%") -> 9.8E+05 & | O52: =SUBSTITUTE(TEXT(O13,$S13)&IF(P52="\\",""," &"),"%","\%") -> 1.2E+06 & | P52: =SUBSTITUTE(TEXT(P13,$S13)&IF(Q52="\\",""," &"),"%","\%") -> 1.2E+06 & | Q52: =SUBSTITUTE(TEXT(Q13,$S13)&IF(R52="\\",""," &"),"%","\%") -> 1.3E+06 & | R52: =SUBSTITUTE(TEXT(R13,$S13)&IF(S52="\\",""," &"),"%","\%") -> 6.9E+05 | S52: \\
A53: ="\textbf{"&A14&"} &" -> \textbf{Trial Success Rate} & | B53: =SUBSTITUTE(TEXT(B14,$J14)&IF(C53="\\",""," &"),"%","\%") -> & | C53: =SUBSTITUTE(TEXT(C14,$J14)&IF(D53="\\",""," &"),"%","\%") -> 26.7\% & | D53: =SUBSTITUTE(TEXT(D14,$J14)&IF(E53="\\",""," &"),"%","\%") -> 45.0\% & | E53: =SUBSTITUTE(TEXT(E14,$J14)&IF(F53="\\",""," &"),"%","\%") -> 20.1\% & | F53: =SUBSTITUTE(TEXT(F14,$J14)&IF(G53="\\",""," &"),"%","\%") -> 7.4\% & | G53: =SUBSTITUTE(TEXT(G14,$J14)&IF(H53="\\",""," &"),"%","\%") -> 9.1\% & | H53: =SUBSTITUTE(TEXT(H14,$J14)&IF(I53="\\",""," &"),"%","\%") -> 7.9\% | I53: \\ | M53: ="\textbf{"&M14&"} &" -> \textbf{Time/Trial} & | N53: =SUBSTITUTE(TEXT(N14,$S14)&IF(O53="\\",""," &"),"%","\%") -> 1.3E+04 & | O53: =SUBSTITUTE(TEXT(O14,$S14)&IF(P53="\\",""," &"),"%","\%") -> 1.5E+04 & | P53: =SUBSTITUTE(TEXT(P14,$S14)&IF(Q53="\\",""," &"),"%","\%") -> 1.6E+04 & | Q53: =SUBSTITUTE(TEXT(Q14,$S14)&IF(R53="\\",""," &"),"%","\%") -> 1.7E+04 & | R53: =SUBSTITUTE(TEXT(R14,$S14)&IF(S53="\\",""," &"),"%","\%") -> 8.9E+03 | S53: \\
A54: ="\textbf{"&A15&"} &" -> \textbf{Time/Trial} & | B54: =SUBSTITUTE(TEXT(B15,$J15)&IF(C54="\\",""," &"),"%","\%") -> & | C54: =SUBSTITUTE(TEXT(C15,$J15)&IF(D54="\\",""," &"),"%","\%") -> 3.0E-03 & | D54: =SUBSTITUTE(TEXT(D15,$J15)&IF(E54="\\",""," &"),"%","\%") -> 1.1E-03 & | E54: =SUBSTITUTE(TEXT(E15,$J15)&IF(F54="\\",""," &"),"%","\%") -> 5.2E-02 & | F54: =SUBSTITUTE(TEXT(F15,$J15)&IF(G54="\\",""," &"),"%","\%") -> 2.9E-02 & | G54: =SUBSTITUTE(TEXT(G15,$J15)&IF(H54="\\",""," &"),"%","\%") -> 3.2E-02 & | H54: =SUBSTITUTE(TEXT(H15,$J15)&IF(I54="\\",""," &"),"%","\%") -> 6.7E-02 | I54: \\ | M54: ="\textbf{"&M15&"} &" -> \textbf{Time/Successful Trial} & | N54: =SUBSTITUTE(TEXT(N15,$S15)&IF(O54="\\",""," &"),"%","\%") -> 1.5E+04 & | O54: =SUBSTITUTE(TEXT(O15,$S15)&IF(P54="\\",""," &"),"%","\%") -> 1.8E+04 & | P54: =SUBSTITUTE(TEXT(P15,$S15)&IF(Q54="\\",""," &"),"%","\%") -> 2.5E+04 & | Q54: =SUBSTITUTE(TEXT(Q15,$S15)&IF(R54="\\",""," &"),"%","\%") -> 4.0E+04 & | R54: =SUBSTITUTE(TEXT(R15,$S15)&IF(S54="\\",""," &"),"%","\%") -> 9.0E+03 | S54: \\ | T54: \hline
A55: ="\textbf{"&A16&"} &" -> \textbf{Time/Successful Trial} & | B55: =SUBSTITUTE(TEXT(B16,$J16)&IF(C55="\\",""," &"),"%","\%") -> & | C55: =SUBSTITUTE(TEXT(C16,$J16)&IF(D55="\\",""," &"),"%","\%") -> 1.1E-02 & | D55: =SUBSTITUTE(TEXT(D16,$J16)&IF(E55="\\",""," &"),"%","\%") -> 2.4E-03 & | E55: =SUBSTITUTE(TEXT(E16,$J16)&IF(F55="\\",""," &"),"%","\%") -> 2.6E-01 & | F55: =SUBSTITUTE(TEXT(F16,$J16)&IF(G55="\\",""," &"),"%","\%") -> 3.9E-01 & | G55: =SUBSTITUTE(TEXT(G16,$J16)&IF(H55="\\",""," &"),"%","\%") -> 3.5E-01 & | H55: =SUBSTITUTE(TEXT(H16,$J16)&IF(I55="\\",""," &"),"%","\%") -> 8.4E-01 | I55: \\ | J55: \hline | M55: \end{tabular}
A56: \end{tabular} | M56: \end{center}
A57: \end{center}
A64: Offset | B64: =MATCH("name",INDIRECT($A$67&"!a:a"),) -> 27
...

Sheet best
A1: Reported distance - codetables.de
A26: #########################################
A27: name | B27: n | C27: k | D27: d
A28: [[3,1,1]] | B28: 3 | C28: 1 | D28: 1
A29: [[4,1,2]] | B29: 4 | C29: 1 | D29: 2
A30: [[5,1,3]] | B30: 5 | C30: 1 | D30: 3
A31: [[6,1,3]] | B31: 6 | C31: 1 | D31: 3
A32: [[7,1,3]] | B32: 7 | C32: 1 | D32: 3
A33: [[8,1,3]] | B33: 8 | C33: 1 | D33: 3
A34: [[9,1,3]] | B34: 9 | C34: 1 | D34: 3
A35: [[10,1,4]] | B35: 10 | C35: 1 | D35: 4
A36: [[11,1,5]] | B36: 11 | C36: 1 | D36: 5
A37: [[12,6,3]] | B37: 12 | C37: 6 | D37: 3
A38: [[13,6,3]] | B38: 13 | C38: 6 | D38: 3
A39: [[14,2,5]] | B39: 14 | C39: 2 | D39: 5
... A148: [[123,38,15]] | B148: 123 | C148: 38 | D148: 15

Sheet magma
A1: runMode: serial
A2: maxCount: 10000
A3: repeat: 1
A4: dataset: codeTables
A5: datafile: QECC_sample.txt
A6: method: magmaMinWeight
A7: ignoreTrivialCodes: 1
A8: resume: 0
A9: iterCount: 10000
A10: maxTime: 28800
A11: nThreads: 1
A12: verbose: False
... A26: #########################################
A27: name | B27: n | C27: k | D27: d | E27: delta d | F27: Time | G27: R | H27: T | I27: Progress
A28: [[3,1,1]] | B28: 3 | C28: 1 | D28: 1 | E28: 0 | F28: 0.8679157500009751 | G28: 1 | H28: 1 | I28: Magma V2.28-26 Tue Dec 30 2025 12:10:36 on Marks-MacBook-Air-2 [Seed = \n672301251]\nType ? for help. Type <Ctrl>-D to quit.\n[0 1 0 0 0 0]\n[0 0 1 0 0 0]\n[[3, 1]] quantum code over GF(2^2), stabilised by:\n[ 0 1 0]\n[ 0 0 1]\nCalculating the Weight Distribution for [3, 4] linear code, #R = 4\nNumber of threads: 1\nCalculating the Weight Distribution for [3, 2] linear code, #R = 4\nNumber of threads: 1\nDoing quick check for code being known to be MDS:\nCode is not known to be MDS\nCalculating the Weight Distribution for [3, 4] linear code, #R = 4\nNumber of threads: 1\nDoing quick check for code being known to be MDS:\nCode is not known to be MDS\nUsing the Dual\n1\n\nTotal time: 0.010 seconds, Total memory usage: 32.09MB\n
A29: [[4,1,2]] | B29: 4 | C29: 1 | D29: 2 | E29: 0 | F29: 0.057046084009925835 | G29: 1 | H29: 1 | I29: Magma V2.28-26 Tue Dec 30 2025 12:10:36 on Marks-MacBook-Air-2 [Seed = \n3555294009]\nType ? for help. Type <Ctrl>-D to quit.\n[1 0 1 0 0 0 0 0]\n[0 1 0 1 0 0 0 0]\n[0 0 0 0 1 1 1 1]\n[[4, 1]] quantum code over GF(2^2), stabilised by:\n[ 1 0 1 0]\n[ $.1 $.1 $.1 $.1]\n[ 0 1 0 1]\nCalculating the Weight Distribution for [4, 5] linear code, #R = 4\nNumber of threads: 1\nCalculating the Weight Distribution for [4, 3] linear code, #R = 4\nNumber of threads: 1\nDoing quick check for code being known to be MDS:\nCode is not known to be MDS\nCalculating the Weight Distribution for [4, 5] linear code, #R = 4\nNumber of threads: 1\nDoing quick check for code being known to be MDS:\nCode is not known to be MDS\nUsing the Dual\n2\n\nTotal time: 0.019 seconds, Total memory usage: 32.09MB\n
A30: [[5,1,3]] | B30: 5 | C30: 1 | D30: 3 | E30: 0 | F30: 0.057239332993049175 | G30: 1 | H30: 1 | I30: Magma V2.28-26 Tue Dec 30 2025 12:10:36 on Marks-MacBook-Air-2 [Seed = \n3722933559]\nType ? for help. Type <Ctrl>-D to quit.\n[1 0 0 1 1 1 0 1 0 1]\n[0 1 0 0 1 1 0 0 1 1]\n[0 0 1 1 0 1 0 0 1 1]\n[0 0 0 0 0 0 1 1 1 1]\n[[5, 1]] quantum code over GF(2^2), stabilised by:\n[ 1 0 $.1^2 $.1 1]\n[ $.1 0 1 $.1^2 $.1]\n[ 0 1 1 1 1]\n[ 0 $.1 $.1 $.1 $.1]\nCalculating the Weight Distribution for [5, 6] linear code, #R = 4\nNumber of threads: 1\nCalculating the Weight Distribution for [5, 4] linear code, #R = 4\nNumber of threads: 1\nDoing quick check for code being known to be MDS:\nCode is not known to be MDS\nCalculating the Weight Distribution for [5, 2] linear code, #R = 4\nNumber of threads: 1\nDoing quick check for code being known to be MDS:\nCode is not known to be MDS\nCalculating the Weight Distribution for [5, 6] linear code, #R = 4\nNumber of threads: 1\nDoing quick check for code being known to be MDS:\nCode is not known to be MDS\nUsing the Dual\n3\n\nTotal time: 0.019 seconds, Total memory usage: 32.09MB\n
A31: [[6,1,3]] | B31: 6 | C31: 1 | D31: 3 | E31: 0 | F31: 0.057163917 | G31: 1 | H31: 1 | I31: Magma V2.28-26 Tue Dec 30 2025 12:10:36 on Marks-MacBook-Air-2 [Seed = \n3355275053]\nType ? for help. Type <Ctrl>-D to quit.\n[1 0 0 1 1 0 1 0 1 0 1 0]\n[0 1 0 0 1 0 1 0 0 1 1 0]\n[0 0 1 1 0 0 1 0 0 1 1 0]\n[0 0 0 0 0 1 0 0 0 0 0 0]\n[0 0 0 0 0 0 0 1 1 1 1 0]\n[[6, 1]] quantum code over GF(2^2), stabilised by:\n[ 1 0 $.1^2 $.1 1 0]\n[ $.1 0 1 $.1^2 $.1 0]\n[ 0 1 1 1 1 0]\n[ 0 $.1 $.1 $.1 $.1 0]\n[ 0 0 0 0 0 1]\nQuantum GF(2)-Additive code over GF(4) of length 6 with 7 generators.\nLower Bound: 1, Upper Bound: 4\nConstructed 2 distinct generator matrices\nTotal Ranks: 4 4 \nRelative Ranks: 4 2 \n(4 4 4 2 )\n(4 4 4 2 )\nTime Taken: 0.00\nStarting search for low weight codewords... (reset timings)\nEnumerating using 1 generator at a time:\n New codeword identified of weight 3, time 0.00\n Impurity detected of weight 1, time 0.00\n Discarding non-contributing rank 2 matrix\n New Total Ranks: 4 \n New Relative Ranks: 4 \n Completed Matrix 1: lower = 2, upper = 3. Elapsed: 0.00s\nTermination predicted with 2 generators at matrix 1\nEnumerating using 2 generators at a time:\n Completed Matrix 1: lower = 3, upper = 3. Elapsed: 0.00s\nComputation complete \nFinal Results: lower = 3, upper = 3,\nTotal CPU time: 0.00, real time: 0.004\n3\n\nTotal time: 0.010 seconds, Total memory usage: 32.09MB\n
A32: [[7,1,3]] | B32: 7 | C32: 1 | D32: 3 | E32: 0 | F32: 0.055149333 | G32: 1 | H32: 1 | I32: Magma V2.28-26 Tue Dec 30 2025 12:10:36 on Marks-MacBook-Air-2 [Seed = \n3254479147]\nType ? for help. Type <Ctrl>-D to quit.\n[1 0 0 1 0 1 1 0 0 0 0 0 0 0]\n[0 1 0 1 1 1 0 0 0 0 0 0 0 0]\n[0 0 1 0 1 1 1 0 0 0 0 0 0 0]\n[0 0 0 0 0 0 0 1 0 0 1 0 1 1]\n[0 0 0 0 0 0 0 0 1 0 1 1 1 0]\n[0 0 0 0 0 0 0 0 0 1 0 1 1 1]\n[[7, 1]] quantum code over GF(2^2), stabilised by:\n[ 1 0 0 1 0 1 1]\n[ $.1 0 0 $.1 0 $.1 $.1]\n[ 0 1 0 1 1 1 0]\n[ 0 $.1 0 $.1 $.1 $.1 0]\n[ 0 0 1 0 1 1 1]\n[ 0 0 $.1 0 $.1 $.1 $.1]\nQuantum GF(2)-Additive code over GF(4) of length 7 with 8 generators.\nLower Bound: 1, Upper Bound: 4\nBCHBound gives the lower bound = 3\nConstructed 2 distinct generator matrices\nTotal Ranks: 4 4 \nRelative Ranks: 4 3 \n(4 4 4 4 )\n(4 4 4 4 )\nTime Taken: 0.00\nStarting search for low weight codewords... (reset timings)\nEnumerating using 1 generator at a time:\n New codeword identified of weight 3, time 0.00\nComputation complete \nFinal Results: lower = 3, upper = 3,\nTotal CPU time: 0.00, real time: 0.004\n3\n\nTotal time: 0.010 seconds, Total memory usage: 32.09MB\n
A33: [[8,1,3]] | B33: 8 | C33: 1 | D33: 3 | E33: 0 | F33: 0.0527205 | G33: 1 | H33: 1 | I33: Magma V2.28-26 Tue Dec 30 2025 12:10:36 on Marks-MacBook-Air-2 [Seed = \n3421594401]\nType ? for help. Type <Ctrl>-D to quit.\n[1 0 0 1 1 0 0 0 1 0 1 0 1 0 0 0]\n[0 1 0 0 1 0 0 0 1 0 0 1 1 0 0 0]\n[0 0 1 1 0 0 0 0 1 0 0 1 1 0 0 0]\n[0 0 0 0 0 1 0 0 0 0 0 0 0 0 0 0]\n[0 0 0 0 0 0 1 0 0 0 0 0 0 0 0 0]\n[0 0 0 0 0 0 0 1 0 0 0 0 0 0 0 0]\n[0 0 0 0 0 0 0 0 0 1 1 1 1 0 0 0]\n[[8, 1]] quantum code over GF(2^2), stabilised by:\n[ 1 0 $.1^2 $.1 1 0 0 0]\n[ $.1 0 1 $.1^2 $.1 0 0 0]\n[ 0 1 1 1 1 0 0 0]\n[ 0 $.1 $.1 $.1 $.1 0 0 0]\n[ 0 0 0 0 0 1 0 0]\n[ 0 0 0 0 0 0 1 0]\n[ 0 0 0 0 0 0 0 1]\nQuantum GF(2)-Additive code over GF(4) of length 8 with 9 generators.\nLower Bound: 1, Upper Bound: 5\nConstructed 2 distinct generator matrices\nTotal Ranks: 6 6 \nRelative Ranks: 6 2 \n(4 4 4 2 2 2 )\n(4 4 4 2 2 2 )\n Discarding non-contributing rank 2 matrix\n New Total Ranks: 6 \n New Relative Ranks: 6 \nTime Taken: 0.00\nStarting search for low weight codewords... (reset timings)\nEnumerating using 1 generator at a time:\n New codeword identified of weight 3, time 0.00\n Impurity detected of weight 1, time 0.00\n Completed Matrix 1: lower = 2, upper = 3. Elapsed: 0.00s\nTermination predicted with 2 generators at matrix 1\nEnumerating using 2 generators at a time:\n Completed Matrix 1: lower = 3, upper = 3. Elapsed: 0.00s\nComputation complete \nFinal Results: lower = 3, upper = 3,\nTotal CPU time: 0.00, real time: 0.001\n3\n\nTotal time: 0.010 seconds, Total memory usage: 32.09MB\n
A34: [[9,1,3]] | B34: 9 | C34: 1 | D34: 3 | E34: 0 | F34: 0.052406625 | G34: 1 | H34: 1 | I34: Magma V2.28-26 Tue Dec 30 2025 12:10:36 on Marks-MacBook-Air-2 [Seed = \n4124007711]\nType ? for help. Type <Ctrl>-D to quit.\n[1 0 0 1 1 0 0 0 0 1 0 1 0 1 0 0 0 0]\n[0 1 0 0 1 0 0 0 0 1 0 0 1 1 0 0 0 0]\n[0 0 1 1 0 0 0 0 0 1 0 0 1 1 0 0 0 0]\n[0 0 0 0 0 1 0 0 0 0 0 0 0 0 0 0 0 0]\n[0 0 0 0 0 0 1 0 0 0 0 0 0 0 0 0 0 0]\n[0 0 0 0 0 0 0 1 0 0 0 0 0 0 0 0 0 0]\n[0 0 0 0 0 0 0 0 1 0 0 0 0 0 0 0 0 0]\n[0 0 0 0 0 0 0 0 0 0 1 1 1 1 0 0 0 0]\n[[9, 1]] quantum code over GF(2^2), stabilised by:\n[ 1 0 $.1^2 $.1 1 0 0 0 0]\n[ $.1 0 1 $.1^2 $.1 0 0 0 0]\n[ 0 1 1 1 1 0 0 0 0]\n[ 0 $.1 $.1 $.1 $.1 0 0 0 0]\n[ 0 0 0 0 0 1 0 0 0]\n[ 0 0 0 0 0 0 1 0 0]\n[ 0 0 0 0 0 0 0 1 0]\n[ 0 0 0 0 0 0 0 0 1]\nQuantum GF(2)-Additive code over GF(4) of length 9 with 10 generators.\nLower Bound: 1, Upper Bound: 5\nConstructed 2 distinct generator matrices\nTotal Ranks: 7 7 \nRelative Ranks: 7 2 \n(4 4 4 2 2 2 2 )\n(4 4 4 2 2 2 2 )\n Discarding non-contributing rank 2 matrix\n New Total Ranks: 7 \n New Relative Ranks: 7 \nTime Taken: 0.00\nStarting search for low weight codewords... (reset timings)\nEnumerating using 1 generator at a time:\n New codeword identified of weight 3, time 0.00\n Impurity detected of weight 1, time 0.00\n Completed Matrix 1: lower = 2, upper = 3. Elapsed: 0.00s\nTermination predicted with 2 generators at matrix 1\nEnumerating using 2 generators at a time:\n Completed Matrix 1: lower = 3, upper = 3. Elapsed: 0.00s\nComputation complete \nFinal Results: lower = 3, upper = 3,\nTotal CPU time: 0.00, real time: 0.001\n3\n\nTotal time: 0.010 seconds, Total memory usage: 32.09MB\n
A35: [[10,1,4]] | B35: 10 | C35: 1 | D35: 4 | E35: 0 | F35: 0.052589167 | G35: 1 | H35: 1 | I35: Magma V2.28-26 Tue Dec 30 2025 12:10:36 on Marks-MacBook-Air-2 [Seed = \n4291122965]\nType ? for help. Type <Ctrl>-D to quit.\n[1 0 0 0 0 1 0 0 0 0 0 1 0 1 0 0 0 1 1 0]\n[0 1 0 0 0 1 0 0 0 0 0 1 0 1 1 1 0 0 1 1]\n[0 0 1 0 0 1 0 1 0 0 0 0 1 1 1 1 0 0 0 0]\n[0 0 0 1 0 1 0 0 0 0 0 1 1 1 0 1 1 0 0 1]\n[0 0 0 0 1 1 0 1 0 0 0 1 0 0 0 1 1 1 0 0]\n[0 0 0 0 0 0 1 1 0 0 0 1 1 0 1 1 0 0 1 1]\n[0 0 0 0 0 0 0 0 1 0 0 0 1 1 1 1 1 0 0 1]\n[0 0 0 0 0 0 0 0 0 1 0 1 1 1 1 0 0 1 1 0]\n[0 0 0 0 0 0 0 0 0 0 1 1 1 1 1 1 0 0 0 0]\n[[10, 1]] quantum code over GF(2^2), stabilised by:\n[ 1 0 0 0 0 1 $.1^2 $.1^2 1 0]\n[ $.1 0 0 0 0 $.1 0 $.1 $.1 1]\n[ 0 1 0 0 $.1 $.1^2 $.1^2 1 1 $.1]\n[ 0 $.1 0 0 0 $.1 $.1 $.1 $.1^2 $.1^2]\n[ 0 0 1 0 0 1 $.1 1 1 $.1]\n[ 0 0 $.1 0 $.1 0 $.1^2 $.1^2 1 1]\n[ 0 0 0 1 $.1 $.1^2 $.1 $.1 $.1 $.1^2]\n[ 0 0 0 $.1 0 $.1 1 $.1^2 0 $.1^2]\n[ 0 0 0 0 1 1 0 1 $.1^2 $.1^2]\nQuantum GF(2)-Additive code over GF(4) of length 10 with 11 generators.\nLower Bound: 1, Upper Bound: 6\nConstructed 2 distinct generator matrices\nTotal Ranks: 6 6 \nRelative Ranks: 6 4 \n(4 4 4 4 4 2 )\n(4 4 4 4 2 4 )\nTime Taken: 0.00\nStarting search for low weight codewords... (reset timings)\nEnumerating using 1 generator at a time:\n New codeword identified of weight 5, time 0.00\n New codeword identified of weight 4, time 0.00\n Completed Matrix 1: lower = 2, upper = 4. Elapsed: 0.00s\n Completed Matrix 2: lower = 2, upper = 4. Elapsed: 0.00s\nTermination predicted with 2 generators at matrix 2\nEnumerating using 2 generators at a time:\n Completed Matrix 1: lower = 3, upper = 4. Elapsed: 0.00s\n Completed Matrix 2: lower = 4, upper = 4. Elapsed: 0.00s\nComputation complete \nFinal Results: lower = 4, upper = 4,\nTotal CPU time: 0.00, real time: 0.001\n4\n\nTotal time: 0.010 seconds, Total memory usage: 32.09MB\n
A36: [[11,1,5]] | B36: 11 | C36: 1 | D36: 5 | E36: 0 | F36: 0.052994916 | G36: 1 | H36: 1 | I36: Magma V2.28-26 Tue Dec 30 2025 12:10:36 on Marks-MacBook-Air-2 [Seed = \n4190327058]\nType ? for help. Type <Ctrl>-D to quit.\n[1 0 0 0 0 1 0 0 0 0 0 0 1 0 1 0 0 0 1 1 0 0]\n[0 1 0 0 0 1 0 0 0 0 0 0 1 0 1 1 1 0 0 1 1 0]\n[0 0 1 0 0 1 0 0 0 0 0 0 1 0 0 1 0 0 0 0 1 1]\n[0 0 0 1 0 1 0 0 0 0 0 0 1 1 1 0 1 1 0 0 1 0]\n[0 0 0 0 1 1 0 0 0 0 0 0 0 1 1 0 0 1 1 0 1 1]\n[0 0 0 0 0 0 1 0 0 0 1 0 0 1 1 0 0 1 1 1 0 1]\n[0 0 0 0 0 0 0 1 0 0 1 0 1 0 1 1 1 1 1 0 1 1]\n[0 0 0 0 0 0 0 0 1 0 1 0 0 0 1 0 1 0 1 0 1 0]\n[0 0 0 0 0 0 0 0 0 1 1 0 1 0 1 0 0 1 0 1 0 0]\n[0 0 0 0 0 0 0 0 0 0 0 1 1 1 1 1 1 0 0 0 0 0]\n[[11, 1]] quantum code over GF(2^2), stabilised by:\n[ 1 0 0 0 0 1 $.1 $.1 0 1 1]\n[ $.1 0 0 0 0 $.1 1 $.1^2 $.1^2 0 1]\n[ 0 1 0 0 0 1 $.1 $.1^2 $.1 0 $.1^2]\n[ 0 $.1 0 0 0 $.1 $.1 $.1 $.1^2 $.1^2 0]\n[ 0 0 1 0 0 1 $.1 1 1 $.1 0]\n[ 0 0 $.1 0 0 $.1 $.1^2 0 $.1^2 $.1 $.1]\n[ 0 0 0 1 0 1 $.1^2 0 1 1 $.1^2]\n[ 0 0 0 $.1 0 $.1 0 $.1 1 $.1 1]\n[ 0 0 0 0 1 1 1 0 $.1 $.1 1]\n[ 0 0 0 0 $.1 $.1 0 $.1^2 $.1 $.1^2 $.1]\nQuantum GF(2)-Additive code over GF(4) of length 11 with 12 generators.\nLower Bound: 1, Upper Bound: 6\nConstructed 2 distinct generator matrices\nTotal Ranks: 6 6 \nRelative Ranks: 6 5 \n(4 4 4 4 4 4 )\n(4 4 4 4 4 4 )\nTime Taken: 0.00\nStarting search for low weight codewords... (reset timings)\nEnumerating using 1 generator at a time:\n New codeword identified of weight 5, time 0.00\n Completed Matrix 1: lower = 2, upper = 5. Elapsed: 0.00s\n Completed Matrix 2: lower = 3, upper = 5. Elapsed: 0.00s\nTermination predicted with 2 generators at matrix 2\nEnumerating using 2 generators at a time:\n Completed Matrix 1: lower = 4, upper = 5. Elapsed: 0.00s\n Completed Matrix 2: lower = 5, upper = 5. Elapsed: 0.00s\nComputation complete \nFinal Results: lower = 5, upper = 5,\nTotal CPU time: 0.00, real time: 0.001\n5\n\nTotal time: 0.010 seconds, Total memory usage: 32.09MB\n
A37: [[12,6,3]] | B37: 12 | C37: 6 | D37: 3 | E37: 0 | F37: 0.052198792 | G37: 1 | H37: 1 | I37: Magma V2.28-26 Tue Dec 30 2025 12:10:37 on Marks-MacBook-Air-2 [Seed = \n3822668552]\nType ? for help. Type <Ctrl>-D to quit.\n[1 0 0 0 0 1 0 1 0 1 0 1 1 0 0 1 0 1 0 0 1 1 1 1]\n[0 1 0 0 0 1 1 0 1 0 1 0 1 0 0 1 1 0 1 1 0 0 1 1]\n[0 0 1 0 0 0 0 1 1 0 0 1 0 1 0 0 1 0 0 1 0 1 1 0]\n[0 0 0 1 0 0 0 1 1 0 1 0 1 0 0 0 0 1 0 1 0 1 0 1]\n[0 0 0 0 1 1 1 1 1 1 0 0 1 1 0 0 1 1 0 0 0 0 1 1]\n[0 0 0 0 0 0 0 0 0 0 0 0 0 0 1 1 1 1 1 1 1 1 1 1]\n[[12, 6]] quantum code over GF(2^2), stabilised by:\n[ 1 0 0 $.1^2 0 1 0 $.1 $.1^2 1 $.1^2 1]\n[ $.1 0 0 1 0 $.1 0 $.1^2 1 $.1 1 $.1]\n[ 0 1 0 $.1^2 $.1 $.1^2 $.1^2 1 0 $.1 $.1 0]\n[ 0 $.1 0 1 $.1^2 1 1 $.1 0 $.1^2 $.1^2 0]\n[ 0 0 1 1 1 1 1 1 1 1 1 1]\n[ 0 0 $.1 $.1 $.1 $.1 $.1 $.1 $.1 $.1 $.1 $.1]\nQuantum GF(2)-Additive code over GF(4) of length 12 with 18 generators.\nLower Bound: 1, Upper Bound: 4\nConstructed 2 distinct generator matrices\nTotal Ranks: 9 9 \nRelative Ranks: 9 3 \n(4 4 4 4 4 4 4 4 4 )\n(4 4 4 4 4 4 4 4 4 )\n Discarding non-contributing rank 3 matrix\n New Total Ranks: 9 \n New Relative Ranks: 9 \nTime Taken: 0.00\nStarting search for low weight codewords... (reset timings)\nEnumerating using 1 generator at a time:\n New codeword identified of weight 3, time 0.00\n Completed Matrix 1: lower = 2, upper = 3. Elapsed: 0.00s\nTermination predicted with 2 generators at matrix 1\nEnumerating using 2 generators at a time:\n Completed Matrix 1: lower = 3, upper = 3. Elapsed: 0.00s\nComputation complete \nFinal Results: lower = 3, upper = 3,\nTotal CPU time: 0.00, real time: 0.001\n3\n\nTotal time: 0.010 seconds, Total memory usage: 32.09MB\n
A38: [[13,6,3]] | B38: 13 | C38: 6 | D38: 3 | E38: 0 | F38: 0.053350833 | G38: 1 | H38: 1 | I38: Magma V2.28-26 Tue Dec 30 2025 12:10:37 on Marks-MacBook-Air-2 [Seed = \n3990308102]\nType ? for help. Type <Ctrl>-D to quit.\n[1 0 0 0 0 1 0 1 0 1 0 1 0 1 0 0 1 0 1 0 0 1 1 1 1 0]\n[0 1 0 0 0 1 1 0 1 0 1 0 0 1 0 0 1 1 0 1 1 0 0 1 1 0]\n[0 0 1 0 0 0 0 1 1 0 0 1 0 0 1 0 0 1 0 0 1 0 1 1 0 0]\n[0 0 0 1 0 0 0 1 1 0 1 0 0 1 0 0 0 0 1 0 1 0 1 0 1 0]\n[0 0 0 0 1 1 1 1 1 1 0 0 0 1 1 0 0 1 1 0 0 0 0 1 1 0]\n[0 0 0 0 0 0 0 0 0 0 0 0 1 0 0 0 0 0 0 0 0 0 0 0 0 0]\n[0 0 0 0 0 0 0 0 0 0 0 0 0 0 0 1 1 1 1 1 1 1 1 1 1 0]\n[[13, 6]] quantum code over GF(2^2), stabilised by:\n[ 1 0 0 $.1^2 0 1 0 $.1 $.1^2 1 $.1^2 1 0]\n[ $.1 0 0 1 0 $.1 0 $.1^2 1 $.1 1 $.1 0]\n[ 0 1 0 $.1^2 $.1 $.1^2 $.1^2 1 0 $.1 $.1 0 0]\n[ 0 $.1 0 1 $.1^2 1 1 $.1 0 $.1^2 $.1^2 0 0]\n[ 0 0 1 1 1 1 1 1 1 1 1 1 0]\n[ 0 0 $.1 $.1 $.1 $.1 $.1 $.1 $.1 $.1 $.1 $.1 0]\n[ 0 0 0 0 0 0 0 0 0 0 0 0 1]\nQuantum GF(2)-Additive code over GF(4) of length 13 with 19 generators.\nLower Bound: 1, Upper Bound: 5\nConstructed 2 distinct generator matrices\nTotal Ranks: 10 10 \nRelative Ranks: 10 3 \n(4 4 4 4 4 4 4 4 4 2 )\n(4 4 4 4 4 4 4 4 4 2 )\n Discarding non-contributing rank 3 matrix\n New Total Ranks: 10 \n New Relative Ranks: 10 \nTime Taken: 0.00\nStarting search for low weight codewords... (reset timings)\nEnumerating using 1 generator at a time:\n New codeword identified of weight 3, time 0.00\n Impurity detected of weight 1, time 0.00\n Completed Matrix 1: lower = 2, upper = 3. Elapsed: 0.00s\nTermination predicted with 2 generators at matrix 1\nEnumerating using 2 generators at a time:\n Completed Matrix 1: lower = 3, upper = 3. Elapsed: 0.00s\nComputation complete \nFinal Results: lower = 3, upper = 3,\nTotal CPU time: 0.00, real time: 0.001\n3\n\nTotal time: 0.010 seconds, Total memory usage: 32.09MB\n
A39: [[14,2,5]] | B39: 14 | C39: 2 | D39: 5 | E39: 0 | F39: 0.053272625 | G39: 1 | H39: 1 | I39: Magma V2.28-26 Tue Dec 30 2025 12:10:37 on Marks-MacBook-Air-2 [Seed = \n2544713596]\nType ? for help. Type <Ctrl>-D to quit.\n[1 0 0 0 0 0 0 0 0 0 0 0 1 0 0 0 0 1 1 1 0 1 1 1 0 0 0 0]\n[0 1 0 0 0 0 0 0 0 0 0 0 0 1 0 0 0 0 1 1 1 0 1 1 1 0 0 0]\n[0 0 1 0 0 0 0 0 0 0 0 0 1 0 0 0 0 1 1 0 1 0 1 0 1 1 0 0]\n[0 0 0 1 0 0 0 0 0 0 0 0 0 1 0 0 0 0 1 1 0 1 0 1 0 1 1 0]\n[0 0 0 0 1 0 0 0 0 0 0 0 1 0 0 0 0 1 1 0 1 1 0 1 1 0 1 1]\n[0 0 0 0 0 1 0 0 0 0 0 0 0 1 1 0 0 0 1 1 0 1 1 0 1 1 0 1]\n[0 0 0 0 0 0 1 0 0 0 0 0 1 0 1 1 0 1 1 0 1 1 0 0 0 1 1 0]\n[0 0 0 0 0 0 0 1 0 0 0 0 0 1 0 1 1 0 1 1 0 1 1 0 0 0 1 1]\n[0 0 0 0 0 0 0 0 1 0 0 0 1 0 1 0 1 0 1 0 1 1 0 0 0 0 0 1]\n[0 0 0 0 0 0 0 0 0 1 0 0 0 1 1 1 0 1 0 1 0 1 1 0 0 0 0 0]\n[0 0 0 0 0 0 0 0 0 0 1 0 1 0 0 1 1 1 0 1 1 1 0 0 0 0 0 0]\n[0 0 0 0 0 0 0 0 0 0 0 1 0 1 0 0 1 1 1 0 1 1 1 0 0 0 0 0]\n[[14, 2]] quantum code over GF(2^2), stabilised by:\n[1 0 0 0 0 0 1 1 1 $.1 0 $.1 1 1]\n[$.1 0 0 0 0 0 $.1 $.1^2 $.1 1 0 1 $.1 $.1^2]\n[0 1 0 0 0 0 1 0 0 $.1^2 $.1 $.1 $.1^2 0]\n[0 $.1 0 0 0 0 $.1^2 0 0 1 1 $.1^2 $.1 0]\n[0 0 1 0 0 0 0 1 0 0 $.1^2 $.1 $.1 $.1^2]\n[0 0 $.1 0 0 0 0 $.1^2 0 0 1 1 $.1^2 $.1]\n[0 0 0 1 0 0 $.1^2 $.1 $.1 $.1^2 0 0 1 0]\n[0 0 0 $.1 0 0 $.1 $.1^2 1 1 0 0 $.1^2 0]\n[0 0 0 0 1 0 0 $.1^2 $.1 $.1 $.1^2 0 0 1]\n[0 0 0 0 $.1 0 0 $.1 $.1^2 1 1 0 0 $.1^2]\n[0 0 0 0 0 1 1 1 $.1 0 $.1 1 1 1]\n[0 0 0 0 0 $.1 $.1^2 $.1 1 0 1 $.1 $.1^2 $.1]\nQuantum GF(2)-Additive code over GF(4) of length 14 with 16 generators.\nLower Bound: 1, Upper Bound: 7\nConstructed 2 distinct generator matrices\nTotal Ranks: 8 8 \nRelative Ranks: 8 6 \n(4 4 4 4 4 4 4 4 )\n(4 4 4 4 4 4 4 4 )\nTime Taken: 0.00\nStarting search for low weight codewords... (reset timings)\nEnumerating using 1 generator at a time:\n New codeword identified of weight 5, time 0.00\n Completed Matrix 1: lower = 2, upper = 5. Elapsed: 0.00s\n Completed Matrix 2: lower = 2, upper = 5. Elapsed: 0.00s\nTermination predicted with 3 generators at matrix 1\nEnumerating using 2 generators at a time:\n Completed Matrix 1: lower = 3, upper = 5. Elapsed: 0.00s\n Completed Matrix 2: lower = 4, upper = 5. Elapsed: 0.00s\nTermination predicted with 3 generators at matrix 1\nEnumerating using 3 generators at a time:\n Completed Matrix 1: lower = 5, upper = 5. Elapsed: 0.00s\nComputation complete \nFinal Results: lower = 5, upper = 5,\nTotal CPU time: 0.00, real time: 0.001\n5\n\nTotal time: 0.010 seconds, Total memory usage: 32.09MB\n
A40: [[15,2,5]] | B40: 15 | C40: 2 | D40: 5 | E40: 0 | F40: 0.054226708991336636 | G40: 1 | H40: 1 | I40: Magma V2.28-26 Tue Dec 30 2025 12:10:37 on Marks-MacBook-Air-2 [Seed = \n2443917690]\nType ? for help. Type <Ctrl>-D to quit.\n[1 0 0 0 0 0 0 0 0 0 0 0 1 0 0 0 0 0 1 1 1 0 1 1 1 0 0 0 0 0]\n[0 1 0 0 0 0 0 0 0 0 0 0 0 1 0 0 0 0 0 1 1 1 0 1 1 1 0 0 0 0]\n[0 0 1 0 0 0 0 0 0 0 0 0 1 0 0 0 0 0 1 1 0 1 0 1 0 1 1 0 0 0]\n[0 0 0 1 0 0 0 0 0 0 0 0 0 1 0 0 0 0 0 1 1 0 1 0 1 0 1 1 0 0]\n[0 0 0 0 1 0 0 0 0 0 0 0 1 0 0 0 0 0 1 1 0 1 1 0 1 1 0 1 1 0]\n[0 0 0 0 0 1 0 0 0 0 0 0 0 1 0 1 0 0 0 1 1 0 1 1 0 1 1 0 1 0]\n[0 0 0 0 0 0 1 0 0 0 0 0 1 0 0 1 1 0 1 1 0 1 1 0 0 0 1 1 0 0]\n[0 0 0 0 0 0 0 1 0 0 0 0 0 1 0 0 1 1 0 1 1 0 1 1 0 0 0 1 1 0]\n[0 0 0 0 0 0 0 0 1 0 0 0 1 0 0 1 0 1 0 1 0 1 1 0 0 0 0 0 1 0]\n[0 0 0 0 0 0 0 0 0 1 0 0 0 1 0 1 1 0 1 0 1 0 1 1 0 0 0 0 0 0]\n[0 0 0 0 0 0 0 0 0 0 1 0 1 0 0 0 1 1 1 0 1 1 1 0 0 0 0 0 0 0]\n[0 0 0 0 0 0 0 0 0 0 0 1 0 1 0 0 0 1 1 1 0 1 1 1 0 0 0 0 0 0]\n[0 0 0 0 0 0 0 0 0 0 0 0 0 0 1 0 0 0 0 0 0 0 0 0 0 0 0 0 0 0]\n[[15, 2]] quantum code over GF(2^2), stabilised by:\n[1 0 0 0 0 0 1 1 1 $.1 0 $.1 1 1 0]\n[$.1 0 0 0 0 0 $.1 $.1^2 $.1 1 0 1 $.1 $.1^2 0]\n[0 1 0 0 0 0 1 0 0 $.1^2 $.1 $.1 $.1^2 0 0]\n[0 $.1 0 0 0 0 $.1^2 0 0 1 1 $.1^2 $.1 0 0]\n[0 0 1 0 0 0 0 1 0 0 $.1^2 $.1 $.1 $.1^2 0]\n[0 0 $.1 0 0 0 0 $.1^2 0 0 1 1 $.1^2 $.1 0]\n[0 0 0 1 0 0 $.1^2 $.1 $.1 $.1^2 0 0 1 0 0]\n[0 0 0 $.1 0 0 $.1 $.1^2 1 1 0 0 $.1^2 0 0]\n[0 0 0 0 1 0 0 $.1^2 $.1 $.1 $.1^2 0 0 1 0]\n[0 0 0 0 $.1 0 0 $.1 $.1^2 1 1 0 0 $.1^2 0]\n[0 0 0 0 0 1 1 1 $.1 0 $.1 1 1 1 0]\n[0 0 0 0 0 $.1 $.1^2 $.1 1 0 1 $.1 $.1^2 $.1 0]\n[0 0 0 0 0 0 0 0 0 0 0 0 0 0 1]\nQuantum GF(2)-Additive code over GF(4) of length 15 with 17 generators.\nLower Bound: 1, Upper Bound: 8\nConstructed 2 distinct generator matrices\nTotal Ranks: 9 9 \nRelative Ranks: 9 6 \n(4 4 4 4 4 4 4 4 2 )\n(4 4 4 4 4 4 4 4 2 )\nTime Taken: 0.00\nStarting search for low weight codewords... (reset timings)\nEnumerating using 1 generator at a time:\n New codeword identified of weight 5, time 0.00\n Impurity detected of weight 1, time 0.00\n Completed Matrix 1: lower = 2, upper = 5. Elapsed: 0.00s\n Completed Matrix 2: lower = 2, upper = 5. Elapsed: 0.00s\nTermination predicted with 3 generators at matrix 2\nEnumerating using 2 generators at a time:\n Completed Matrix 1: lower = 3, upper = 5. Elapsed: 0.00s\n Completed Matrix 2: lower = 3, upper = 5. Elapsed: 0.00s\nTermination predicted with 3 generators at matrix 2\nEnumerating using 3 generators at a time:\n Completed Matrix 1: lower = 4, upper = 5. Elapsed: 0.00s\n Completed Matrix 2: lower = 5, upper = 5. Elapsed: 0.00s\nComputation complete \nFinal Results: lower = 5, upper = 5,\nTotal CPU time: 0.00, real time: 0.002\n5\n\nTotal time: 0.010 seconds, Total memory usage: 32.09MB\n
A41: [[16,1,6]] | B41: 16 | C41: 1 | D41: 6 | E41: 0 | F41: 0.053124625 | G41: 1 | H41: 1 | I41: Magma V2.28-26 Tue Dec 30 2025 12:10:37 on Marks-MacBook-Air-2 [Seed = \n2611032944]\nType ? for help. Type <Ctrl>-D to quit.\n[1 0 0 0 0 0 0 0 0 0 0 0 0 0 0 1 0 1 1 0 0 1 1 1 1 1 1 0 0 1 1 0]\n[0 1 0 0 0 0 0 0 0 0 0 0 0 0 0 1 0 0 0 1 1 1 1 1 0 0 1 0 0 0 0 1]\n[0 0 1 0 0 0 0 0 0 0 0 0 0 0 0 1 1 1 1 0 1 0 0 0 0 1 1 1 0 1 1 0]\n[0 0 0 1 0 0 0 0 0 0 0 0 0 0 0 1 0 0 0 0 0 1 0 1 1 0 1 1 0 1 0 0]\n[0 0 0 0 1 0 0 0 0 0 0 0 0 0 0 1 0 0 1 0 1 1 1 0 0 0 0 0 1 0 0 0]\n[0 0 0 0 0 1 0 0 0 0 0 0 0 0 0 1 0 1 1 0 0 1 1 0 1 0 0 0 1 0 1 1]\n[0 0 0 0 0 0 1 0 0 0 0 0 0 0 0 1 1 0 0 0 1 0 0 1 1 1 1 1 1 1 1 0]\n[0 0 0 0 0 0 0 1 0 0 0 0 0 0 0 1 0 1 1 0 1 0 0 0 0 0 1 0 1 1 0 1]\n[0 0 0 0 0 0 0 0 1 0 0 0 0 0 0 1 1 1 0 1 0 0 1 1 1 1 1 1 0 0 0 0]\n[0 0 0 0 0 0 0 0 0 1 0 0 0 0 0 1 0 0 0 1 1 0 0 0 0 1 1 1 0 1 1 1]\n[0 0 0 0 0 0 0 0 0 0 1 0 0 0 0 1 1 0 1 1 0 1 1 0 1 0 0 0 0 0 0 0]\n[0 0 0 0 0 0 0 0 0 0 0 1 0 0 0 1 0 1 1 1 0 1 1 1 1 0 0 1 0 0 1 0]\n[0 0 0 0 0 0 0 0 0 0 0 0 1 0 0 1 0 1 0 0 1 0 1 0 0 1 0 0 0 1 1 0]\n[0 0 0 0 0 0 0 0 0 0 0 0 0 1 0 1 0 0 0 0 1 0 0 1 1 1 1 1 0 0 0 1]\n[0 0 0 0 0 0 0 0 0 0 0 0 0 0 1 1 1 1 1 0 0 0 1 1 0 0 0 1 1 1 1 0]\n[[16, 1]] quantum code over GF(2^2), stabilised by:\n[1 0 0 0 0 0 0 $.1 $.1 $.1^2 $.1 $.1^2 0 1 $.1 0]\n[$.1 0 0 0 0 0 0 $.1 $.1^2 $.1^2 0 0 1 0 0 $.1^2]\n[0 1 0 0 0 0 0 0 $.1 $.1 $.1^2 $.1 $.1^2 0 1 $.1]\n[0 $.1 0 0 0 0 0 0 $.1^2 $.1^2 1 $.1^2 1 0 $.1 $.1^2]\n[0 0 1 0 0 0 0 $.1 $.1^2 $.1^2 $.1^2 $.1^2 $.1 $.1 1 $.1]\n[0 0 $.1 0 0 0 0 $.1 1 $.1^2 $.1 0 $.1 1 1 0]\n[0 0 0 1 0 0 0 $.1 1 $.1 $.1 $.1^2 $.1^2 $.1^2 $.1^2 $.1]\n[0 0 0 $.1 0 0 0 $.1 $.1 1 0 0 0 $.1^2 $.1 0]\n[0 0 0 0 1 0 0 $.1 1 0 $.1^2 $.1 $.1^2 $.1 $.1 0]\n[0 0 0 0 $.1 0 0 $.1 $.1 $.1 $.1 $.1 0 1 0 $.1^2]\n[0 0 0 0 0 1 0 0 $.1 1 0 $.1^2 $.1 $.1^2 $.1 $.1]\n[0 0 0 0 0 $.1 0 0 $.1^2 $.1 0 1 $.1^2 1 $.1^2 $.1^2]\n[0 0 0 0 0 0 1 $.1 $.1^2 $.1^2 0 0 $.1^2 $.1^2 $.1 1]\n[0 0 0 0 0 0 $.1 $.1 1 $.1^2 $.1^2 1 0 $.1^2 0 1]\n[0 0 0 0 0 0 0 1 0 $.1 $.1^2 1 1 $.1 $.1^2 $.1^2]\nQuantum GF(2)-Additive code over GF(4) of length 16 with 17 generators.\nLower Bound: 1, Upper Bound: 9\nConstructed 2 distinct generator matrices\nTotal Ranks: 9 9 \nRelative Ranks: 9 7 \n(4 4 4 4 4 4 4 4 2 )\n(4 4 4 4 4 4 4 4 2 )\nTime Taken: 0.00\nStarting search for low weight codewords... (reset timings)\nEnumerating using 1 generator at a time:\n New codeword identified of weight 8, time 0.00\n New codeword identified of weight 7, time 0.00\n New codeword identified of weight 6, time 0.00\n Completed Matrix 1: lower = 2, upper = 6. Elapsed: 0.00s\n Completed Matrix 2: lower = 2, upper = 6. Elapsed: 0.00s\nTermination predicted with 3 generators at matrix 2\nEnumerating using 2 generators at a time:\n Completed Matrix 1: lower = 3, upper = 6. Elapsed: 0.00s\n Completed Matrix 2: lower = 4, upper = 6. Elapsed: 0.00s\nTermination predicted with 3 generators at matrix 2\nEnumerating using 3 generators at a time:\n Completed Matrix 1: lower = 5, upper = 6. Elapsed: 0.00s\n Completed Matrix 2: lower = 6, upper = 6. Elapsed: 0.00s\nComputation complete \nFinal Results: lower = 6, upper = 6,\nTotal CPU time: 0.00, real time: 0.001\n6\n\nTotal time: 0.010 seconds, Total memory usage: 32.09MB\n
A42: [[17,3,5]] | B42: 17 | C42: 3 | D42: 5 | E42: 0 | F42: 0.054344375006621704 | G42: 1 | H42: 1 | I42: Magma V2.28-26 Tue Dec 30 2025 12:10:37 on Marks-MacBook-Air-2 [Seed = \n2243898734]\nType ? for help. Type <Ctrl>-D to quit.\n[1 0 0 0 0 0 0 0 0 0 0 0 1 0 0 0 0 0 0 1 0 1 1 0 1 1 0 1 0 0 0 0 0 0]\n[0 1 0 0 0 0 0 0 0 0 0 0 0 1 0 0 0 0 0 0 1 0 1 1 0 1 1 0 1 0 0 0 0 0]\n[0 0 1 0 0 0 0 0 0 0 0 0 0 0 1 0 0 0 0 0 0 1 0 1 1 0 1 1 0 1 0 0 0 0]\n[0 0 0 1 0 0 0 0 0 0 0 0 1 0 0 0 0 0 1 0 0 1 1 1 1 1 1 1 1 0 0 1 0 0]\n[0 0 0 0 1 0 0 0 0 0 0 0 0 0 1 0 0 1 1 0 0 1 1 0 1 0 0 0 1 0 1 1 0 0]\n[0 0 0 0 0 1 0 0 0 0 0 0 1 1 1 0 0 1 1 0 0 0 1 1 0 0 0 1 0 0 0 1 0 0]\n[0 0 0 0 0 0 1 0 0 0 0 0 1 0 0 0 0 1 1 0 0 0 0 1 1 1 0 1 1 1 0 0 0 0]\n[0 0 0 0 0 0 0 1 0 0 0 0 0 1 0 0 0 0 1 1 0 0 0 0 1 1 1 0 1 1 1 0 0 0]\n[0 0 0 0 0 0 0 0 1 0 0 0 0 0 1 0 0 0 0 1 1 0 0 0 0 1 1 1 0 1 1 1 0 0]\n[0 0 0 0 0 0 0 0 0 1 0 0 1 1 1 0 0 1 0 1 1 1 0 0 0 1 1 0 1 1 1 1 0 0]\n[0 0 0 0 0 0 0 0 0 0 1 0 1 0 0 0 0 1 1 1 1 1 1 0 0 1 1 0 0 0 1 1 0 0]\n[0 0 0 0 0 0 0 0 0 0 0 1 0 0 1 0 0 1 0 0 1 0 1 0 0 1 0 0 0 1 1 0 0 0]\n[0 0 0 0 0 0 0 0 0 0 0 0 0 0 0 1 0 0 0 0 0 0 0 0 0 0 0 0 0 0 0 0 0 0]\n[0 0 0 0 0 0 0 0 0 0 0 0 0 0 0 0 1 0 0 0 0 0 0 0 0 0 0 0 0 0 0 0 0 0]\n[[17, 3]] quantum code over GF(2^2), stabilised by:\n[1 0 0 0 0 0 0 $.1 $.1 $.1^2 $.1 $.1^2 0 1 $.1 0 0]\n[$.1 0 0 0 0 0 0 $.1^2 $.1^2 1 $.1^2 1 0 $.1 $.1^2 0 0]\n[0 1 0 0 0 0 $.1 $.1^2 $.1^2 $.1^2 $.1^2 $.1 $.1 1 $.1 0 0]\n[0 $.1 0 0 0 0 $.1^2 1 1 1 1 $.1^2 $.1^2 $.1 $.1^2 0 0]\n[0 0 1 0 0 0 $.1 1 $.1 $.1 $.1^2 $.1^2 $.1^2 $.1^2 $.1 0 0]\n[0 0 $.1 0 0 0 $.1^2 $.1 $.1^2 $.1^2 1 1 1 1 $.1^2 0 0]\n[0 0 0 1 0 0 $.1 1 0 $.1^2 $.1 $.1^2 $.1 $.1 0 0 0]\n[0 0 0 $.1 0 0 $.1^2 $.1 0 1 $.1^2 1 $.1^2 $.1^2 0 0 0]\n[0 0 0 0 1 0 0 $.1 1 0 $.1^2 $.1 $.1^2 $.1 $.1 0 0]\n[0 0 0 0 $.1 0 0 $.1^2 $.1 0 1 $.1^2 1 $.1^2 $.1^2 0 0]\n[0 0 0 0 0 1 $.1 $.1^2 $.1^2 0 0 $.1^2 $.1^2 $.1 1 0 0]\n[0 0 0 0 0 $.1 $.1^2 1 1 0 0 1 1 $.1^2 $.1 0 0]\n[0 0 0 0 0 0 0 0 0 0 0 0 0 0 0 1 0]\n[0 0 0 0 0 0 0 0 0 0 0 0 0 0 0 0 1]\nQuantum GF(2)-Additive code over GF(4) of length 17 with 20 generators.\nLower Bound: 1, Upper Bound: 8\nConstructed 2 distinct generator matrices\nTotal Ranks: 11 11 \nRelative Ranks: 11 6 \n(4 4 4 4 4 4 4 4 4 2 2 )\n(4 4 4 4 4 4 4 4 4 2 2 )\nTime Taken: 0.00\nStarting search for low weight codewords... (reset timings)\nEnumerating using 1 generator at a time:\n New codeword identified of weight 6, time 0.00\n New codeword identified of weight 5, time 0.00\n Impurity detected of weight 1, time 0.00\n Discarding non-contributing rank 6 matrix\n New Total Ranks: 11 \n New Relative Ranks: 11 \n Completed Matrix 1: lower = 2, upper = 5. Elapsed: 0.00s\nTermination predicted with 4 generators at matrix 1\nEnumerating using 2 generators at a time:\n Completed Matrix 1: lower = 3, upper = 5. Elapsed: 0.00s\nTermination predicted with 4 generators at matrix 1\nEnumerating using 3 generators at a time:\n Completed Matrix 1: lower = 4, upper = 5. Elapsed: 0.00s\nTermination predicted with 4 generators at matrix 1\nEnumerating using 4 generators at a time:\n Completed Matrix 1: lower = 5, upper = 5. Elapsed: 0.00s\nComputation complete \nFinal Results: lower = 5, upper = 5,\nTotal CPU time: 0.00, real time: 0.002\n5\n\nTotal time: 0.010 seconds, Total memory usage: 32.09MB\n
A43: [[18,5,5]] | B43: 18 | C43: 5 | D43: 5 | E43: 0 | F43: 0.054014333 | G43: 1 | H43: 1 | I43: Magma V2.28-26 Tue Dec 30 2025 12:10:37 on Marks-MacBook-Air-2 [Seed = \n2411013988]\nType ? for help. Type <Ctrl>-D to quit.\n[1 0 0 0 0 0 0 0 0 0 0 0 0 1 1 0 0 0 1 0 1 1 1 0 0 0 1 1 1 1 0 1 0 1 0 0]\n[0 1 0 0 0 0 0 0 0 0 0 0 0 1 1 1 0 0 1 1 1 0 0 1 0 0 1 0 0 0 0 1 0 1 0 1]\n[0 0 1 0 0 0 0 0 0 0 0 0 0 1 1 1 1 0 0 1 0 0 1 0 1 0 1 0 1 1 1 1 0 1 0 1]\n[0 0 0 1 0 0 0 0 0 0 0 0 0 1 1 1 1 1 1 0 0 1 1 1 0 1 1 0 1 0 1 0 0 1 0 1]\n[0 0 0 0 1 0 0 0 0 0 0 0 0 0 0 0 0 0 0 1 1 1 0 1 0 1 1 1 0 1 0 1 0 0 1 0]\n[0 0 0 0 0 1 0 0 0 0 0 0 0 1 0 0 0 0 0 0 0 0 0 0 0 0 0 0 0 1 0 1 0 1 1 0]\n[0 0 0 0 0 0 1 0 0 0 0 0 0 1 0 0 0 1 0 0 0 1 1 0 0 0 0 1 0 1 1 1 0 1 1 1]\n[0 0 0 0 0 0 0 1 0 0 0 0 0 1 0 1 1 1 0 0 0 0 1 1 0 1 1 1 0 1 0 0 0 1 0 0]\n[0 0 0 0 0 0 0 0 1 0 0 0 0 1 0 1 0 0 1 0 0 0 0 1 0 1 0 0 0 1 1 1 1 1 0 1]\n[0 0 0 0 0 0 0 0 0 1 0 0 0 0 1 0 1 0 1 1 0 0 0 0 1 0 1 0 0 0 1 1 1 1 1 0]\n[0 0 0 0 0 0 0 0 0 0 1 0 0 0 0 1 0 1 0 1 1 0 0 0 0 1 0 1 0 0 0 1 1 1 1 1]\n[0 0 0 0 0 0 0 0 0 0 0 1 0 1 1 1 0 1 0 0 1 1 0 0 1 1 0 1 0 1 0 1 0 0 0 0]\n[0 0 0 0 0 0 0 0 0 0 0 0 1 1 1 1 1 1 0 0 0 0 0 0 1 1 1 1 1 1 1 1 1 1 1 1]\n[[18, 5]] quantum code over GF(2^2), stabilised by:\n[1 0 0 0 0 0 0 1 $.1^2 0 0 $.1^2 1 1 1 0 $.1 1]\n[$.1 0 0 0 0 $.1 0 $.1 1 0 0 $.1 $.1 $.1^2 $.1 $.1^2 0 $.1]\n[0 1 0 0 0 0 0 0 $.1^2 $.1 1 $.1 $.1 $.1 1 $.1^2 $.1 $.1^2]\n[0 $.1 0 0 0 $.1 0 0 1 $.1^2 $.1 0 $.1^2 $.1 $.1 $.1 0 1]\n[0 0 1 0 0 0 0 1 $.1^2 $.1^2 $.1 $.1 $.1 $.1^2 0 1 $.1^2 1]\n[0 0 $.1 0 0 $.1 0 $.1 1 1 $.1^2 0 $.1^2 0 0 1 $.1 $.1]\n[0 0 0 1 0 0 0 1 $.1 $.1^2 $.1^2 1 0 $.1^2 1 0 1 0]\n[0 0 0 $.1 0 $.1 0 $.1 $.1^2 1 1 1 0 0 $.1 $.1^2 1 0]\n[0 0 0 0 1 0 0 $.1 1 1 0 $.1^2 0 0 0 0 1 $.1^2]\n[0 0 0 0 $.1 $.1 0 $.1^2 $.1 $.1 0 $.1 0 1 0 $.1^2 1 1]\n[0 0 0 0 0 1 0 0 0 0 0 $.1 0 $.1^2 0 $.1 $.1 0]\n[0 0 0 0 0 0 1 1 1 1 1 1 $.1 $.1 $.1 $.1 $.1 $.1]\n[0 0 0 0 0 0 $.1 $.1 $.1 $.1 $.1 $.1 $.1^2 $.1^2 $.1^2 $.1^2 $.1^2 $.1^2]\nQuantum GF(2)-Additive code over GF(4) of length 18 with 23 generators.\nLower Bound: 1, Upper Bound: 8\nConstructed 2 distinct generator matrices\nTotal Ranks: 12 12 \nRelative Ranks: 12 6 \n(4 4 4 4 4 4 4 4 4 4 2 4 )\n(4 4 4 4 4 4 4 4 4 4 4 2 )\nTime Taken: 0.00\nStarting search for low weight codewords... (reset timings)\nEnumerating using 1 generator at a time:\n New codeword identified of weight 6, time 0.00\n New codeword identified of weight 5, time 0.00\n Discarding non-contributing rank 6 matrix\n New Total Ranks: 12 \n New Relative Ranks: 12 \n Completed Matrix 1: lower = 2, upper = 5. Elapsed: 0.00s\nTermination predicted with 4 generators at matrix 1\nEnumerating using 2 generators at a time:\n Completed Matrix 1: lower = 3, upper = 5. Elapsed: 0.00s\nTermination predicted with 4 generators at matrix 1\nEnumerating using 3 generators at a time:\n Completed Matrix 1: lower = 4, upper = 5. Elapsed: 0.00s\nTermination predicted with 4 generators at matrix 1\nEnumerating using 4 generators at a time:\n Completed Matrix 1: lower = 5, upper = 5. Elapsed: 0.00s\nComputation complete \nFinal Results: lower = 5, upper = 5,\nTotal CPU time: 0.00, real time: 0.002\n5\n\nTotal time: 0.010 seconds, Total memory usage: 32.09MB\n
A44: [[19,5,5]] | B44: 19 | C44: 5 | D44: 5 | E44: 0 | F44: 0.054391625002608635 | G44: 1 | H44: 1 | I44: Magma V2.28-26 Tue Dec 30 2025 12:10:37 on Marks-MacBook-Air-2 [Seed = \n2310218082]\nType ? for help. Type <Ctrl>-D to quit.\n[1 0 0 0 0 0 0 0 0 0 0 0 0 1 1 0 0 0 0 1 0 1 1 1 0 0 0 1 1 1 1 0 1 0 1 0 0 0]\n[0 1 0 0 0 0 0 0 0 0 0 0 0 1 1 1 0 0 0 1 1 1 0 0 1 0 0 1 0 0 0 0 1 0 1 0 1 0]\n[0 0 1 0 0 0 0 0 0 0 0 0 0 1 1 1 1 0 0 0 1 0 0 1 0 1 0 1 0 1 1 1 1 0 1 0 1 0]\n[0 0 0 1 0 0 0 0 0 0 0 0 0 1 1 1 1 1 0 1 0 0 1 1 1 0 1 1 0 1 0 1 0 0 1 0 1 0]\n[0 0 0 0 1 0 0 0 0 0 0 0 0 0 0 0 0 0 0 0 1 1 1 0 1 0 1 1 1 0 1 0 1 0 0 1 0 0]\n[0 0 0 0 0 1 0 0 0 0 0 0 0 1 0 0 0 0 0 0 0 0 0 0 0 0 0 0 0 0 1 0 1 0 1 1 0 0]\n[0 0 0 0 0 0 1 0 0 0 0 0 0 1 0 0 0 1 0 0 0 0 1 1 0 0 0 0 1 0 1 1 1 0 1 1 1 0]\n[0 0 0 0 0 0 0 1 0 0 0 0 0 1 0 1 1 1 0 0 0 0 0 1 1 0 1 1 1 0 1 0 0 0 1 0 0 0]\n[0 0 0 0 0 0 0 0 1 0 0 0 0 1 0 1 0 0 0 1 0 0 0 0 1 0 1 0 0 0 1 1 1 1 1 0 1 0]\n[0 0 0 0 0 0 0 0 0 1 0 0 0 0 1 0 1 0 0 1 1 0 0 0 0 1 0 1 0 0 0 1 1 1 1 1 0 0]\n[0 0 0 0 0 0 0 0 0 0 1 0 0 0 0 1 0 1 0 0 1 1 0 0 0 0 1 0 1 0 0 0 1 1 1 1 1 0]\n[0 0 0 0 0 0 0 0 0 0 0 1 0 1 1 1 0 1 0 0 0 1 1 0 0 1 1 0 1 0 1 0 1 0 0 0 0 0]\n[0 0 0 0 0 0 0 0 0 0 0 0 1 1 1 1 1 1 0 0 0 0 0 0 0 1 1 1 1 1 1 1 1 1 1 1 1 0]\n[0 0 0 0 0 0 0 0 0 0 0 0 0 0 0 0 0 0 1 0 0 0 0 0 0 0 0 0 0 0 0 0 0 0 0 0 0 0]\n[[19, 5]] quantum code over GF(2^2), stabilised by:\n[1 0 0 0 0 0 0 1 $.1^2 0 0 $.1^2 1 1 1 0 $.1 1 0]\n[$.1 0 0 0 0 $.1 0 $.1 1 0 0 $.1 $.1 $.1^2 $.1 $.1^2 0 $.1 0]\n[0 1 0 0 0 0 0 0 $.1^2 $.1 1 $.1 $.1 $.1 1 $.1^2 $.1 $.1^2 0]\n[0 $.1 0 0 0 $.1 0 0 1 $.1^2 $.1 0 $.1^2 $.1 $.1 $.1 0 1 0]\n[0 0 1 0 0 0 0 1 $.1^2 $.1^2 $.1 $.1 $.1 $.1^2 0 1 $.1^2 1 0]\n[0 0 $.1 0 0 $.1 0 $.1 1 1 $.1^2 0 $.1^2 0 0 1 $.1 $.1 0]\n[0 0 0 1 0 0 0 1 $.1 $.1^2 $.1^2 1 0 $.1^2 1 0 1 0 0]\n[0 0 0 $.1 0 $.1 0 $.1 $.1^2 1 1 1 0 0 $.1 $.1^2 1 0 0]\n[0 0 0 0 1 0 0 $.1 1 1 0 $.1^2 0 0 0 0 1 $.1^2 0]\n[0 0 0 0 $.1 $.1 0 $.1^2 $.1 $.1 0 $.1 0 1 0 $.1^2 1 1 0]\n[0 0 0 0 0 1 0 0 0 0 0 $.1 0 $.1^2 0 $.1 $.1 0 0]\n[0 0 0 0 0 0 1 1 1 1 1 1 $.1 $.1 $.1 $.1 $.1 $.1 0]\n[0 0 0 0 0 0 $.1 $.1 $.1 $.1 $.1 $.1 $.1^2 $.1^2 $.1^2 $.1^2 $.1^2 $.1^2 0]\n[0 0 0 0 0 0 0 0 0 0 0 0 0 0 0 0 0 0 1]\nQuantum GF(2)-Additive code over GF(4) of length 19 with 24 generators.\nLower Bound: 1, Upper Bound: 8\nConstructed 2 distinct generator matrices\nTotal Ranks: 13 13 \nRelative Ranks: 13 6 \n(4 4 4 4 4 4 4 4 4 4 2 4 2 )\n(4 4 4 4 4 4 4 4 4 4 4 2 2 )\n Discarding non-contributing rank 6 matrix\n New Total Ranks: 13 \n New Relative Ranks: 13 \nTime Taken: 0.00\nStarting search for low weight codewords... (reset timings)\nEnumerating using 1 generator at a time:\n New codeword identified of weight 6, time 0.00\n New codeword identified of weight 5, time 0.00\n Impurity detected of weight 1, time 0.00\n Completed Matrix 1: lower = 2, upper = 5. Elapsed: 0.00s\nTermination predicted with 4 generators at matrix 1\nEnumerating using 2 generators at a time:\n Completed Matrix 1: lower = 3, upper = 5. Elapsed: 0.00s\nTermination predicted with 4 generators at matrix 1\nEnumerating using 3 generators at a time:\n Completed Matrix 1: lower = 4, upper = 5. Elapsed: 0.00s\nTermination predicted with 4 generators at matrix 1\nEnumerating using 4 generators at a time:\n Completed Matrix 1: lower = 5, upper = 5. Elapsed: 0.00s\nComputation complete \nFinal Results: lower = 5, upper = 5,\nTotal CPU time: 0.00, real time: 0.002\n5\n\nTotal time: 0.010 seconds, Total memory usage: 32.09MB\n
A45: [[20,3,6]] | B45: 20 | C45: 3 | D45: 6 | E45: 0 | F45: 0.054379583001718856 | G45: 1 | H45: 1 | I45: Magma V2.28-26 Tue Dec 30 2025 12:10:37 on Marks-MacBook-Air-2 [Seed = \n3012107096]\nType ? for help. Type <Ctrl>-D to quit.\n[1 0 0 0 0 0 0 0 0 0 0 0 0 0 0 0 0 1 1 0 0 0 0 1 0 1 0 0 0 1 0 0 0 0 0 0 1 1 1 \n 0]\n[0 1 0 0 0 0 0 0 0 0 0 0 0 0 0 0 0 1 1 1 0 1 1 0 0 1 1 1 0 1 0 0 0 1 1 1 1 1 1 \n 1]\n[0 0 1 0 0 0 0 0 0 0 0 0 0 0 0 0 0 1 0 1 0 0 0 1 0 1 0 1 1 1 1 0 0 1 1 1 0 1 0 \n 0]\n[0 0 0 1 0 0 0 0 0 0 0 0 0 0 0 0 0 0 0 0 1 1 0 0 0 0 0 1 1 1 0 1 0 0 0 0 1 0 0 \n 1]\n[0 0 0 0 1 0 0 0 0 0 0 0 0 0 0 0 0 1 0 0 0 0 0 0 1 1 0 1 1 0 1 0 1 1 1 1 1 1 0 \n 0]\n[0 0 0 0 0 1 0 0 0 0 0 0 0 0 0 0 0 1 1 0 1 1 1 0 1 0 1 1 1 0 0 1 0 0 0 0 0 1 1 \n 0]\n[0 0 0 0 0 0 1 0 0 0 0 0 0 0 0 0 0 1 1 1 1 0 0 1 1 0 0 0 1 0 0 0 1 1 1 1 1 0 1 \n 1]\n[0 0 0 0 0 0 0 1 0 0 0 0 0 0 0 0 0 1 0 1 1 1 1 0 1 0 1 0 0 0 1 0 0 0 1 1 0 1 1 \n 0]\n[0 0 0 0 0 0 0 0 1 0 0 0 0 0 0 0 0 0 0 0 0 0 1 1 1 1 1 0 0 0 0 1 0 0 1 0 1 0 0 \n 0]\n[0 0 0 0 0 0 0 0 0 1 0 0 0 0 0 0 0 1 0 0 1 1 1 1 0 0 1 0 0 1 0 0 1 1 1 0 1 1 0 \n 0]\n[0 0 0 0 0 0 0 0 0 0 1 0 0 0 0 0 0 0 1 0 0 1 0 0 1 0 1 1 0 0 0 0 0 0 1 1 0 0 1 \n 1]\n[0 0 0 0 0 0 0 0 0 0 0 1 0 0 0 0 0 1 0 1 1 1 0 0 1 0 0 0 1 1 1 0 0 1 1 0 0 0 0 \n 1]\n[0 0 0 0 0 0 0 0 0 0 0 0 1 0 0 0 0 1 0 0 0 1 0 0 0 0 1 0 0 0 1 1 0 1 1 1 1 0 1 \n 1]\n[0 0 0 0 0 0 0 0 0 0 0 0 0 1 0 0 0 0 1 0 0 0 1 0 0 0 0 1 0 0 1 1 1 0 1 1 1 1 0 \n 1]\n[0 0 0 0 0 0 0 0 0 0 0 0 0 0 1 0 0 0 0 1 0 0 0 1 0 0 0 0 1 0 1 1 1 1 0 1 1 1 1 \n 0]\n[0 0 0 0 0 0 0 0 0 0 0 0 0 0 0 1 0 0 1 0 0 1 0 0 0 0 1 1 0 1 0 1 1 1 0 1 1 1 0 \n 0]\n[0 0 0 0 0 0 0 0 0 0 0 0 0 0 0 0 1 1 0 1 0 1 0 0 1 1 0 0 1 1 0 0 1 0 0 1 0 1 1 \n 0]\n[[20, 3]] quantum code over GF(2^2), stabilised by:\n[1 0 0 0 0 0 0 0 0 $.1^2 0 1 0 $.1^2 $.1 $.1^2 1 $.1 1 0]\n[$.1 0 0 0 0 0 0 0 $.1 1 0 $.1 0 $.1^2 1 $.1^2 0 1 $.1 $.1^2]\n[0 1 0 0 0 0 0 0 $.1 $.1^2 $.1 $.1^2 1 0 1 $.1^2 $.1^2 $.1^2 0 $.1]\n[0 $.1 0 0 0 0 0 0 0 1 $.1^2 1 $.1 $.1^2 1 $.1 $.1 $.1 0 $.1]\n[0 0 1 0 0 0 0 0 $.1 1 0 1 $.1^2 1 $.1 0 $.1^2 1 1 $.1^2]\n[0 0 $.1 0 0 0 0 0 0 $.1 0 $.1 1 1 0 $.1^2 $.1 1 $.1 0]\n[0 0 0 1 0 0 0 0 0 0 1 1 1 0 $.1 0 0 0 1 1]\n[0 0 0 $.1 0 0 0 0 $.1 0 $.1 $.1 $.1 $.1 1 $.1 $.1 $.1 $.1 1]\n[0 0 0 0 1 0 0 0 0 1 $.1^2 1 1 1 1 $.1^2 1 1 1 1]\n[0 0 0 0 $.1 0 0 0 0 $.1 1 $.1 $.1 $.1 $.1 1 $.1 $.1 $.1 $.1]\n[0 0 0 0 0 1 0 0 0 $.1^2 1 $.1 1 $.1 $.1^2 $.1 $.1 $.1^2 0 1]\n[0 0 0 0 0 $.1 0 0 $.1 1 $.1 $.1^2 $.1 1 $.1^2 1 1 $.1^2 0 1]\n[0 0 0 0 0 0 1 0 $.1 $.1^2 $.1^2 $.1 $.1 1 0 $.1 $.1 0 1 $.1^2]\n[0 0 0 0 0 0 $.1 0 0 1 1 $.1^2 $.1^2 1 $.1^2 0 0 $.1^2 $.1 0]\n[0 0 0 0 0 0 0 1 $.1 1 1 0 $.1 $.1 $.1^2 1 $.1 0 $.1 $.1]\n[0 0 0 0 0 0 0 $.1 0 $.1 $.1 0 $.1^2 0 $.1 1 0 $.1^2 $.1^2 $.1]\n[0 0 0 0 0 0 0 0 1 0 0 0 0 1 1 1 1 1 0 $.1]\nQuantum GF(2)-Additive code over GF(4) of length 20 with 23 generators.\nLower Bound: 1, Upper Bound: 10\nConstructed 2 distinct generator matrices\nTotal Ranks: 12 12 \nRelative Ranks: 12 8 \n(4 4 4 4 4 4 4 4 4 4 4 2 )\n(4 4 4 4 4 4 4 4 4 4 4 2 )\nTime Taken: 0.00\nStarting search for low weight codewords... (reset timings)\nEnumerating using 1 generator at a time:\n New codeword identified of weight 8, time 0.00\n New codeword identified of weight 7, time 0.00\n Completed Matrix 1: lower = 2, upper = 7. Elapsed: 0.00s\n New codeword identified of weight 6, time 0.00\n Completed Matrix 2: lower = 2, upper = 6. Elapsed: 0.00s\nTermination predicted with 4 generators at matrix 2\nEnumerating using 2 generators at a time:\n Completed Matrix 1: lower = 3, upper = 6. Elapsed: 0.00s\n Completed Matrix 2: lower = 3, upper = 6. Elapsed: 0.00s\nTermination predicted with 4 generators at matrix 2\nEnumerating using 3 generators at a time:\n Completed Matrix 1: lower = 4, upper = 6. Elapsed: 0.00s\n Completed Matrix 2: lower = 4, upper = 6. Elapsed: 0.00s\nTermination predicted with 4 generators at matrix 2\nEnumerating using 4 generators at a time:\n Completed Matrix 1: lower = 5, upper = 6. Elapsed: 0.00s\n Completed Matrix 2: lower = 6, upper = 6. Elapsed: 0.00s\nComputation complete \nFinal Results: lower = 6, upper = 6,\nTotal CPU time: 0.00, real time: 0.002\n6\n\nTotal time: 0.010 seconds, Total memory usage: 32.09MB\n
