Workbook

Sheet analysis-all
A1: {=MID(CELL("filename"),SEARCH("[",CELL("filename"))+1,SEARCH("]",CELL("filename"))-SEARCH("[",CELL("filename"))-1)} -> BB-Rnd-v-Evol.xlsx
A3: Family Size | B3: =COUNT(AB:AB) -> 0 | C3: nMax | D3: =MAX(B68:B300) -> 3024 | E3: nMin | F3: =MIN(B68:B300) -> 72
A4: Sum dMin | B4: =SUM(C68:C188) -> 710 | C4: Sum d actual | D4: =B4 -> 710
A5: Heuristic Methods
B6: m4riRW | C6: QDistRndMW | D6: QDistEvol
A7: Codes completed | B7: =SUM(BD:BD) -> 20 | C7: =SUM(BE:BE) -> 20 | D7: =SUM(BF:BF) -> 20 | J7: #,##0;;
A8: Codes at lowest distance | B8: =SUM(CL:CL) -> 8 | C8: =SUM(CM:CM) -> 8 | D8: =SUM(CN:CN) -> 20 | J8: #,##0;;
A9: Overall Success Rate | B9: =IF(B7,B8/B7,"") -> 0.4 | C9: =IF(C7,C8/C7,"") -> 0.4 | D9: =IF(D7,D8/D7,"") -> 1 | J9: 0.0%;;
A10: Avg Delta d | B10: =(SUM(V:V)-$D$4)/B7 -> 17.8 | C10: =(SUM(W:W)-$D$4)/C7 -> 20.9 | D10: =(SUM(X:X)-$D$4)/D7 -> 0 | J10: #,##0.0
A11: Trials | C11: =SUM(FC:FC) -> 1000000 | D11: =SUM(FD:FD) -> 1000000 | J11: #,##0;;
A12: Trials at lowest distance | C12: =SUM(EL:EL) -> 148856 | D12: =SUM(EM:EM) -> 374187 | J12: #,##0;;
A13: Trial Success Rate | C13: =IF(C12,C12/C11,"") -> 0.148856 | D13: =IF(D12,D12/D11,"") -> 0.374187 | J13: 0.0%;;
A14: Total Processing Time (s) | B14: =SUM(DC:DC) -> 112.32264 | C14: =SUM(DD:DD) -> 47449.721 | D14: =SUM(DE:DE) -> 46856.61 | J14: 0.0E+00;;
A15: Time/Trial | B15: =IF(B11,B14/B11,"") | C15: =IF(C11,C14/C11,"") -> 0.047449721 | D15: =IF(D11,D14/D11,"") -> 0.04685661 | J15: 0.0E+00;; | N15: =IF(N11,N14/N11,"")
A16: Time/Successful Trial | B16: =IF(B12,B14/B12,"") | C16: =IF(C12,C14/C12,"") -> 0.31876257 | D16: =IF(D12,D14/D12,"") -> 0.12522244 | J16: 0.0E+00;; | N16: =IF(N12,N14/N12,"")
FX34: =IF(FU34,FT34/FU34,"")
FX35: =IF(FU35,FT35/FU35,"")
FX36: =IF(FU36,FT36/FU36,"")
FX37: =IF(FU37,FT37/FU37,"")
FX38: =IF(FU38,FT38/FU38,"")
A43: \begin{center}
A44: \begin{tabular}{ |l| | B44: r| | C44: r| | D44: r| | E44: } | F44: \hline
A45: =A2&" &" -> & | B45: ="\textbf{"&B6&"}"&IF(C45="\\",""," &") -> \textbf{m4riRW} & | C45: ="\textbf{"&C6&"}"&IF(D45="\\",""," &") -> \textbf{QDistRndMW} & | D45: ="\textbf{"&D6&"}"&IF(E45="\\",""," &") -> \textbf{QDistEvol} | E45: \\ | F45: \hline
A46: ="\textbf{"&A7&"} &" -> \textbf{Codes completed} & | B46: =SUBSTITUTE(TEXT(B7,$J7)&IF(C46="\\",""," &"),"%","\%") -> 20 & | C46: =SUBSTITUTE(TEXT(C7,$J7)&IF(D46="\\",""," &"),"%","\%") -> 20 & | D46: =SUBSTITUTE(TEXT(D7,$J7)&IF(E46="\\",""," &"),"%","\%") -> 20 | E46: \\
A47: ="\textbf{"&A8&"} &" -> \textbf{Codes at lowest distance} & | B47: =SUBSTITUTE(TEXT(B8,$J8)&IF(C47="\\",""," &"),"%","\%") -> 8 & | C47: =SUBSTITUTE(TEXT(C8,$J8)&IF(D47="\\",""," &"),"%","\%") -> 8 & | D47: =SUBSTITUTE(TEXT(D8,$J8)&IF(E47="\\",""," &"),"%","\%") -> 20 | E47: \\
A48: ="\textbf{"&A9&"} &" -> \textbf{Overall Success Rate} & | B48: =SUBSTITUTE(TEXT(B9,$J9)&IF(C48="\\",""," &"),"%","\%") -> 40.0\% & | C48: =SUBSTITUTE(TEXT(C9,$J9)&IF(D48="\\",""," &"),"%","\%") -> 40.0\% & | D48: =SUBSTITUTE(TEXT(D9,$J9)&IF(E48="\\",""," &"),"%","\%") -> 100.0\% | E48: \\
A49: ="\textbf{"&A10&"} &" -> \textbf{Avg Delta d} & | B49: =SUBSTITUTE(TEXT(B10,$J10)&IF(C49="\\",""," &"),"%","\%") -> 17.8 & | C49: =SUBSTITUTE(TEXT(C10,$J10)&IF(D49="\\",""," &"),"%","\%") -> 20.9 & | D49: =SUBSTITUTE(TEXT(D10,$J10)&IF(E49="\\",""," &"),"%","\%") -> 0.0 | E49: \\ | F49: \hline
A50: ="\textbf{"&A11&"} &" -> \textbf{Trials} & | B50: =SUBSTITUTE(TEXT(B11,$J11)&IF(C50="\\",""," &"),"%","\%") -> & | C50: =SUBSTITUTE(TEXT(C11,$J11)&IF(D50="\\",""," &"),"%","\%") -> 1,000,000 & | D50: =SUBSTITUTE(TEXT(D11,$J11)&IF(E50="\\",""," &"),"%","\%") -> 1,000,000 | E50: \\
A51: ="\textbf{"&A12&"} &" -> \textbf{Trials at lowest distance} & | B51: =SUBSTITUTE(TEXT(B12,$J12)&IF(C51="\\",""," &"),"%","\%") -> & | C51: =SUBSTITUTE(TEXT(C12,$J12)&IF(D51="\\",""," &"),"%","\%") -> 148,856 & | D51: =SUBSTITUTE(TEXT(D12,$J12)&IF(E51="\\",""," &"),"%","\%") -> 374,187 | E51: \\
A52: ="\textbf{"&A13&"} &" -> \textbf{Trial Success Rate} & | B52: =SUBSTITUTE(TEXT(B13,$J13)&IF(C52="\\",""," &"),"%","\%") -> & | C52: =SUBSTITUTE(TEXT(C13,$J13)&IF(D52="\\",""," &"),"%","\%") -> 14.9\% & | D52: =SUBSTITUTE(TEXT(D13,$J13)&IF(E52="\\",""," &"),"%","\%") -> 37.4\% | E52: \\ | F52: \hline
A53: ="\textbf{"&A14&"} &" -> \textbf{Total Processing Time (s)} & | B53: =SUBSTITUTE(TEXT(B14,$J14)&IF(C53="\\",""," &"),"%","\%") -> 1.1E+02 & | C53: =SUBSTITUTE(TEXT(C14,$J14)&IF(D53="\\",""," &"),"%","\%") -> 4.7E+04 & | D53: =SUBSTITUTE(TEXT(D14,$J14)&IF(E53="\\",""," &"),"%","\%") -> 4.7E+04 | E53: \\
A54: ="\textbf{"&A15&"} &" -> \textbf{Time/Trial} & | B54: =SUBSTITUTE(TEXT(B15,$J15)&IF(C54="\\",""," &"),"%","\%") -> & | C54: =SUBSTITUTE(TEXT(C15,$J15)&IF(D54="\\",""," &"),"%","\%") -> 4.7E-02 & | D54: =SUBSTITUTE(TEXT(D15,$J15)&IF(E54="\\",""," &"),"%","\%") -> 4.7E-02 | E54: \\
A55: ="\textbf{"&A16&"} &" -> \textbf{Time/Successful Trial} & | B55: =SUBSTITUTE(TEXT(B16,$J16)&IF(C55="\\",""," &"),"%","\%") -> & | C55: =SUBSTITUTE(TEXT(C16,$J16)&IF(D55="\\",""," &"),"%","\%") -> 3.2E-01 & | D55: =SUBSTITUTE(TEXT(D16,$J16)&IF(E55="\\",""," &"),"%","\%") -> 1.3E-01 | E55: \\ | F55: \hline
A56: \end{tabular}
A57: \end{center}
A65: Offset | B65: =35-ROW(D68) -> -33
E66: Match | V66: dCalc | AM66: Algorithm Completed within maxTime | BD66: d Estimated Successfully | BU66: dEst | CL66: d correct | DC66: Time - Completed Trials | DT66: Time - Successful Trials | EK66: R | FB66: T
A67: QDistEvol_all | B67: n | C67: dMin | E67: m4ri_RW_all | F67: QDistRndMW_all | G67: QDistEvol_all | V67: =E67 -> m4ri_RW_all | W67: =F67 -> QDistRndMW_all | X67: =G67 -> QDistEvol_all | AM67: =E67 -> m4ri_RW_all | AN67: =F67 -> QDistRndMW_all | AO67: =G67 -> QDistEvol_all | BD67: =V67 -> m4ri_RW_all | BE67: =W67 -> QDistRndMW_all | BF67: =X67 -> QDistEvol_all | BU67: =BD67 -> m4ri_RW_all | BV67: =BE67 -> QDistRndMW_all | BW67: =BF67 -> QDistEvol_all | CL67: =BU67 -> m4ri_RW_all | CM67: =BV67 -> QDistRndMW_all | CN67: =BW67 -> QDistEvol_all | DC67: =CL67 -> m4ri_RW_all | DD67: =CM67 -> QDistRndMW_all | DE67: =CN67 -> QDistEvol_all | DT67: =DC67 -> m4ri_RW_all | DU67: =DD67 -> QDistRndMW_all | DV67: =DE67 -> QDistEvol_all | EK67: =DT67 -> m4ri_RW_all | EL67: =DU67 -> QDistRndMW_all | EM67: =DV67 -> QDistEvol_all | FB67: =EK67 -> m4ri_RW_all | FC67: =EL67 -> QDistRndMW_all | FD67: =EM67 -> QDistEvol_all
A68: {=INDIRECT($A$67&"!A"&ROW(C68)+$B$65)} -> [[72,12,6]] | B68: {=INDIRECT($A$67&"!b"&ROW(C68)+$B$65)} -> 72 | C68: =MIN(V68:X68) -> 6 | D68: 6 | E68: =MATCH($B68,INDIRECT("'"&E$67&"'!b:b"),) -> 32 | F68: =MATCH($B68,INDIRECT("'"&F$67&"'!b:b"),) -> 32 | G68: =MATCH($B68,INDIRECT("'"&G$67&"'!b:b"),) -> 35 | V68: {=IF(ISNA(E68),$B68,OFFSET(INDIRECT("'"&V$67&"'!d1"),E68-1,))} -> 6 | W68: {=IF(ISNA(F68),,OFFSET(INDIRECT("'"&W$67&"'!d1"),F68-1,))} -> 6 | X68: {=IF(ISNA(G68),,OFFSET(INDIRECT("'"&X$67&"'!d1"),G68-1,))} -> 6 | AM68: =IF(DC68> $N$3,0,1) -> 0 | AN68: =IF(DD68> $N$3,0,1) -> 0 | AO68: =IF(DE68> $N$3,0,1) -> 0 | BD68: =IF(AND(V68>0,V68<$B68),1,0) -> 1 | BE68: =IF(AND(W68>0,W68<$B68),1,0) -> 1 | BF68: =IF(AND(X68>0,X68<$B68),1,0) -> 1 | BU68: =IF(BD68,V68,$B68) -> 6 | BV68: =IF(BE68,W68,$B68) -> 6 | BW68: =IF(BF68,X68,$B68) -> 6 | CL68: =IF(BU68=$C68,1,0) -> 1 | CM68: =IF(BV68=$C68,1,0) -> 1 | CN68: =IF(BW68=$C68,1,0) -> 1 | DC68: {=IF(BD68,OFFSET(INDIRECT("'"&DT$67&"'!f1"),E68-1,),"")} -> 0.5121673261746764 | DD68: {=IF(BE68,OFFSET(INDIRECT("'"&DU$67&"'!f1"),F68-1,),"")} -> 13.753417 | DE68: {=IF(BF68,OFFSET(INDIRECT("'"&DV$67&"'!f1"),G68-1,),"")} -> 19.267282 | DT68: {=IF(CL68,OFFSET(INDIRECT("'"&DT$67&"'!f1"),E68-1,),"")} -> 0.5121673261746764 | DU68: {=IF(CM68,OFFSET(INDIRECT("'"&DU$67&"'!f1"),F68-1,),"")} -> 13.753417 | DV68: {=IF(CN68,OFFSET(INDIRECT("'"&DV$67&"'!f1"),G68-1,),"")} -> 19.267282 | EK68: {=IF(ISNA(E68),0,OFFSET(INDIRECT("'"&EK$67&"'!g1"),E68-1,)*CL68)} -> 1 | EL68: {=IF(ISNA(F68),0,OFFSET(INDIRECT("'"&EL$67&"'!g1"),F68-1,)*CM68)} -> 47412 | EM68: {=IF(ISNA(G68),0,OFFSET(INDIRECT("'"&EM$67&"'!g1"),G68-1,)*CN68)} -> 49959 | FB68: {=IF(ISNA(E68),0,OFFSET(INDIRECT("'"&EK$67&"'!h1"),E68-1,))} -> 1 | FC68: {=IF(ISNA(F68),0,OFFSET(INDIRECT("'"&EL$67&"'!h1"),F68-1,))} -> 50000 | FD68: {=IF(ISNA(G68),0,OFFSET(INDIRECT("'"&EM$67&"'!h1"),G68-1,))} -> 50000
A69: {=INDIRECT($A$67&"!A"&ROW(C69)+$B$65)} -> [[90,8,10]] | B69: {=INDIRECT($A$67&"!b"&ROW(C69)+$B$65)} -> 90 | C69: =MIN(V69:X69) -> 10 | D69: 10 | E69: =MATCH($B69,INDIRECT("'"&E$67&"'!b:b"),) -> 33 | F69: =MATCH($B69,INDIRECT("'"&F$67&"'!b:b"),) -> 33 | G69: =MATCH($B69,INDIRECT("'"&G$67&"'!b:b"),) -> 36 | V69: {=IF(ISNA(E69),,OFFSET(INDIRECT("'"&V$67&"'!d1"),E69-1,))} -> 10 | W69: {=IF(ISNA(F69),,OFFSET(INDIRECT("'"&W$67&"'!d1"),F69-1,))} -> 10 | X69: {=IF(ISNA(G69),,OFFSET(INDIRECT("'"&X$67&"'!d1"),G69-1,))} -> 10 | AM69: =IF(DC69> $N$3,0,1) -> 0 | AN69: =IF(DD69> $N$3,0,1) -> 0 | AO69: =IF(DE69> $N$3,0,1) -> 0 | BD69: =IF(AND(V69>0,V69<$B69),1,0) -> 1 | BE69: =IF(AND(W69>0,W69<$B69),1,0) -> 1 | BF69: =IF(AND(X69>0,X69<$B69),1,0) -> 1 | BU69: =IF(BD69,V69,$B69) -> 10 | BV69: =IF(BE69,W69,$B69) -> 10 | BW69: =IF(BF69,X69,$B69) -> 10 | CL69: =IF(BU69=$C69,1,0) -> 1 | CM69: =IF(BV69=$C69,1,0) -> 1 | CN69: =IF(BW69=$C69,1,0) -> 1 | DC69: {=IF(BD69,OFFSET(INDIRECT("'"&DT$67&"'!f1"),E69-1,),"")} -> 0.89620366 | DD69: {=IF(BE69,OFFSET(INDIRECT("'"&DU$67&"'!f1"),F69-1,),"")} -> 16.089497 | DE69: {=IF(BF69,OFFSET(INDIRECT("'"&DV$67&"'!f1"),G69-1,),"")} -> 21.447926 | DT69: {=IF(CL69,OFFSET(INDIRECT("'"&DT$67&"'!f1"),E69-1,),"")} -> 0.89620366 | DU69: {=IF(CM69,OFFSET(INDIRECT("'"&DU$67&"'!f1"),F69-1,),"")} -> 16.089497 | DV69: {=IF(CN69,OFFSET(INDIRECT("'"&DV$67&"'!f1"),G69-1,),"")} -> 21.447926 | EK69: {=IF(ISNA(E69),0,OFFSET(INDIRECT("'"&EK$67&"'!g1"),E69-1,)*CL69)} -> 1 | EL69: {=IF(ISNA(F69),0,OFFSET(INDIRECT("'"&EL$67&"'!g1"),F69-1,)*CM69)} -> 35187 | EM69: {=IF(ISNA(G69),0,OFFSET(INDIRECT("'"&EM$67&"'!g1"),G69-1,)*CN69)} -> 49654 | FB69: {=IF(ISNA(E69),0,OFFSET(INDIRECT("'"&EK$67&"'!h1"),E69-1,))} -> 1 | FC69: {=IF(ISNA(F69),0,OFFSET(INDIRECT("'"&EL$67&"'!h1"),F69-1,))} -> 50000 | FD69: {=IF(ISNA(G69),0,OFFSET(INDIRECT("'"&EM$67&"'!h1"),G69-1,))} -> 50000
...

Sheet analysis-756
A1: {=MID(CELL("filename"),SEARCH("[",CELL("filename"))+1,SEARCH("]",CELL("filename"))-SEARCH("[",CELL("filename"))-1)} -> BB-Rnd-v-Evol.xlsx
A3: Family Size | B3: =COUNT(AB:AB) -> 0 | C3: nMax | D3: =MAX(B68:B300) -> 756 | E3: nMin | F3: =MIN(B68:B300) -> 756
A4: Sum dMin | B4: =SUM(C68:C188) -> 3400 | C4: Sum d actual | D4: =B4 -> 3400
A5: Heuristic Methods
B6: m4riRW | C6: QDistRndMW | D6: QDistEvol
A7: Runs completed | B7: =COUNT(M:M) -> 100 | C7: =COUNT(N:N) -> 100 | D7: =COUNT(O:O) -> 100 | J7: #,##0;;
A8: Runs at lowest distance | B8: =COUNTIF(I:I,0) -> 4 | C8: =COUNTIF(J:J,0) -> 2 | D8: =COUNTIF(K:K,0) -> 57 | J8: #,##0;;
A9: Overall Success Rate | B9: =IF(B7,B8/B7,"") -> 0.04 | C9: =IF(C7,C8/C7,"") -> 0.02 | D9: =IF(D7,D8/D7,"") -> 0.57 | J9: 0.0%;;
A10: Avg Delta d | B10: =SUM(I:I)/B7 -> 7.2 | C10: =SUM(J:J)/C7 -> 7.88 | D10: =SUM(K:K)/D7 -> 1.22 | J10: #,##0.0
A11: Trials | C11: =SUM(V:V) -> 1000000 | D11: =SUM(W:W) -> 1000000 | J11: #,##0;;
A12: Trials at lowest distance | C12: =SUM(Z:Z) -> 2 | D12: =SUM(AA:AA) -> 158898 | J12: #,##0;;
A13: Trial Success Rate | C13: =IF(C12,C12/C11,"") -> 2e-06 | D13: =IF(D12,D12/D11,"") -> 0.158898 | J13: 0.0%;;
A14: Total Processing Time (s) | B14: =SUM(M:M) -> 1149.3476 | C14: =SUM(N:N) -> 14208.769 | D14: =SUM(O:O) -> 13855.731 | J14: 0.0E+00;;
A15: Time/Trial | C15: =IF(C11,C14/C11,"") -> 0.014208769 | D15: =IF(D11,D14/D11,"") -> 0.013855731 | J15: 0.0E+00;;
A16: Time/Successful Trial | C16: =IF(C12,C14/C12,"") -> 7104.3846 | D16: =IF(D12,D14/D12,"") -> 0.087198904 | J16: 0.0E+00;;
FX34: =IF(FU34,FT34/FU34,"")
FX35: =IF(FU35,FT35/FU35,"")
FX36: =IF(FU36,FT36/FU36,"")
FX37: =IF(FU37,FT37/FU37,"")
FX38: =IF(FU38,FT38/FU38,"")
A43: \begin{center}
A44: \begin{tabular}{ |l| | B44: r| | C44: r| | D44: r| | G44: } | H44: \hline
A45: =A2&" &" -> & | B45: ="\textbf{"&B6&"}"&IF(C45="\\",""," &") -> \textbf{m4riRW} & | C45: ="\textbf{"&C6&"}"&IF(D45="\\",""," &") -> \textbf{QDistRndMW} & | D45: ="\textbf{"&D6&"}"&IF(E45="\\",""," &") -> \textbf{QDistEvol} & | G45: \\ | H45: \hline
A46: ="\textbf{"&A7&"} &" -> \textbf{Runs completed} & | B46: =SUBSTITUTE(TEXT(B7,$J7)&IF(C46="\\",""," &"),"%","\%") -> 100 & | C46: =SUBSTITUTE(TEXT(C7,$J7)&IF(D46="\\",""," &"),"%","\%") -> 100 & | D46: =SUBSTITUTE(TEXT(D7,$J7)&IF(E46="\\",""," &"),"%","\%") -> 100 & | G46: \\
A47: ="\textbf{"&A8&"} &" -> \textbf{Runs at lowest distance} & | B47: =SUBSTITUTE(TEXT(B8,$J8)&IF(C47="\\",""," &"),"%","\%") -> 4 & | C47: =SUBSTITUTE(TEXT(C8,$J8)&IF(D47="\\",""," &"),"%","\%") -> 2 & | D47: =SUBSTITUTE(TEXT(D8,$J8)&IF(E47="\\",""," &"),"%","\%") -> 57 & | G47: \\
A48: ="\textbf{"&A9&"} &" -> \textbf{Overall Success Rate} & | B48: =SUBSTITUTE(TEXT(B9,$J9)&IF(C48="\\",""," &"),"%","\%") -> 4.0\% & | C48: =SUBSTITUTE(TEXT(C9,$J9)&IF(D48="\\",""," &"),"%","\%") -> 2.0\% & | D48: =SUBSTITUTE(TEXT(D9,$J9)&IF(E48="\\",""," &"),"%","\%") -> 57.0\% & | G48: \\
A49: ="\textbf{"&A10&"} &" -> \textbf{Avg Delta d} & | B49: =SUBSTITUTE(TEXT(B10,$J10)&IF(C49="\\",""," &"),"%","\%") -> 7.2 & | C49: =SUBSTITUTE(TEXT(C10,$J10)&IF(D49="\\",""," &"),"%","\%") -> 7.9 & | D49: =SUBSTITUTE(TEXT(D10,$J10)&IF(E49="\\",""," &"),"%","\%") -> 1.2 & | G49: \\ | H49: \hline
A50: ="\textbf{"&A11&"} &" -> \textbf{Trials} & | B50: =SUBSTITUTE(TEXT(B11,$J11)&IF(C50="\\",""," &"),"%","\%") -> & | C50: =SUBSTITUTE(TEXT(C11,$J11)&IF(D50="\\",""," &"),"%","\%") -> 1,000,000 & | D50: =SUBSTITUTE(TEXT(D11,$J11)&IF(E50="\\",""," &"),"%","\%") -> 1,000,000 & | G50: \\
A51: ="\textbf{"&A12&"} &" -> \textbf{Trials at lowest distance} & | B51: =SUBSTITUTE(TEXT(B12,$J12)&IF(C51="\\",""," &"),"%","\%") -> & | C51: =SUBSTITUTE(TEXT(C12,$J12)&IF(D51="\\",""," &"),"%","\%") -> 2 & | D51: =SUBSTITUTE(TEXT(D12,$J12)&IF(E51="\\",""," &"),"%","\%") -> 158,898 & | G51: \\
A52: ="\textbf{"&A13&"} &" -> \textbf{Trial Success Rate} & | B52: =SUBSTITUTE(TEXT(B13,$J13)&IF(C52="\\",""," &"),"%","\%") -> & | C52: =SUBSTITUTE(TEXT(C13,$J13)&IF(D52="\\",""," &"),"%","\%") -> 0.0\% & | D52: =SUBSTITUTE(TEXT(D13,$J13)&IF(E52="\\",""," &"),"%","\%") -> 15.9\% & | G52: \\ | H52: \hline
A53: ="\textbf{"&A14&"} &" -> \textbf{Total Processing Time (s)} & | B53: =SUBSTITUTE(TEXT(B14,$J14)&IF(C53="\\",""," &"),"%","\%") -> 1.1E+03 & | C53: =SUBSTITUTE(TEXT(C14,$J14)&IF(D53="\\",""," &"),"%","\%") -> 1.4E+04 & | D53: =SUBSTITUTE(TEXT(D14,$J14)&IF(E53="\\",""," &"),"%","\%") -> 1.4E+04 & | G53: \\
A54: ="\textbf{"&A15&"} &" -> \textbf{Time/Trial} & | B54: =SUBSTITUTE(TEXT(B15,$J15)&IF(C54="\\",""," &"),"%","\%") -> & | C54: =SUBSTITUTE(TEXT(C15,$J15)&IF(D54="\\",""," &"),"%","\%") -> 1.4E-02 & | D54: =SUBSTITUTE(TEXT(D15,$J15)&IF(E54="\\",""," &"),"%","\%") -> 1.4E-02 & | G54: \\
A55: ="\textbf{"&A16&"} &" -> \textbf{Time/Successful Trial} & | B55: =SUBSTITUTE(TEXT(B16,$J16)&IF(C55="\\",""," &"),"%","\%") -> & | C55: =SUBSTITUTE(TEXT(C16,$J16)&IF(D55="\\",""," &"),"%","\%") -> 7.1E+03 & | D55: =SUBSTITUTE(TEXT(D16,$J16)&IF(E55="\\",""," &"),"%","\%") -> 8.7E-02 & | G55: \\ | H55: \hline
A56: \end{tabular}
A57: \end{center}
A65: Offset | B65: =25-ROW(D68) -> -43 | E65: D | F65: =E65 -> D | G65: =F65 -> D | H65: =G65 -> D | I65: =H65 -> D | J65: =I65 -> D | K65: =J65 -> D | L65: =K65 -> D | M65: F | N65: =M65 -> F | O65: =N65 -> F | P65: =O65 -> F | Q65: G | R65: =Q65 -> G | S65: =R65 -> G | T65: =S65 -> G | U65: H | V65: =U65 -> H | W65: =V65 -> H
E66: dCalc | I66: delta d | M66: Time | Q66: R | U66: T | Y66: R Succ | BU66: dEst | CL66: d correct | DC66: Time - Completed Trials | DT66: Time - Successful Trials | EK66: R | FB66: T
A67: QDistEvol_all | B67: n | C67: dMin | E67: m4riRW_756 | F67: QDistRnd_756 | G67: QDistEvol_756 | I67: =E67 -> m4riRW_756 | J67: =F67 -> QDistRnd_756 | K67: =G67 -> QDistEvol_756 | M67: =I67 -> m4riRW_756 | N67: =J67 -> QDistRnd_756 | O67: =K67 -> QDistEvol_756 | Q67: =M67 -> m4riRW_756 | R67: =N67 -> QDistRnd_756 | S67: =O67 -> QDistEvol_756 | U67: =Q67 -> m4riRW_756 | V67: =R67 -> QDistRnd_756 | W67: =S67 -> QDistEvol_756 | Y67: =U67 -> m4riRW_756 | Z67: =V67 -> QDistRnd_756 | AA67: =W67 -> QDistEvol_756 | BU67: =BD67 -> 0 | BV67: =BE67 -> 0 | BW67: =BF67 -> 0 | CL67: =BU67 -> 0 | CM67: =BV67 -> 0 | CN67: =BW67 -> 0 | DC67: =CL67 -> 0 | DD67: =CM67 -> 0 | DE67: =CN67 -> 0 | DT67: =DC67 -> 0 | DU67: =DD67 -> 0 | DV67: =DE67 -> 0 | EK67: =DT67 -> 0 | EL67: =DU67 -> 0 | EM67: =DV67 -> 0 | FB67: =EK67 -> 0 | FC67: =EL67 -> 0 | FD67: =EM67 -> 0
A68: =QDistRnd_756_20251225!A28 -> [[756,16,34]] | B68: =QDistRnd_756_20251225!B28 -> 756 | C68: 34 | E68: {=INDIRECT(E$67&"!"&E$65&ROW(E28))} -> 38 | F68: {=INDIRECT(F$67&"!"&F$65&ROW(F32))} -> 40 | G68: {=INDIRECT(G$67&"!"&G$65&ROW(G32))} -> 34 | I68: =E68-$C68 -> 4 | J68: =F68-$C68 -> 6 | K68: =G68-$C68 -> 0 | M68: {=INDIRECT(M$67&"!"&M$65&ROW(M28))} -> 11.064749 | N68: {=INDIRECT(N$67&"!"&N$65&ROW(N32))} -> 158.90274 | O68: {=INDIRECT(O$67&"!"&O$65&ROW(O32))} -> 153.9466 | Q68: {=INDIRECT(Q$67&"!"&Q$65&ROW(Q28))} -> 1 | R68: {=INDIRECT(R$67&"!"&R$65&ROW(R32))} -> 1 | S68: {=INDIRECT(S$67&"!"&S$65&ROW(S32))} -> 3986 | U68: {=INDIRECT(U$67&"!"&U$65&ROW(U28))} -> 1 | V68: {=INDIRECT(V$67&"!"&V$65&ROW(V32))} -> 10000 | W68: {=INDIRECT(W$67&"!"&W$65&ROW(W32))} -> 10000 | Y68: =IF(I68=0,Q68,0) -> 0 | Z68: =IF(J68=0,R68,0) -> 0 | AA68: =IF(K68=0,S68,0) -> 3986 | BU68: =IF(BD68,#REF!,$B68) -> 756 | BV68: =IF(BE68,W68,$B68) -> 756 | BW68: =IF(BF68,X68,$B68) -> 756 | CL68: =IF(BU68=$C68,1,0) -> 0 | CM68: =IF(BV68=$C68,1,0) -> 0 | CN68: =IF(BW68=$C68,1,0) -> 0 | DC68: {=IF(BD68,OFFSET(INDIRECT("'"&DT$67&"'!f1"),E68-1,),"")} | DD68: {=IF(BE68,OFFSET(INDIRECT("'"&DU$67&"'!f1"),F68-1,),"")} | DE68: {=IF(BF68,OFFSET(INDIRECT("'"&DV$67&"'!f1"),G68-1,),"")} | DT68: {=IF(CL68,OFFSET(INDIRECT("'"&DT$67&"'!f1"),E68-1,),"")} | DU68: {=IF(CM68,OFFSET(INDIRECT("'"&DU$67&"'!f1"),F68-1,),"")} | DV68: {=IF(CN68,OFFSET(INDIRECT("'"&DV$67&"'!f1"),G68-1,),"")} | EK68: {=IF(ISNA(E68),0,OFFSET(INDIRECT("'"&EK$67&"'!g1"),E68-1,)*CL68)} -> #REF! | EL68: {=IF(ISNA(F68),0,OFFSET(INDIRECT("'"&EL$67&"'!g1"),F68-1,)*CM68)} -> #REF! | EM68: {=IF(ISNA(G68),0,OFFSET(INDIRECT("'"&EM$67&"'!g1"),G68-1,)*CN68)} -> #REF! | FB68: {=IF(ISNA(E68),0,OFFSET(INDIRECT("'"&EK$67&"'!h1"),E68-1,))} -> #REF! | FC68: {=IF(ISNA(F68),0,OFFSET(INDIRECT("'"&EL$67&"'!h1"),F68-1,))} -> #REF! | FD68: {=IF(ISNA(G68),0,OFFSET(INDIRECT("'"&EM$67&"'!h1"),G68-1,))} -> #REF!
A69: =QDistRnd_756_20251225!A29 -> [[756,16,34]] | B69: =QDistRnd_756_20251225!B29 -> 756 | C69: 34 | E69: {=INDIRECT(E$67&"!"&E$65&ROW(E29))} -> 46 | F69: {=INDIRECT(F$67&"!"&F$65&ROW(F33))} -> 42 | G69: {=INDIRECT(G$67&"!"&G$65&ROW(G33))} -> 36 | I69: =E69-$C69 -> 12 | J69: =F69-$C69 -> 8 | K69: =G69-$C69 -> 2 | M69: {=INDIRECT(M$67&"!"&M$65&ROW(M29))} -> 11.16847 | N69: {=INDIRECT(N$67&"!"&N$65&ROW(N33))} -> 159.9445 | O69: {=INDIRECT(O$67&"!"&O$65&ROW(O33))} -> 155.90221 | Q69: {=INDIRECT(Q$67&"!"&Q$65&ROW(Q29))} -> 1 | R69: {=INDIRECT(R$67&"!"&R$65&ROW(R33))} -> 1 | S69: {=INDIRECT(S$67&"!"&S$65&ROW(S33))} -> 3168 | U69: {=INDIRECT(U$67&"!"&U$65&ROW(U29))} -> 1 | V69: {=INDIRECT(V$67&"!"&V$65&ROW(V33))} -> 10000 | W69: {=INDIRECT(W$67&"!"&W$65&ROW(W33))} -> 10000 | Y69: =IF(I69=0,Q69,0) -> 0 | Z69: =IF(J69=0,R69,0) -> 0 | AA69: =IF(K69=0,S69,0) -> 0 | BU69: =IF(BD69,V69,$B69) -> 756 | BV69: =IF(BE69,W69,$B69) -> 756 | BW69: =IF(BF69,X69,$B69) -> 756 | CL69: =IF(BU69=$C69,1,0) -> 0 | CM69: =IF(BV69=$C69,1,0) -> 0 | CN69: =IF(BW69=$C69,1,0) -> 0 | DC69: {=IF(BD69,OFFSET(INDIRECT("'"&DT$67&"'!f1"),E69-1,),"")} | DD69: {=IF(BE69,OFFSET(INDIRECT("'"&DU$67&"'!f1"),F69-1,),"")} | DE69: {=IF(BF69,OFFSET(INDIRECT("'"&DV$67&"'!f1"),G69-1,),"")} | DT69: {=IF(CL69,OFFSET(INDIRECT("'"&DT$67&"'!f1"),E69-1,),"")} | DU69: {=IF(CM69,OFFSET(INDIRECT("'"&DU$67&"'!f1"),F69-1,),"")} | DV69: {=IF(CN69,OFFSET(INDIRECT("'"&DV$67&"'!f1"),G69-1,),"")} | EK69: {=IF(ISNA(E69),0,OFFSET(INDIRECT("'"&EK$67&"'!g1"),E69-1,)*CL69)} -> #REF! | EL69: {=IF(ISNA(F69),0,OFFSET(INDIRECT("'"&EL$67&"'!g1"),F69-1,)*CM69)} -> #REF! | EM69: {=IF(ISNA(G69),0,OFFSET(INDIRECT("'"&EM$67&"'!g1"),G69-1,)*CN69)} -> #REF! | FB69: {=IF(ISNA(E69),0,OFFSET(INDIRECT("'"&EK$67&"'!h1"),E69-1,))} -> #REF! | FC69: {=IF(ISNA(F69),0,OFFSET(INDIRECT("'"&EL$67&"'!h1"),F69-1,))} -> #REF! | FD69: {=IF(ISNA(G69),0,OFFSET(INDIRECT("'"&EM$67&"'!h1"),G69-1,))} -> #REF!
...

Sheet m4ri_RW_all
A1: runMode: serial
A2: maxCount: 10000
A3: repeat: 1
A4: dataset: bivariate_bicycle
A5: datafile:
A6: method: dist_m4ri_RW
A7: ignoreTrivialCodes: 1
A8: resume: 0
A9: nMin: 1
A10: nMax: 100000
A11: iterCount: 50000
A12: maxTime: 28800
... A30: #########################################
A31: name | B31: n | C31: k | D31: d | E31: delta d | F31: Time | G31: R | H31: T | I31: Progress
A32: [[72,12,6]] | B32: 72 | C32: 12 | D32: 6 | E32: 0 | F32: 0.5121673261746764 | G32: 1 | H32: 1 | I32: # step=0 row=0 minW=73 found cw of W=14: [1 2 3 11 19 20 22 27 37 43 47 56 62 68]\n# step=0 row=2 minW=14 found cw of W=8: [5 14 15 22 45 60 62 71]\n# step=0 row=22 minW=8 found cw of W=6: [38 47 56 62 68 71]\n# round=1000 of 50000 minW=6\n# round=2000 of 50000 minW=6\n# round=3000 of 50000 minW=6\n# round=4000 of 50000 minW=6\n# round=5000 of 50000 minW=6\n# round=6000 of 50000 minW=6\n# round=7000 of 50000 minW=6\n# round=8000 of 50000 minW=6\n# round=9000 of 50000 minW=6\n# round=10000 of 50000 minW=6\n# round=11000 of 50000 minW=6\n# round=12000 of 50000 minW=6\n# round=13000 of 50000 minW=6\n# round=14000 of 50000 minW=6\n# round=15000 of 50000 minW=6\n# round=16000 of 50000 minW=6\n# round=17000 of 50000 minW=6\n# round=18000 of 50000 minW=6\n# round=19000 of 50000 minW=6\n# round=20000 of 50000 minW=6\n# round=21000 of 50000 minW=6\n# round=22000 of 50000 minW=6\n# round=23000 of 50000 minW=6\n# round=24000 of 50000 minW=6\n# round=25000 of 50000 minW=6\n# round=26000 of 50000 minW=6\n# round=27000 of 50000 minW=6\n# round=28000 of 50000 minW=6\n# round=29000 of 50000 minW=6\n# round=30000 of 50000 minW=6\n# round=31000 of 50000 minW=6\n# round=32000 of 50000 minW=6\n# round=33000 of 50000 minW=6\n# round=34000 of 50000 minW=6\n# round=35000 of 50000 minW=6\n# round=36000 of 50000 minW=6\n# round=37000 of 50000 minW=6\n# round=38000 of 50000 minW=6\n# round=39000 of 50000 minW=6\n# round=40000 of 50000 minW=6\n# round=41000 of 50000 minW=6\n# round=42000 of 50000 minW=6\n# round=43000 of 50000 minW=6\n# round=44000 of 50000 minW=6\n# round=45000 of 50000 minW=6\n# round=46000 of 50000 minW=6\n# round=47000 of 50000 minW=6\n# round=48000 of 50000 minW=6\n# round=49000 of 50000 minW=6\n# round=50000 of 50000 minW=6\nRW algorithm upper bound for the distance d=6\n
A33: [[90,8,10]] | B33: 90 | C33: 8 | D33: 10 | E33: 0 | F33: 0.89620366 | G33: 1 | H33: 1 | I33: # step=0 row=0 minW=91 found cw of W=20: [1 5 8 9 17 34 39 40 47 53 54 55 57 58 61 63 68 78 83 85]\n# step=0 row=2 minW=20 found cw of W=16: [3 7 9 19 32 40 46 47 48 54 55 58 70 71 76 85]\n# step=0 row=7 minW=16 found cw of W=14: [7 8 12 13 34 53 56 65 68 71 76 81 83 89]\n# step=0 row=10 minW=14 found cw of W=12: [5 7 16 33 48 53 54 55 63 68 76 78]\n# step=0 row=47 minW=12 found cw of W=10: [9 32 33 34 47 53 57 71 78 86]\n# round=1000 of 50000 minW=10\n# round=2000 of 50000 minW=10\n# round=3000 of 50000 minW=10\n# round=4000 of 50000 minW=10\n# round=5000 of 50000 minW=10\n# round=6000 of 50000 minW=10\n# round=7000 of 50000 minW=10\n# round=8000 of 50000 minW=10\n# round=9000 of 50000 minW=10\n# round=10000 of 50000 minW=10\n# round=11000 of 50000 minW=10\n# round=12000 of 50000 minW=10\n# round=13000 of 50000 minW=10\n# round=14000 of 50000 minW=10\n# round=15000 of 50000 minW=10\n# round=16000 of 50000 minW=10\n# round=17000 of 50000 minW=10\n# round=18000 of 50000 minW=10\n# round=19000 of 50000 minW=10\n# round=20000 of 50000 minW=10\n# round=21000 of 50000 minW=10\n# round=22000 of 50000 minW=10\n# round=23000 of 50000 minW=10\n# round=24000 of 50000 minW=10\n# round=25000 of 50000 minW=10\n# round=26000 of 50000 minW=10\n# round=27000 of 50000 minW=10\n# round=28000 of 50000 minW=10\n# round=29000 of 50000 minW=10\n# round=30000 of 50000 minW=10\n# round=31000 of 50000 minW=10\n# round=32000 of 50000 minW=10\n# round=33000 of 50000 minW=10\n# round=34000 of 50000 minW=10\n# round=35000 of 50000 minW=10\n# round=36000 of 50000 minW=10\n# round=37000 of 50000 minW=10\n# round=38000 of 50000 minW=10\n# round=39000 of 50000 minW=10\n# round=40000 of 50000 minW=10\n# round=41000 of 50000 minW=10\n# round=42000 of 50000 minW=10\n# round=43000 of 50000 minW=10\n# round=44000 of 50000 minW=10\n# round=45000 of 50000 minW=10\n# round=46000 of 50000 minW=10\n# round=47000 of 50000 minW=10\n# round=48000 of 50000 minW=10\n# round=49000 of 50000 minW=10\n# round=50000 of 50000 minW=10\nRW algorithm upper bound for the distance d=10\n
A34: [[108,8,10]] | B34: 108 | C34: 8 | D34: 10 | E34: 0 | F34: 1.1873942716047168 | G34: 1 | H34: 1 | I34: # step=0 row=0 minW=109 found cw of W=22: [1 2 14 16 18 19 26 30 31 33 39 50 51 54 65 78 80 82 83 86 88 90]\n# step=0 row=2 minW=22 found cw of W=12: [4 16 17 19 20 21 25 41 54 67 80 96]\n# step=0 row=45 minW=12 found cw of W=10: [17 18 26 33 48 50 59 68 91 106]\n# round=1000 of 50000 minW=10\n# round=2000 of 50000 minW=10\n# round=3000 of 50000 minW=10\n# round=4000 of 50000 minW=10\n# round=5000 of 50000 minW=10\n# round=6000 of 50000 minW=10\n# round=7000 of 50000 minW=10\n# round=8000 of 50000 minW=10\n# round=9000 of 50000 minW=10\n# round=10000 of 50000 minW=10\n# round=11000 of 50000 minW=10\n# round=12000 of 50000 minW=10\n# round=13000 of 50000 minW=10\n# round=14000 of 50000 minW=10\n# round=15000 of 50000 minW=10\n# round=16000 of 50000 minW=10\n# round=17000 of 50000 minW=10\n# round=18000 of 50000 minW=10\n# round=19000 of 50000 minW=10\n# round=20000 of 50000 minW=10\n# round=21000 of 50000 minW=10\n# round=22000 of 50000 minW=10\n# round=23000 of 50000 minW=10\n# round=24000 of 50000 minW=10\n# round=25000 of 50000 minW=10\n# round=26000 of 50000 minW=10\n# round=27000 of 50000 minW=10\n# round=28000 of 50000 minW=10\n# round=29000 of 50000 minW=10\n# round=30000 of 50000 minW=10\n# round=31000 of 50000 minW=10\n# round=32000 of 50000 minW=10\n# round=33000 of 50000 minW=10\n# round=34000 of 50000 minW=10\n# round=35000 of 50000 minW=10\n# round=36000 of 50000 minW=10\n# round=37000 of 50000 minW=10\n# round=38000 of 50000 minW=10\n# round=39000 of 50000 minW=10\n# round=40000 of 50000 minW=10\n# round=41000 of 50000 minW=10\n# round=42000 of 50000 minW=10\n# round=43000 of 50000 minW=10\n# round=44000 of 50000 minW=10\n# round=45000 of 50000 minW=10\n# round=46000 of 50000 minW=10\n# round=47000 of 50000 minW=10\n# round=48000 of 50000 minW=10\n# round=49000 of 50000 minW=10\n# round=50000 of 50000 minW=10\nRW algorithm upper bound for the distance d=10\n
A35: [[144,12,12]] | B35: 144 | C35: 12 | D35: 12 | E35: 0 | F35: 1.9778669895604253 | G35: 1 | H35: 1 | I35: # step=0 row=0 minW=145 found cw of W=32: [1 5 10 16 22 27 29 30 39 51 53 58 60 64 65 67 78 89 90 92 98 107 109 110 111 113 115 125 135 136 139 140]\n# step=0 row=2 minW=32 found cw of W=28: [4 5 10 27 28 30 37 51 55 58 59 64 65 67 78 81 86 88 97 101 107 109 110 111 115 125 140 144]\n# step=0 row=7 minW=28 found cw of W=24: [5 10 11 30 52 55 58 64 65 77 81 86 88 97 101 103 107 109 110 115 125 135 140 144]\n# step=0 row=9 minW=24 found cw of W=12: [14 22 28 29 30 80 86 88 92 96 98 101]\n# round=1000 of 50000 minW=12\n# round=2000 of 50000 minW=12\n# round=3000 of 50000 minW=12\n# round=4000 of 50000 minW=12\n# round=5000 of 50000 minW=12\n# round=6000 of 50000 minW=12\n# round=7000 of 50000 minW=12\n# round=8000 of 50000 minW=12\n# round=9000 of 50000 minW=12\n# round=10000 of 50000 minW=12\n# round=11000 of 50000 minW=12\n# round=12000 of 50000 minW=12\n# round=13000 of 50000 minW=12\n# round=14000 of 50000 minW=12\n# round=15000 of 50000 minW=12\n# round=16000 of 50000 minW=12\n# round=17000 of 50000 minW=12\n# round=18000 of 50000 minW=12\n# round=19000 of 50000 minW=12\n# round=20000 of 50000 minW=12\n# round=21000 of 50000 minW=12\n# round=22000 of 50000 minW=12\n# round=23000 of 50000 minW=12\n# round=24000 of 50000 minW=12\n# round=25000 of 50000 minW=12\n# round=26000 of 50000 minW=12\n# round=27000 of 50000 minW=12\n# round=28000 of 50000 minW=12\n# round=29000 of 50000 minW=12\n# round=30000 of 50000 minW=12\n# round=31000 of 50000 minW=12\n# round=32000 of 50000 minW=12\n# round=33000 of 50000 minW=12\n# round=34000 of 50000 minW=12\n# round=35000 of 50000 minW=12\n# round=36000 of 50000 minW=12\n# round=37000 of 50000 minW=12\n# round=38000 of 50000 minW=12\n# round=39000 of 50000 minW=12\n# round=40000 of 50000 minW=12\n# round=41000 of 50000 minW=12\n# round=42000 of 50000 minW=12\n# round=43000 of 50000 minW=12\n# round=44000 of 50000 minW=12\n# round=45000 of 50000 minW=12\n# round=46000 of 50000 minW=12\n# round=47000 of 50000 minW=12\n# round=48000 of 50000 minW=12\n# round=49000 of 50000 minW=12\n# round=50000 of 50000 minW=12\nRW algorithm upper bound for the distance d=12\n
A36: [[288,12,18]] | B36: 288 | C36: 12 | D36: 18 | E36: 0 | F36: 8.368582014925778 | G36: 1 | H36: 1 | I36: # step=0 row=0 minW=289 found cw of W=38: [1 15 18 22 27 35 43 49 55 59 60 67 69 76 81 84 88 95 98 123 130 150 154 159 162 167 184 187 188 193 213 222 228 233 235 243 250 277]\n# step=0 row=61 minW=38 found cw of W=36: [15 18 27 35 43 49 55 59 60 67 69 76 81 84 88 95 98 123 130 133 150 154 159 184 187 188 193 213 222 228 233 235 243 250 265 277]\n# step=1 row=11 minW=36 found cw of W=34: [12 14 17 19 25 37 50 63 66 68 71 91 95 103 115 129 144 146 149 157 158 166 173 179 182 183 210 216 222 227 231 235 236 269]\n# step=1 row=29 minW=34 found cw of W=32: [5 12 21 41 48 50 54 55 57 66 88 100 116 119 122 129 134 136 137 141 150 168 186 209 218 227 268 269 277 282 285 288]\n# step=2 row=51 minW=32 found cw of W=24: [13 17 20 24 30 42 49 50 56 86 89 91 96 123 127 162 182 185 188 191 194 196 197 200]\n# step=100 row=44 minW=24 found cw of W=22: [4 45 46 74 75 79 80 94 106 123 126 145 149 226 245 246 248 257 266 272 280 284]\n# step=173 row=57 minW=22 found cw of W=18: [14 18 52 55 59 60 86 88 94 96 122 123 125 127 128 129 130 132]\n# round=1000 of 50000 minW=18\n# round=2000 of 50000 minW=18\n# round=3000 of 50000 minW=18\n# round=4000 of 50000 minW=18\n# round=5000 of 50000 minW=18\n# round=6000 of 50000 minW=18\n# round=7000 of 50000 minW=18\n# round=8000 of 50000 minW=18\n# round=9000 of 50000 minW=18\n# round=10000 of 50000 minW=18\n# round=11000 of 50000 minW=18\n# round=12000 of 50000 minW=18\n# round=13000 of 50000 minW=18\n# round=14000 of 50000 minW=18\n# round=15000 of 50000 minW=18\n# round=16000 of 50000 minW=18\n# round=17000 of 50000 minW=18\n# round=18000 of 50000 minW=18\n# round=19000 of 50000 minW=18\n# round=20000 of 50000 minW=18\n# round=21000 of 50000 minW=18\n# round=22000 of 50000 minW=18\n# round=23000 of 50000 minW=18\n# round=24000 of 50000 minW=18\n# round=25000 of 50000 minW=18\n# round=26000 of 50000 minW=18\n# round=27000 of 50000 minW=18\n# round=28000 of 50000 minW=18\n# round=29000 of 50000 minW=18\n# round=30000 of 50000 minW=18\n# round=31000 of 50000 minW=18\n# round=32000 of 50000 minW=18\n# round=33000 of 50000 minW=18\n# round=34000 of 50000 minW=18\n# round=35000 of 50000 minW=18\n# round=36000 of 50000 minW=18\n# round=37000 of 50000 minW=18\n# round=38000 of 50000 minW=18\n# round=39000 of 50000 minW=18\n# round=40000 of 50000 minW=18\n# round=41000 of 50000 minW=18\n# round=42000 of 50000 minW=18\n# round=43000 of 50000 minW=18\n# round=44000 of 50000 minW=18\n# round=45000 of 50000 minW=18\n# round=46000 of 50000 minW=18\n# round=47000 of 50000 minW=18\n# round=48000 of 50000 minW=18\n# round=49000 of 50000 minW=18\n# round=50000 of 50000 minW=18\nRW algorithm upper bound for the distance d=18\n
A37: [[360,12,24]] | B37: 360 | C37: 12 | D37: 24 | E37: 0 | F37: 12.563259687274694 | G37: 1 | H37: 1 | I37: # step=0 row=0 minW=361 found cw of W=74: [2 14 23 27 34 36 41 45 47 48 49 61 63 66 67 69 71 83 87 88 92 95 108 120 124 125 126 130 135 154 156 161 169 173 179 180 182 185 194 195 199 203 217 218 232 241 252 270 271 276 277 283 291 295 305 312 317 318 322 323 324 328 331 333 335 338 339 342 343 344 349 350 351 355]\n# step=0 row=2 minW=74 found cw of W=62: [1 3 4 7 8 9 10 13 14 23 36 45 51 61 87 88 95 104 114 120 135 154 156 169 173 176 182 183 188 191 194 199 210 231 242 258 268 269 270 271 275 276 277 286 291 302 303 305 312 322 323 324 329 330 331 333 343 344 345 350 351 356]\n# step=0 row=8 minW=62 found cw of W=56: [13 14 20 22 27 34 41 47 56 67 71 87 100 114 121 124 125 136 150 152 154 156 169 173 174 179 182 195 217 238 244 249 252 268 269 271 276 277 295 301 305 310 317 318 323 329 333 335 338 339 344 345 350 351 354 355]\n# step=0 row=16 minW=56 found cw of W=44: [1 3 14 22 27 35 36 41 47 48 49 56 95 121 136 154 174 179 183 191 195 203 210 217 238 244 276 277 304 312 317 318 323 331 333 335 339 344 345 349 350 351 355 356]\n# step=1 row=53 minW=44 found cw of W=40: [22 43 59 63 69 92 94 108 111 112 113 119 134 141 145 146 147 150 160 163 167 168 171 172 173 174 188 197 204 215 217 218 263 270 289 296 315 341 345 350]\n# step=1 row=64 minW=40 found cw of W=34: [12 14 46 47 71 72 75 76 83 108 110 134 135 136 137 166 167 168 202 204 206 225 227 229 233 262 263 292 319 323 346 347 349 352]\n# step=5 row=88 minW=34 found cw of W=32: [2 7 9 16 25 32 85 101 144 153 154 155 160 186 197 218 245 251 283 310 311 318 320 332 337 338 339 342 345 347 353 359]\n# step=10 row=77 minW=32 found cw of W=30: [41 46 51 57 58 94 126 137 141 142 152 168 179 201 207 222 227 232 233 238 243 248 253 280 286 291 322 333 334 360]\n# step=10 row=143 minW=30 found cw of W=28: [5 41 46 51 57 58 94 126 137 141 142 168 201 207 222 227 232 233 238 243 248 253 280 281 286 291 322 360]\n# step=116 row=153 minW=28 found cw of W=26: [35 38 57 87 88 89 90 91 139 145 157 177 192 199 205 212 226 245 247 253 273 300 320 326 339 358]\n# round=1000 of 50000 minW=26\n# step=1152 row=169 minW=26 found cw of W=24: [13 35 36 56 83 84 87 104 109 114 146 157 185 194 221 227 233 242 264 268 295 327 354 360]\n# round=2000 of 50000 minW=24\n# round=3000 of 50000 minW=24\n# round=4000 of 50000 minW=24\n# round=5000 of 50000 minW=24\n# round=6000 of 50000 minW=24\n# round=7000 of 50000 minW=24\n# round=8000 of 50000 minW=24\n# round=9000 of 50000 minW=24\n# round=10000 of 50000 minW=24\n# round=11000 of 50000 minW=24\n# round=12000 of 50000 minW=24\n# round=13000 of 50000 minW=24\n# round=14000 of 50000 minW=24\n# round=15000 of 50000 minW=24\n# round=16000 of 50000 minW=24\n# round=17000 of 50000 minW=24\n# round=18000 of 50000 minW=24\n# round=19000 of 50000 minW=24\n# round=20000 of 50000 minW=24\n# round=21000 of 50000 minW=24\n# round=22000 of 50000 minW=24\n# round=23000 of 50000 minW=24\n# round=24000 of 50000 minW=24\n# round=25000 of 50000 minW=24\n# round=26000 of 50000 minW=24\n# round=27000 of 50000 minW=24\n# round=28000 of 50000 minW=24\n# round=29000 of 50000 minW=24\n# round=30000 of 50000 minW=24\n# round=31000 of 50000 minW=24\n# round=32000 of 50000 minW=24\n# round=33000 of 50000 minW=24\n# round=34000 of 50000 minW=24\n# round=35000 of 50000 minW=24\n# round=36000 of 50000 minW=24\n# round=37000 of 50000 minW=24\n# round=38000 of 50000 minW=24\n# round=39000 of 50000 minW=24\n# round=40000 of 50000 minW=24\n# round=41000 of 50000 minW=24\n# round=42000 of 50000 minW=24\n# round=43000 of 50000 minW=24\n# round=44000 of 50000 minW=24\n# round=45000 of 50000 minW=24\n# round=46000 of 50000 minW=24\n# round=47000 of 50000 minW=24\n# round=48000 of 50000 minW=24\n# round=49000 of 50000 minW=24\n# round=50000 of 50000 minW=24\nRW algorithm upper bound for the distance d=24\n
A38: [[756,16,34]] | B38: 756 | C38: 16 | D38: 40 | E38: 6 | F38: 58.45441651623696 | G38: 1 | H38: 1 | I38: # step=0 row=0 minW=757 found cw of W=138: [1 2 9 12 16 25 27 29 30 32 41 45 48 52 60 62 67 69 70 83 88 112 116 126 129 133 139 140 153 171 180 191 198 208 222 231 233 234 237 239 240 277 284 289 292 294 297 300 301 305 312 316 319 324 332 337 341 346 347 352 354 355 367 368 380 381 387 390 394 396 399 401 403 405 412 422 428 429 431 436 437 440 441 445 458 461 462 463 467 468 484 486 489 492 502 505 519 526 527 530 533 545 553 557 561 566 568 574 592 594 600 604 606 616 617 618 624 628 635 647 648 651 658 666 675 678 680 682 708 714 719 723 725 727 731 739 748 749]\n# step=0 row=3 minW=138 found cw of W=130: [2 5 9 15 16 18 25 27 30 32 35 36 39 41 46 48 52 53 62 67 69 75 79 80 88 93 94 112 115 116 135 136 142 145 148 155 167 179 191 198 199 200 203 207 214 222 239 251 255 264 270 277 283 284 291 294 300 301 319 324 327 328 332 338 341 346 355 358 360 373 380 381 390 394 399 400 401 403 404 405 412 414 417 426 431 433 437 458 461 463 465 467 485 502 508 515 519 549 552 553 556 602 607 609 612 617 620 624 629 632 646 648 651 656 658 685 686 688 705 710 714 718 723 727 731 739 748 751 753 755]\n# step=0 row=35 minW=130 found cw of W=126: [12 15 17 26 45 46 53 61 62 67 70 75 76 87 88 93 112 122 126 132 136 139 166 173 179 180 191 198 205 222 223 224 231 234 239 245 260 267 270 283 285 289 300 305 307 310 315 319 327 332 337 340 343 355 362 367 372 373 390 399 400 404 405 410 414 422 429 430 431 434 440 450 465 466 467 468 475 485 489 492 499 500 502 503 508 512 519 526 530 533 534 540 545 549 568 590 592 599 600 602 612 616 630 635 641 648 651 653 655 657 658 662 666 672 680 682 688 704 710 711 716 718 725 727 751 756]\n# step=0 row=67 minW=126 found cw of W=118: [2 9 12 16 25 26 27 29 30 36 41 46 47 48 52 60 61 69 80 83 85 88 91 112 129 133 135 137 139 140 144 153 179 180 191 198 208 215 223 251 270 285 290 291 300 310 319 321 332 346 350 352 355 360 380 400 401 403 410 414 430 431 434 437 440 445 461 462 463 466 467 468 485 486 489 502 505 512 522 527 530 534 545 553 568 570 571 583 592 594 602 612 619 620 629 632 635 637 648 651 656 658 660 682 685 686 688 705 719 723 725 727 728 746 748 753 754 755]\n# step=0 row=68 minW=118 found cw of W=112: [15 25 29 38 47 70 80 83 85 89 91 93 112 126 132 135 138 142 148 151 153 155 162 173 179 182 203 208 213 214 223 224 237 239 244 270 283 285 290 292 294 301 305 307 308 310 321 324 347 352 354 359 362 367 373 387 394 400 409 426 428 429 436 437 450 458 461 462 466 467 475 480 484 492 505 515 519 522 526 527 533 545 556 570 574 592 594 602 606 609 612 616 619 647 651 655 656 657 658 660 682 686 688 704 716 731 738 739 751 753 754 755]\n# step=0 row=98 minW=112 found cw of W=108: [15 25 29 38 47 70 80 83 85 91 93 112 126 132 133 135 142 148 151 153 155 162 173 195 203 208 213 214 224 237 239 270 283 290 292 294 301 305 307 308 310 321 324 347 352 354 359 362 367 373 387 394 400 409 426 428 429 436 437 450 458 461 462 466 475 480 484 492 505 515 519 526 527 533 545 556 566 570 574 592 594 602 606 609 612 616 617 619 628 647 651 655 656 657 658 660 682 686 688 704 716 731 738 739 751 753 754 755]\n# step=0 row=194 minW=108 found cw of W=88: [25 26 38 46 67 70 75 112 116 126 130 142 149 151 162 167 179 199 213 215 220 222 223 251 277 283 284 285 287 300 310 327 328 338 341 355 359 367 381 383 390 396 399 400 404 409 410 429 430 437 473 480 492 499 503 515 519 549 556 557 568 575 606 607 609 612 617 624 629 632 635 637 647 648 653 655 660 686 688 704 710 714 718 725 727 738 753 755]\n# step=0 row=308 minW=88 found cw of W=74: [12 15 18 25 46 61 80 83 132 135 145 167 173 198 200 207 220 222 251 255 283 287 308 310 319 338 341 359 368 426 430 433 434 440 445 461 475 486 489 500 505 530 545 549 556 568 575 590 605 606 607 612 613 617 624 629 635 646 647 653 654 656 658 660 662 678 686 695 711 714 725 727 736 753]\n# step=16 row=180 minW=74 found cw of W=66: [24 31 80 121 129 137 161 170 187 192 197 200 205 211 216 225 240 247 258 262 263 269 277 297 298 322 329 336 348 352 359 370 377 384 408 425 449 450 453 458 513 540 554 559 565 569 575 578 610 619 620 624 626 627 631 636 641 647 649 658 690 695 709 721 737 738]\n# step=26 row=97 minW=66 found cw of W=62: [3 14 24 49 69 70 84 113 114 127 139 168 175 194 199 202 212 224 229 237 254 298 302 319 337 360 386 397 413 421 435 448 457 462 470 471 476 482 487 497 505 531 537 546 552 566 567 586 587 590 597 602 607 621 634 645 662 692 701 715 731 750]\n# step=131 row=175 minW=62 found cw of W=58: [5 11 19 31 47 52 54 86 98 102 135 142 146 153 157 160 210 230 259 270 285 300 307 308 328 340 360 368 370 389 395 423 429 430 433 459 472 474 478 500 527 539 562 582 594 608 617 631 632 637 648 657 672 678 697 733 740 741]\n# round=1000 of 50000 minW=58\n# step=1577 row=307 minW=58 found cw of W=52: [36 47 137 141 151 158 175 177 178 202 206 218 219 222 230 233 257 261 264 267 268 273 280 284 321 339 347 383 394 402 409 437 443 450 466 469 473 480 484 504 519 527 555 568 596 599 604 609 610 653 725 754]\n# step=1577 row=333 minW=52 found cw of W=50: [36 47 137 141 151 158 175 178 202 206 218 219 222 230 233 257 261 264 268 273 275 280 284 316 321 339 347 383 394 402 409 437 443 450 466 469 473 480 484 504 519 527 568 596 609 653 659 666 725 754]\n# round=2000 of 50000 minW=50\n# round=3000 of 50000 minW=50\n# step=3781 row=231 minW=50 found cw of W=48: [100 155 161 162 167 189 198 200 205 208 216 235 242 272 283 339 362 373 388 442 451 491 518 532 539 541 545 558 576 578 584 586 600 612 625 640 641 649 650 666 676 682 689 702 712 725 730 739]\n# round=4000 of 50000 minW=48\n# round=5000 of 50000 minW=48\n# round=6000 of 50000 minW=48\n# round=7000 of 50000 minW=48\n# round=8000 of 50000 minW=48\n# round=9000 of 50000 minW=48\n# round=10000 of 50000 minW=48\n# round=11000 of 50000 minW=48\n# round=12000 of 50000 minW=48\n# round=13000 of 50000 minW=48\n# round=14000 of 50000 minW=48\n# round=15000 of 50000 minW=48\n# step=15126 row=126 minW=48 found cw of W=44: [7 14 18 29 55 66 73 117 121 153 165 172 176 179 202 231 236 275 286 292 303 337 341 346 352 359 382 393 413 416 423 503 531 552 586 614 621 669 704 711 724 730 732 737]\n# round=16000 of 50000 minW=44\n# round=17000 of 50000 minW=44\n# step=17865 row=311 minW=44 found cw of W=40: [8 22 25 29 36 185 240 246 247 252 289 290 297 302 325 336 344 359 399 465 466 489 514 515 555 564 579 605 613 624 630 645 646 674 675 694 720 729 736 743]\n# round=18000 of 50000 minW=40\n# round=19000 of 50000 minW=40\n# round=20000 of 50000 minW=40\n# round=21000 of 50000 minW=40\n# round=22000 of 50000 minW=40\n# round=23000 of 50000 minW=40\n# round=24000 of 50000 minW=40\n# round=25000 of 50000 minW=40\n# round=26000 of 50000 minW=40\n# round=27000 of 50000 minW=40\n# round=28000 of 50000 minW=40\n# round=29000 of 50000 minW=40\n# round=30000 of 50000 minW=40\n# round=31000 of 50000 minW=40\n# round=32000 of 50000 minW=40\n# round=33000 of 50000 minW=40\n# round=34000 of 50000 minW=40\n# round=35000 of 50000 minW=40\n# round=36000 of 50000 minW=40\n# round=37000 of 50000 minW=40\n# round=38000 of 50000 minW=40\n# round=39000 of 50000 minW=40\n# round=40000 of 50000 minW=40\n# round=41000 of 50000 minW=40\n# round=42000 of 50000 minW=40\n# round=43000 of 50000 minW=40\n# round=44000 of 50000 minW=40\n# round=45000 of 50000 minW=40\n# round=46000 of 50000 minW=40\n# round=47000 of 50000 minW=40\n# round=48000 of 50000 minW=40\n# round=49000 of 50000 minW=40\n# round=50000 of 50000 minW=40\nRW algorithm upper bound for the distance d=40\n
A39: [[216,8,10]] | B39: 216 | C39: 8 | D39: 10 | E39: 0 | F39: 3.2927756188437343 | G39: 1 | H39: 1 | I39: # step=0 row=1 minW=217 found cw of W=24: [2 4 6 8 14 16 24 36 46 54 56 70 86 94 100 112 116 130 136 150 154 172 176 206]\n# step=0 row=3 minW=24 found cw of W=22: [9 17 27 33 41 51 55 59 63 71 73 83 85 93 101 111 117 165 179 187 197 203]\n# step=0 row=6 minW=22 found cw of W=20: [6 12 14 24 26 50 78 86 100 126 130 134 136 168 172 176 182 188 210 212]\n# step=0 row=7 minW=20 found cw of W=16: [13 15 19 27 33 55 63 73 83 85 87 117 119 155 187 197]\n# step=0 row=37 minW=16 found cw of W=14: [6 26 36 64 72 78 84 86 134 168 170 182 198 206]\n# step=0 row=38 minW=14 found cw of W=10: [16 20 66 80 88 112 114 134 150 186]\n# round=1000 of 50000 minW=10\n# round=2000 of 50000 minW=10\n# round=3000 of 50000 minW=10\n# round=4000 of 50000 minW=10\n# round=5000 of 50000 minW=10\n# round=6000 of 50000 minW=10\n# round=7000 of 50000 minW=10\n# round=8000 of 50000 minW=10\n# round=9000 of 50000 minW=10\n# round=10000 of 50000 minW=10\n# round=11000 of 50000 minW=10\n# round=12000 of 50000 minW=10\n# round=13000 of 50000 minW=10\n# round=14000 of 50000 minW=10\n# round=15000 of 50000 minW=10\n# round=16000 of 50000 minW=10\n# round=17000 of 50000 minW=10\n# round=18000 of 50000 minW=10\n# round=19000 of 50000 minW=10\n# round=20000 of 50000 minW=10\n# round=21000 of 50000 minW=10\n# round=22000 of 50000 minW=10\n# round=23000 of 50000 minW=10\n# round=24000 of 50000 minW=10\n# round=25000 of 50000 minW=10\n# round=26000 of 50000 minW=10\n# round=27000 of 50000 minW=10\n# round=28000 of 50000 minW=10\n# round=29000 of 50000 minW=10\n# round=30000 of 50000 minW=10\n# round=31000 of 50000 minW=10\n# round=32000 of 50000 minW=10\n# round=33000 of 50000 minW=10\n# round=34000 of 50000 minW=10\n# round=35000 of 50000 minW=10\n# round=36000 of 50000 minW=10\n# round=37000 of 50000 minW=10\n# round=38000 of 50000 minW=10\n# round=39000 of 50000 minW=10\n# round=40000 of 50000 minW=10\n# round=41000 of 50000 minW=10\n# round=42000 of 50000 minW=10\n# round=43000 of 50000 minW=10\n# round=44000 of 50000 minW=10\n# round=45000 of 50000 minW=10\n# round=46000 of 50000 minW=10\n# round=47000 of 50000 minW=10\n# round=48000 of 50000 minW=10\n# round=49000 of 50000 minW=10\n# round=50000 of 50000 minW=10\nRW algorithm upper bound for the distance d=10\n
A40: [[576,8,24]] | B40: 576 | C40: 8 | D40: 24 | E40: 0 | F40: 31.007136520929635 | G40: 1 | H40: 1 | I40: # step=0 row=0 minW=577 found cw of W=122: [1 8 10 19 23 24 36 57 59 60 67 74 81 83 87 100 102 108 113 116 117 119 120 122 123 124 137 140 141 153 158 159 162 164 171 172 176 177 180 181 183 184 194 196 197 200 208 232 237 252 253 255 258 261 262 274 281 287 291 292 299 300 302 309 310 312 327 338 339 348 350 351 353 357 370 375 378 380 386 391 393 395 396 397 398 421 437 439 441 449 450 453 461 462 463 465 472 473 474 483 487 489 495 513 521 524 527 528 529 535 539 542 548 552 554 559 560 564 570 571 573 574]\n# step=0 row=1 minW=122 found cw of W=100: [2 3 4 7 8 10 18 19 23 40 50 57 62 67 78 81 87 91 97 101 102 113 116 122 124 137 138 140 141 153 155 158 164 171 172 176 177 179 181 196 197 199 200 253 255 258 261 272 274 281 287 289 291 293 300 310 327 331 333 338 353 356 357 359 375 391 393 396 397 398 399 400 404 414 420 421 424 449 472 473 483 487 488 500 504 508 513 524 527 542 548 552 553 554 559 560 564 570 571 574]\n# step=0 row=4 minW=100 found cw of W=86: [10 11 13 17 19 24 32 55 59 60 83 87 101 102 121 123 124 138 142 153 171 172 177 181 185 194 196 198 200 208 215 223 232 252 274 284 291 292 298 299 310 333 348 350 353 358 363 370 375 378 380 387 392 393 398 415 421 424 426 434 441 447 462 463 465 471 481 489 490 495 497 505 513 514 521 524 526 529 539 541 547 548 551 564 573 574]\n# step=0 row=5 minW=86 found cw of W=62: [3 7 8 12 13 17 19 23 32 36 50 57 71 74 87 91 97 100 101 121 124 145 148 172 194 199 202 218 230 259 284 298 300 310 327 331 338 344 356 360 361 391 397 402 415 421 447 449 471 473 487 500 504 511 513 521 537 540 550 551 561 571]\n# step=4 row=117 minW=62 found cw of W=40: [24 38 62 64 68 70 102 104 132 136 145 164 166 168 169 177 206 242 247 251 258 307 311 348 351 357 376 385 393 406 430 464 468 482 491 500 506 524 534 545]\n# step=5 row=74 minW=40 found cw of W=30: [7 54 64 68 72 102 106 150 154 166 180 204 244 252 294 298 341 353 387 389 420 490 502 514 526 535 536 538 560 562]\n# step=89 row=253 minW=30 found cw of W=28: [45 58 77 87 91 105 171 175 189 207 235 244 273 287 295 319 343 349 377 382 401 410 447 458 507 516 535 559]\n# step=191 row=120 minW=28 found cw of W=24: [18 54 70 156 160 164 168 242 244 248 252 256 258 260 264 295 309 349 434 444 458 468 498 522]\n# round=1000 of 50000 minW=24\n# round=2000 of 50000 minW=24\n# round=3000 of 50000 minW=24\n# round=4000 of 50000 minW=24\n# round=5000 of 50000 minW=24\n# round=6000 of 50000 minW=24\n# round=7000 of 50000 minW=24\n# round=8000 of 50000 minW=24\n# round=9000 of 50000 minW=24\n# round=10000 of 50000 minW=24\n# round=11000 of 50000 minW=24\n# round=12000 of 50000 minW=24\n# round=13000 of 50000 minW=24\n# round=14000 of 50000 minW=24\n# round=15000 of 50000 minW=24\n# round=16000 of 50000 minW=24\n# round=17000 of 50000 minW=24\n# round=18000 of 50000 minW=24\n# round=19000 of 50000 minW=24\n# round=20000 of 50000 minW=24\n# round=21000 of 50000 minW=24\n# round=22000 of 50000 minW=24\n# round=23000 of 50000 minW=24\n# round=24000 of 50000 minW=24\n# round=25000 of 50000 minW=24\n# round=26000 of 50000 minW=24\n# round=27000 of 50000 minW=24\n# round=28000 of 50000 minW=24\n# round=29000 of 50000 minW=24\n# round=30000 of 50000 minW=24\n# round=31000 of 50000 minW=24\n# round=32000 of 50000 minW=24\n# round=33000 of 50000 minW=24\n# round=34000 of 50000 minW=24\n# round=35000 of 50000 minW=24\n# round=36000 of 50000 minW=24\n# round=37000 of 50000 minW=24\n# round=38000 of 50000 minW=24\n# round=39000 of 50000 minW=24\n# round=40000 of 50000 minW=24\n# round=41000 of 50000 minW=24\n# round=42000 of 50000 minW=24\n# round=43000 of 50000 minW=24\n# round=44000 of 50000 minW=24\n# round=45000 of 50000 minW=24\n# round=46000 of 50000 minW=24\n# round=47000 of 50000 minW=24\n# round=48000 of 50000 minW=24\n# round=49000 of 50000 minW=24\n# round=50000 of 50000 minW=24\nRW algorithm upper bound for the distance d=24\n
