Workbook

Sheet analysis
A2: Default | C2: 1 | D2: 2 | E2: 9 | F2: 11 | G2: 10 | H2: 13 | I2: 12 | J2: 14 | K2: 16 | L2: 17 | M2: 15 | N2: 5 | O2: 4 | P2: 3 | Q2: 19 | R2: 7 | S2: 18 | T2: 8 | U2: 20 | V2: 6
C3: {=INDIRECT("Sheet"&C$2&"!a1")} -> runMode: serial | D3: {=INDIRECT("Sheet"&D$2&"!a1")} -> runMode: serial | E3: {=INDIRECT("Sheet"&E$2&"!a1")} -> runMode: serial | F3: {=INDIRECT("Sheet"&F$2&"!a1")} -> runMode: serial | G3: {=INDIRECT("Sheet"&G$2&"!a1")} -> runMode: serial | H3: {=INDIRECT("Sheet"&H$2&"!a1")} -> runMode: serial | I3: {=INDIRECT("Sheet"&I$2&"!a1")} -> runMode: serial | J3: {=INDIRECT("Sheet"&J$2&"!a1")} -> runMode: serial | K3: {=INDIRECT("Sheet"&K$2&"!a1")} -> runMode: serial | M3: {=INDIRECT("Sheet"&M$2&"!a1")} -> runMode: serial | N3: {=INDIRECT("Sheet"&N$2&"!a1")} -> runMode: serial | O3: {=INDIRECT("Sheet"&O$2&"!a1")} -> runMode: serial | P3: {=INDIRECT("Sheet"&P$2&"!a1")} -> runMode: serial | R3: {=INDIRECT("Sheet"&R$2&"!a1")} -> runMode: serial | T3: {=INDIRECT("Sheet"&T$2&"!a1")} -> runMode: serial | V3: {=INDIRECT("Sheet"&V$2&"!a1")} -> runMode: serial
C4: {=INDIRECT("Sheet"&C$2&"!a"&ROW($A4)-2)} -> maxCount: 10000 | D4: {=INDIRECT("Sheet"&D$2&"!a"&ROW($A4)-2)} -> maxCount: 10000 | E4: {=INDIRECT("Sheet"&E$2&"!a"&ROW($A4)-2)} -> maxCount: 10000 | F4: {=INDIRECT("Sheet"&F$2&"!a"&ROW($A4)-2)} -> maxCount: 10000 | G4: {=INDIRECT("Sheet"&G$2&"!a"&ROW($A4)-2)} -> maxCount: 10000 | H4: {=INDIRECT("Sheet"&H$2&"!a"&ROW($A4)-2)} -> maxCount: 10000 | I4: {=INDIRECT("Sheet"&I$2&"!a"&ROW($A4)-2)} -> maxCount: 10000 | J4: {=INDIRECT("Sheet"&J$2&"!a"&ROW($A4)-2)} -> maxCount: 10000 | K4: {=INDIRECT("Sheet"&K$2&"!a"&ROW($A4)-2)} -> maxCount: 10000 | M4: {=INDIRECT("Sheet"&M$2&"!a"&ROW($A4)-2)} -> maxCount: 10000 | N4: {=INDIRECT("Sheet"&N$2&"!a"&ROW($A4)-2)} -> maxCount: 10000 | O4: {=INDIRECT("Sheet"&O$2&"!a"&ROW($A4)-2)} -> maxCount: 10000 | P4: {=INDIRECT("Sheet"&P$2&"!a"&ROW($A4)-2)} -> maxCount: 10000 | R4: {=INDIRECT("Sheet"&R$2&"!a"&ROW($A4)-2)} -> maxCount: 10000 | T4: {=INDIRECT("Sheet"&T$2&"!a"&ROW($A4)-2)} -> maxCount: 10000 | V4: {=INDIRECT("Sheet"&V$2&"!a"&ROW($A4)-2)} -> maxCount: 10000
C5: {=INDIRECT("Sheet"&C$2&"!a"&ROW($A5)-2)} -> repeat: 1 | D5: {=INDIRECT("Sheet"&D$2&"!a"&ROW($A5)-2)} -> repeat: 1 | E5: {=INDIRECT("Sheet"&E$2&"!a"&ROW($A5)-2)} -> repeat: 1 | F5: {=INDIRECT("Sheet"&F$2&"!a"&ROW($A5)-2)} -> repeat: 1 | G5: {=INDIRECT("Sheet"&G$2&"!a"&ROW($A5)-2)} -> repeat: 1 | H5: {=INDIRECT("Sheet"&H$2&"!a"&ROW($A5)-2)} -> repeat: 1 | I5: {=INDIRECT("Sheet"&I$2&"!a"&ROW($A5)-2)} -> 0 | J5: {=INDIRECT("Sheet"&J$2&"!a"&ROW($A5)-2)} -> repeat: 1 | K5: {=INDIRECT("Sheet"&K$2&"!a"&ROW($A5)-2)} -> repeat: 1 | M5: {=INDIRECT("Sheet"&M$2&"!a"&ROW($A5)-2)} -> repeat: 1 | N5: {=INDIRECT("Sheet"&N$2&"!a"&ROW($A5)-2)} -> repeat: 1 | O5: {=INDIRECT("Sheet"&O$2&"!a"&ROW($A5)-2)} -> repeat: 1 | P5: {=INDIRECT("Sheet"&P$2&"!a"&ROW($A5)-2)} -> repeat: 1 | R5: {=INDIRECT("Sheet"&R$2&"!a"&ROW($A5)-2)} -> repeat: 1 | T5: {=INDIRECT("Sheet"&T$2&"!a"&ROW($A5)-2)} -> repeat: 1 | V5: {=INDIRECT("Sheet"&V$2&"!a"&ROW($A5)-2)} -> repeat: 1
C6: {=INDIRECT("Sheet"&C$2&"!a"&ROW($A6)-2)} -> dataset: codeTables | D6: {=INDIRECT("Sheet"&D$2&"!a"&ROW($A6)-2)} -> dataset: codeTables | E6: {=INDIRECT("Sheet"&E$2&"!a"&ROW($A6)-2)} -> dataset: codeTables | F6: {=INDIRECT("Sheet"&F$2&"!a"&ROW($A6)-2)} -> dataset: codeTables | G6: {=INDIRECT("Sheet"&G$2&"!a"&ROW($A6)-2)} -> dataset: codeTables | H6: {=INDIRECT("Sheet"&H$2&"!a"&ROW($A6)-2)} -> dataset: codeTables | I6: {=INDIRECT("Sheet"&I$2&"!a"&ROW($A6)-2)} -> dataset: codeTables | J6: {=INDIRECT("Sheet"&J$2&"!a"&ROW($A6)-2)} -> dataset: codeTables | K6: {=INDIRECT("Sheet"&K$2&"!a"&ROW($A6)-2)} -> dataset: codeTables | M6: {=INDIRECT("Sheet"&M$2&"!a"&ROW($A6)-2)} -> dataset: codeTables | N6: {=INDIRECT("Sheet"&N$2&"!a"&ROW($A6)-2)} -> dataset: codeTables | O6: {=INDIRECT("Sheet"&O$2&"!a"&ROW($A6)-2)} -> dataset: codeTables | P6: {=INDIRECT("Sheet"&P$2&"!a"&ROW($A6)-2)} -> dataset: codeTables | R6: {=INDIRECT("Sheet"&R$2&"!a"&ROW($A6)-2)} -> dataset: codeTables | T6: {=INDIRECT("Sheet"&T$2&"!a"&ROW($A6)-2)} -> dataset: codeTables | V6: {=INDIRECT("Sheet"&V$2&"!a"&ROW($A6)-2)} -> dataset: codeTables
C7: {=INDIRECT("Sheet"&C$2&"!a"&ROW($A7)-2)} -> datafile: QECC_sample.txt | D7: {=INDIRECT("Sheet"&D$2&"!a"&ROW($A7)-2)} -> datafile: QECC_sample.txt | E7: {=INDIRECT("Sheet"&E$2&"!a"&ROW($A7)-2)} -> datafile: QECC_sample.txt | F7: {=INDIRECT("Sheet"&F$2&"!a"&ROW($A7)-2)} -> datafile: QECC_sample.txt | G7: {=INDIRECT("Sheet"&G$2&"!a"&ROW($A7)-2)} -> datafile: QECC_sample.txt | H7: {=INDIRECT("Sheet"&H$2&"!a"&ROW($A7)-2)} -> datafile: QECC_sample.txt | I7: {=INDIRECT("Sheet"&I$2&"!a"&ROW($A7)-2)} -> datafile: QECC_sample.txt | J7: {=INDIRECT("Sheet"&J$2&"!a"&ROW($A7)-2)} -> datafile: QECC_sample.txt | K7: {=INDIRECT("Sheet"&K$2&"!a"&ROW($A7)-2)} -> datafile: QECC_sample.txt | M7: {=INDIRECT("Sheet"&M$2&"!a"&ROW($A7)-2)} -> datafile: QECC_sample.txt | N7: {=INDIRECT("Sheet"&N$2&"!a"&ROW($A7)-2)} -> datafile: QECC_sample.txt | O7: {=INDIRECT("Sheet"&O$2&"!a"&ROW($A7)-2)} -> datafile: QECC_sample.txt | P7: {=INDIRECT("Sheet"&P$2&"!a"&ROW($A7)-2)} -> datafile: QECC_sample.txt | R7: {=INDIRECT("Sheet"&R$2&"!a"&ROW($A7)-2)} -> datafile: QECC_sample.txt | T7: {=INDIRECT("Sheet"&T$2&"!a"&ROW($A7)-2)} -> datafile: QECC_sample.txt | V7: {=INDIRECT("Sheet"&V$2&"!a"&ROW($A7)-2)} -> datafile: QECC_sample.txt
A8: method: x | C8: {=INDIRECT("Sheet"&C$2&"!a"&ROW($A8)-2)} -> method: GurobiDist | D8: {=INDIRECT("Sheet"&D$2&"!a"&ROW($A8)-2)} -> method: GurobiDist | E8: {=INDIRECT("Sheet"&E$2&"!a"&ROW($A8)-2)} -> method: BZDistMW | F8: {=INDIRECT("Sheet"&F$2&"!a"&ROW($A8)-2)} -> method: BZDistMW | G8: {=INDIRECT("Sheet"&G$2&"!a"&ROW($A8)-2)} -> method: BZDistMW | H8: {=INDIRECT("Sheet"&H$2&"!a"&ROW($A8)-2)} -> method: dist_m4ri_CC | I8: {=INDIRECT("Sheet"&I$2&"!a"&ROW($A8)-2)} -> method: dist_m4ri_CC | J8: {=INDIRECT("Sheet"&J$2&"!a"&ROW($A8)-2)} -> method: dist_m4ri_RW | ... V8: {=INDIRECT("Sheet"&V$2&"!a"&ROW($A8)-2)} -> method: QDistRndMW
C9: {=INDIRECT("Sheet"&C$2&"!a"&ROW($A9)-2)} -> ignoreTrivialCodes: 1 | D9: {=INDIRECT("Sheet"&D$2&"!a"&ROW($A9)-2)} -> ignoreTrivialCodes: 1 | E9: {=INDIRECT("Sheet"&E$2&"!a"&ROW($A9)-2)} -> ignoreTrivialCodes: 1 | F9: {=INDIRECT("Sheet"&F$2&"!a"&ROW($A9)-2)} -> ignoreTrivialCodes: 1 | G9: {=INDIRECT("Sheet"&G$2&"!a"&ROW($A9)-2)} -> ignoreTrivialCodes: 1 | H9: {=INDIRECT("Sheet"&H$2&"!a"&ROW($A9)-2)} -> ignoreTrivialCodes: 1 | I9: {=INDIRECT("Sheet"&I$2&"!a"&ROW($A9)-2)} -> ignoreTrivialCodes: 1 | J9: {=INDIRECT("Sheet"&J$2&"!a"&ROW($A9)-2)} -> ignoreTrivialCodes: 1 | ... V9: {=INDIRECT("Sheet"&V$2&"!a"&ROW($A9)-2)} -> ignoreTrivialCodes: 1
C10: {=INDIRECT("Sheet"&C$2&"!a"&ROW($A10)-2)} -> resume: 0 | D10: {=INDIRECT("Sheet"&D$2&"!a"&ROW($A10)-2)} -> resume: 0 | E10: {=INDIRECT("Sheet"&E$2&"!a"&ROW($A10)-2)} -> resume: 0 | F10: {=INDIRECT("Sheet"&F$2&"!a"&ROW($A10)-2)} -> resume: 0 | G10: {=INDIRECT("Sheet"&G$2&"!a"&ROW($A10)-2)} -> resume: 0 | H10: {=INDIRECT("Sheet"&H$2&"!a"&ROW($A10)-2)} -> resume: 0 | I10: {=INDIRECT("Sheet"&I$2&"!a"&ROW($A10)-2)} -> resume: 0 | J10: {=INDIRECT("Sheet"&J$2&"!a"&ROW($A10)-2)} -> resume: 0 | ... V10: {=INDIRECT("Sheet"&V$2&"!a"&ROW($A10)-2)} -> resume: 0
C11: {=INDIRECT("Sheet"&C$2&"!a"&ROW($A11)-2)} -> nMin: 1 | D11: {=INDIRECT("Sheet"&D$2&"!a"&ROW($A11)-2)} -> nMin: 1 | E11: {=INDIRECT("Sheet"&E$2&"!a"&ROW($A11)-2)} -> nMin: 1 | F11: {=INDIRECT("Sheet"&F$2&"!a"&ROW($A11)-2)} -> nMin: 1 | G11: {=INDIRECT("Sheet"&G$2&"!a"&ROW($A11)-2)} -> nMin: 1 | H11: {=INDIRECT("Sheet"&H$2&"!a"&ROW($A11)-2)} -> nMin: 1 | I11: {=INDIRECT("Sheet"&I$2&"!a"&ROW($A11)-2)} -> 0 | J11: {=INDIRECT("Sheet"&J$2&"!a"&ROW($A11)-2)} -> nMin: 1 | ... V11: {=INDIRECT("Sheet"&V$2&"!a"&ROW($A11)-2)} -> nMin: 1
C12: {=INDIRECT("Sheet"&C$2&"!a"&ROW($A12)-2)} -> nMax: 100000 | D12: {=INDIRECT("Sheet"&D$2&"!a"&ROW($A12)-2)} -> nMax: 100000 | E12: {=INDIRECT("Sheet"&E$2&"!a"&ROW($A12)-2)} -> nMax: 100000 | F12: {=INDIRECT("Sheet"&F$2&"!a"&ROW($A12)-2)} -> nMax: 100000 | G12: {=INDIRECT("Sheet"&G$2&"!a"&ROW($A12)-2)} -> nMax: 100000 | H12: {=INDIRECT("Sheet"&H$2&"!a"&ROW($A12)-2)} -> nMax: 100000 | I12: {=INDIRECT("Sheet"&I$2&"!a"&ROW($A12)-2)} -> 0 | J12: {=INDIRECT("Sheet"&J$2&"!a"&ROW($A12)-2)} -> nMax: 100000 | ... V12: {=INDIRECT("Sheet"&V$2&"!a"&ROW($A12)-2)} -> nMax: 100000
C13: {=INDIRECT("Sheet"&C$2&"!a"&ROW($A13)-2)} -> iterCount: 10000 | D13: {=INDIRECT("Sheet"&D$2&"!a"&ROW($A13)-2)} -> iterCount: 10000 | E13: {=INDIRECT("Sheet"&E$2&"!a"&ROW($A13)-2)} -> iterCount: 10000 | F13: {=INDIRECT("Sheet"&F$2&"!a"&ROW($A13)-2)} -> iterCount: 10000 | G13: {=INDIRECT("Sheet"&G$2&"!a"&ROW($A13)-2)} -> iterCount: 10000 | H13: {=INDIRECT("Sheet"&H$2&"!a"&ROW($A13)-2)} -> iterCount: 10000 | I13: {=INDIRECT("Sheet"&I$2&"!a"&ROW($A13)-2)} -> iterCount: 10000 | J13: {=INDIRECT("Sheet"&J$2&"!a"&ROW($A13)-2)} -> iterCount: 10000 | ... V13: {=INDIRECT("Sheet"&V$2&"!a"&ROW($A13)-2)} -> iterCount: 10000
C14: {=INDIRECT("Sheet"&C$2&"!a"&ROW($A14)-2)} -> maxTime: 28800 | D14: {=INDIRECT("Sheet"&D$2&"!a"&ROW($A14)-2)} -> maxTime: 28800 | E14: {=INDIRECT("Sheet"&E$2&"!a"&ROW($A14)-2)} -> maxTime: 28800 | F14: {=INDIRECT("Sheet"&F$2&"!a"&ROW($A14)-2)} -> maxTime: 28800 | G14: {=INDIRECT("Sheet"&G$2&"!a"&ROW($A14)-2)} -> maxTime: 28800 | H14: {=INDIRECT("Sheet"&H$2&"!a"&ROW($A14)-2)} -> maxTime: 28800 | I14: {=INDIRECT("Sheet"&I$2&"!a"&ROW($A14)-2)} -> maxTime: 28800 | J14: {=INDIRECT("Sheet"&J$2&"!a"&ROW($A14)-2)} -> maxTime: 28800 | ... V14: {=INDIRECT("Sheet"&V$2&"!a"&ROW($A14)-2)} -> maxTime: 28800
C15: {=INDIRECT("Sheet"&C$2&"!a"&ROW($A15)-2)} -> nThreads: 1 | D15: {=INDIRECT("Sheet"&D$2&"!a"&ROW($A15)-2)} -> nThreads: 1 | E15: {=INDIRECT("Sheet"&E$2&"!a"&ROW($A15)-2)} -> nThreads: 1 | F15: {=INDIRECT("Sheet"&F$2&"!a"&ROW($A15)-2)} -> nThreads: 1 | G15: {=INDIRECT("Sheet"&G$2&"!a"&ROW($A15)-2)} -> nThreads: 1 | H15: {=INDIRECT("Sheet"&H$2&"!a"&ROW($A15)-2)} -> nThreads: 1 | I15: {=INDIRECT("Sheet"&I$2&"!a"&ROW($A15)-2)} -> nThreads: 1 | J15: {=INDIRECT("Sheet"&J$2&"!a"&ROW($A15)-2)} -> nThreads: 1 | ... V15: {=INDIRECT("Sheet"&V$2&"!a"&ROW($A15)-2)} -> nThreads: 1
C16: {=INDIRECT("Sheet"&C$2&"!a"&ROW($A16)-2)} -> verbose: False | D16: {=INDIRECT("Sheet"&D$2&"!a"&ROW($A16)-2)} -> verbose: False | E16: {=INDIRECT("Sheet"&E$2&"!a"&ROW($A16)-2)} -> verbose: False | F16: {=INDIRECT("Sheet"&F$2&"!a"&ROW($A16)-2)} -> verbose: False | G16: {=INDIRECT("Sheet"&G$2&"!a"&ROW($A16)-2)} -> verbose: False | H16: {=INDIRECT("Sheet"&H$2&"!a"&ROW($A16)-2)} -> verbose: False | I16: {=INDIRECT("Sheet"&I$2&"!a"&ROW($A16)-2)} -> verbose: False | J16: {=INDIRECT("Sheet"&J$2&"!a"&ROW($A16)-2)} -> verbose: False | ... V16: {=INDIRECT("Sheet"&V$2&"!a"&ROW($A16)-2)} -> verbose: False
C17: {=INDIRECT("Sheet"&C$2&"!a"&ROW($A17)-2)} -> maxErr: -1 | D17: {=INDIRECT("Sheet"&D$2&"!a"&ROW($A17)-2)} -> maxErr: -1 | E17: {=INDIRECT("Sheet"&E$2&"!a"&ROW($A17)-2)} -> maxErr: -1 | F17: {=INDIRECT("Sheet"&F$2&"!a"&ROW($A17)-2)} -> maxErr: -1 | G17: {=INDIRECT("Sheet"&G$2&"!a"&ROW($A17)-2)} -> maxErr: -1 | H17: {=INDIRECT("Sheet"&H$2&"!a"&ROW($A17)-2)} -> maxErr: -1 | I17: {=INDIRECT("Sheet"&I$2&"!a"&ROW($A17)-2)} -> maxErr: -1 | J17: {=INDIRECT("Sheet"&J$2&"!a"&ROW($A17)-2)} -> maxErr: -1 | ... V17: {=INDIRECT("Sheet"&V$2&"!a"&ROW($A17)-2)} -> maxErr: -1
A18: GF4blockRep: x | C18: {=INDIRECT("Sheet"&C$2&"!a"&ROW($A18)-2)} -> GF4blockRep: 2 | D18: {=INDIRECT("Sheet"&D$2&"!a"&ROW($A18)-2)} -> GF4blockRep: 3 | E18: {=INDIRECT("Sheet"&E$2&"!a"&ROW($A18)-2)} -> GF4blockRep: 2 | F18: {=INDIRECT("Sheet"&F$2&"!a"&ROW($A18)-2)} -> GF4blockRep: 3 | G18: {=INDIRECT("Sheet"&G$2&"!a"&ROW($A18)-2)} -> GF4blockRep: 4 | H18: {=INDIRECT("Sheet"&H$2&"!a"&ROW($A18)-2)} -> GF4blockRep: 3 | I18: {=INDIRECT("Sheet"&I$2&"!a"&ROW($A18)-2)} -> GF4blockRep: 4 | J18: {=INDIRECT("Sheet"&J$2&"!a"&ROW($A18)-2)} -> GF4blockRep: 3 | ... V18: {=INDIRECT("Sheet"&V$2&"!a"&ROW($A18)-2)} -> GF4blockRep: 4
A19: regroupPerm: 1 | C19: {=INDIRECT("Sheet"&C$2&"!a"&ROW($A19)-2)} -> regroupPerm: 1 | D19: {=INDIRECT("Sheet"&D$2&"!a"&ROW($A19)-2)} -> regroupPerm: 1 | E19: {=INDIRECT("Sheet"&E$2&"!a"&ROW($A19)-2)} -> regroupPerm: 1 | F19: {=INDIRECT("Sheet"&F$2&"!a"&ROW($A19)-2)} -> regroupPerm: 1 | G19: {=INDIRECT("Sheet"&G$2&"!a"&ROW($A19)-2)} -> regroupPerm: 1 | H19: {=INDIRECT("Sheet"&H$2&"!a"&ROW($A19)-2)} -> regroupPerm: 1 | I19: {=INDIRECT("Sheet"&I$2&"!a"&ROW($A19)-2)} -> 0 | J19: {=INDIRECT("Sheet"&J$2&"!a"&ROW($A19)-2)} -> regroupPerm: 1 | ... V19: {=INDIRECT("Sheet"&V$2&"!a"&ROW($A19)-2)} -> regroupPerm: 1
A20: filterCircuit: 1 | C20: {=INDIRECT("Sheet"&C$2&"!a"&ROW($A20)-2)} -> filterCircuit: 1 | D20: {=INDIRECT("Sheet"&D$2&"!a"&ROW($A20)-2)} -> filterCircuit: 1 | E20: {=INDIRECT("Sheet"&E$2&"!a"&ROW($A20)-2)} -> filterCircuit: 1 | F20: {=INDIRECT("Sheet"&F$2&"!a"&ROW($A20)-2)} -> filterCircuit: 1 | G20: {=INDIRECT("Sheet"&G$2&"!a"&ROW($A20)-2)} -> filterCircuit: 1 | H20: {=INDIRECT("Sheet"&H$2&"!a"&ROW($A20)-2)} -> filterCircuit: 1 | I20: {=INDIRECT("Sheet"&I$2&"!a"&ROW($A20)-2)} -> filterCircuit: 1 | J20: {=INDIRECT("Sheet"&J$2&"!a"&ROW($A20)-2)} -> filterCircuit: 1 | ... V20: {=INDIRECT("Sheet"&V$2&"!a"&ROW($A20)-2)} -> filterCircuit: 1
A21: HL: 0 | C21: {=INDIRECT("Sheet"&C$2&"!a"&ROW($A21)-2)} -> HL: 0 | D21: {=INDIRECT("Sheet"&D$2&"!a"&ROW($A21)-2)} -> HL: 0 | E21: {=INDIRECT("Sheet"&E$2&"!a"&ROW($A21)-2)} -> HL: 0 | F21: {=INDIRECT("Sheet"&F$2&"!a"&ROW($A21)-2)} -> HL: 0 | G21: {=INDIRECT("Sheet"&G$2&"!a"&ROW($A21)-2)} -> HL: 0 | H21: {=INDIRECT("Sheet"&H$2&"!a"&ROW($A21)-2)} -> HL: 0 | I21: {=INDIRECT("Sheet"&I$2&"!a"&ROW($A21)-2)} -> HL: 0 | J21: {=INDIRECT("Sheet"&J$2&"!a"&ROW($A21)-2)} -> HL: 0 | ... V21: {=INDIRECT("Sheet"&V$2&"!a"&ROW($A21)-2)} -> HL: 0
A22: genCount: 100 | C22: {=INDIRECT("Sheet"&C$2&"!a"&ROW($A22)-2)} -> genCount: 100 | D22: {=INDIRECT("Sheet"&D$2&"!a"&ROW($A22)-2)} -> genCount: 100 | E22: {=INDIRECT("Sheet"&E$2&"!a"&ROW($A22)-2)} -> genCount: 100 | F22: {=INDIRECT("Sheet"&F$2&"!a"&ROW($A22)-2)} -> genCount: 100 | G22: {=INDIRECT("Sheet"&G$2&"!a"&ROW($A22)-2)} -> genCount: 100 | H22: {=INDIRECT("Sheet"&H$2&"!a"&ROW($A22)-2)} -> genCount: 100 | I22: {=INDIRECT("Sheet"&I$2&"!a"&ROW($A22)-2)} -> popSize: 100 | J22: {=INDIRECT("Sheet"&J$2&"!a"&ROW($A22)-2)} -> genCount: 100 | ... V22: {=INDIRECT("Sheet"&V$2&"!a"&ROW($A22)-2)} -> genCount: 100
A23: offspring: 10 | C23: {=INDIRECT("Sheet"&C$2&"!a"&ROW($A23)-2)} -> offspring: 10 | D23: {=INDIRECT("Sheet"&D$2&"!a"&ROW($A23)-2)} -> offspring: 10 | E23: {=INDIRECT("Sheet"&E$2&"!a"&ROW($A23)-2)} -> offspring: 10 | F23: {=INDIRECT("Sheet"&F$2&"!a"&ROW($A23)-2)} -> offspring: 10 | G23: {=INDIRECT("Sheet"&G$2&"!a"&ROW($A23)-2)} -> offspring: 10 | H23: {=INDIRECT("Sheet"&H$2&"!a"&ROW($A23)-2)} -> offspring: 10 | I23: {=INDIRECT("Sheet"&I$2&"!a"&ROW($A23)-2)} -> offspring: 10 | J23: {=INDIRECT("Sheet"&J$2&"!a"&ROW($A23)-2)} -> offspring: 10 | ... V23: {=INDIRECT("Sheet"&V$2&"!a"&ROW($A23)-2)} -> offspring: 10
A24: pMut: 6.0 | C24: {=INDIRECT("Sheet"&C$2&"!a"&ROW($A24)-2)} -> pMut: 8.0 | D24: {=INDIRECT("Sheet"&D$2&"!a"&ROW($A24)-2)} -> pMut: 8.0 | E24: {=INDIRECT("Sheet"&E$2&"!a"&ROW($A24)-2)} -> pMut: 6.0 | F24: {=INDIRECT("Sheet"&F$2&"!a"&ROW($A24)-2)} -> pMut: 6.0 | G24: {=INDIRECT("Sheet"&G$2&"!a"&ROW($A24)-2)} -> pMut: 6.0 | H24: {=INDIRECT("Sheet"&H$2&"!a"&ROW($A24)-2)} -> pMut: 2.0 | I24: {=INDIRECT("Sheet"&I$2&"!a"&ROW($A24)-2)} -> 0 | J24: {=INDIRECT("Sheet"&J$2&"!a"&ROW($A24)-2)} -> pMut: 8.0 | ... V24: {=INDIRECT("Sheet"&V$2&"!a"&ROW($A24)-2)} -> pMut: 6.0
A25: sMut: 0.2 | C25: {=INDIRECT("Sheet"&C$2&"!a"&ROW($A25)-2)} -> sMut: 0.2 | D25: {=INDIRECT("Sheet"&D$2&"!a"&ROW($A25)-2)} -> sMut: 0.2 | E25: {=INDIRECT("Sheet"&E$2&"!a"&ROW($A25)-2)} -> sMut: 0.2 | F25: {=INDIRECT("Sheet"&F$2&"!a"&ROW($A25)-2)} -> sMut: 0.2 | G25: {=INDIRECT("Sheet"&G$2&"!a"&ROW($A25)-2)} -> sMut: 0.2 | H25: {=INDIRECT("Sheet"&H$2&"!a"&ROW($A25)-2)} -> sMut: 1.0 | I25: {=INDIRECT("Sheet"&I$2&"!a"&ROW($A25)-2)} -> 0 | J25: {=INDIRECT("Sheet"&J$2&"!a"&ROW($A25)-2)} -> sMut: 0.2 | ... V25: {=INDIRECT("Sheet"&V$2&"!a"&ROW($A25)-2)} -> sMut: 0.2
A26: tabuLength: 0 | C26: {=INDIRECT("Sheet"&C$2&"!a"&ROW($A26)-2)} -> tabuLength: 0 | D26: {=INDIRECT("Sheet"&D$2&"!a"&ROW($A26)-2)} -> tabuLength: 0 | E26: {=INDIRECT("Sheet"&E$2&"!a"&ROW($A26)-2)} -> tabuLength: 0 | F26: {=INDIRECT("Sheet"&F$2&"!a"&ROW($A26)-2)} -> tabuLength: 0 | G26: {=INDIRECT("Sheet"&G$2&"!a"&ROW($A26)-2)} -> tabuLength: 0 | H26: {=INDIRECT("Sheet"&H$2&"!a"&ROW($A26)-2)} -> CCstart: -1 | I26: {=INDIRECT("Sheet"&I$2&"!a"&ROW($A26)-2)} -> 0 | J26: {=INDIRECT("Sheet"&J$2&"!a"&ROW($A26)-2)} -> tabuLength: 0 | ... V26: {=INDIRECT("Sheet"&V$2&"!a"&ROW($A26)-2)} -> tabuLength: 0
A27: swapPivot: 1 | C27: {=INDIRECT("Sheet"&C$2&"!a"&ROW($A27)-2)} -> swapPivot: 1 | D27: {=INDIRECT("Sheet"&D$2&"!a"&ROW($A27)-2)} -> swapPivot: 1 | E27: {=INDIRECT("Sheet"&E$2&"!a"&ROW($A27)-2)} -> swapPivot: 1 | F27: {=INDIRECT("Sheet"&F$2&"!a"&ROW($A27)-2)} -> swapPivot: 1 | G27: {=INDIRECT("Sheet"&G$2&"!a"&ROW($A27)-2)} -> swapPivot: 1 | H27: {=INDIRECT("Sheet"&H$2&"!a"&ROW($A27)-2)} -> addStabs: 0 | I27: {=INDIRECT("Sheet"&I$2&"!a"&ROW($A27)-2)} -> 0 | J27: {=INDIRECT("Sheet"&J$2&"!a"&ROW($A27)-2)} -> swapPivot: 1 | ... V27: {=INDIRECT("Sheet"&V$2&"!a"&ROW($A27)-2)} -> swapPivot: 1
C28: {=INDIRECT("Sheet"&C$2&"!a"&ROW($A28)-2)} -> swapBlockorder: 0 | D28: {=INDIRECT("Sheet"&D$2&"!a"&ROW($A28)-2)} -> swapBlockorder: 0 | E28: {=INDIRECT("Sheet"&E$2&"!a"&ROW($A28)-2)} -> swapBlockorder: 0 | F28: {=INDIRECT("Sheet"&F$2&"!a"&ROW($A28)-2)} -> swapBlockorder: 0 | G28: {=INDIRECT("Sheet"&G$2&"!a"&ROW($A28)-2)} -> swapBlockorder: 0 | H28: {=INDIRECT("Sheet"&H$2&"!a"&ROW($A28)-2)} -> outfile: /home/ucapmwe/dist-benchmark/results/codeTables-QECC_sample.txt-dist_m4ri_CC-20260203_135026.787691_85062422.txt | I28: {=INDIRECT("Sheet"&I$2&"!a"&ROW($A28)-2)} -> outfile: /home/ucapmwe/dist-benchmark/results/codeTables-QECC_sample.txt-dist_m4ri_CC-20260107_140325.395673_85062422.txt | J28: {=INDIRECT("Sheet"&J$2&"!a"&ROW($A28)-2)} -> swapBlockorder: 0 | ... V28: {=INDIRECT("Sheet"&V$2&"!a"&ROW($A28)-2)} -> swapBlockorder: 0
C29: {=INDIRECT("Sheet"&C$2&"!a"&ROW($A29)-2)} -> CCstart: -1 | D29: {=INDIRECT("Sheet"&D$2&"!a"&ROW($A29)-2)} -> CCstart: -1 | E29: {=INDIRECT("Sheet"&E$2&"!a"&ROW($A29)-2)} -> CCstart: -1 | F29: {=INDIRECT("Sheet"&F$2&"!a"&ROW($A29)-2)} -> CCstart: -1 | G29: {=INDIRECT("Sheet"&G$2&"!a"&ROW($A29)-2)} -> CCstart: -1 | H29: {=INDIRECT("Sheet"&H$2&"!a"&ROW($A29)-2)} -> ######################################### | I29: {=INDIRECT("Sheet"&I$2&"!a"&ROW($A29)-2)} -> ######################################### | J29: {=INDIRECT("Sheet"&J$2&"!a"&ROW($A29)-2)} -> CCstart: -1 | ... V29: {=INDIRECT("Sheet"&V$2&"!a"&ROW($A29)-2)} -> CCstart: -1
A31: =LEFT(A8,FIND(":",A8)) -> method: | B31: =LEN(A31)+1 -> 8 | C31: =IF(C8=$A8,"",RIGHT(C8,LEN(C8)-$B31)) -> GurobiDist | D31: =IF(D8=$A8,"",RIGHT(D8,LEN(D8)-$B31)) -> GurobiDist | E31: =IF(E8=$A8,"",RIGHT(E8,LEN(E8)-$B31)) -> BZDistMW | F31: =IF(F8=$A8,"",RIGHT(F8,LEN(F8)-$B31)) -> BZDistMW | G31: =IF(G8=$A8,"",RIGHT(G8,LEN(G8)-$B31)) -> BZDistMW | H31: =IF(H8=$A8,"",RIGHT(H8,LEN(H8)-$B31)) -> dist_m4ri_CC | I31: =IF(I8=$A8,"",RIGHT(I8,LEN(I8)-$B31)) -> dist_m4ri_CC | J31: =IF(J8=$A8,"",RIGHT(J8,LEN(J8)-$B31)) -> dist_m4ri_RW | ... V31: =IF(V8=$A8,"",RIGHT(V8,LEN(V8)-$B31)) -> QDistRndMW
A32: =LEFT(A18,FIND(":",A18)) -> GF4blockRep: | B32: =LEN(A32)+1 -> 13 | C32: =IF(C18=$A18,"",RIGHT(C18,LEN(C18)-$B32)*1) -> 2 | D32: =IF(D18=$A18,"",RIGHT(D18,LEN(D18)-$B32)*1) -> 3 | E32: =IF(E18=$A18,"",RIGHT(E18,LEN(E18)-$B32)*1) -> 2 | F32: =IF(F18=$A18,"",RIGHT(F18,LEN(F18)-$B32)*1) -> 3 | G32: =IF(G18=$A18,"",RIGHT(G18,LEN(G18)-$B32)*1) -> 4 | H32: =IF(H18=$A18,"",RIGHT(H18,LEN(H18)-$B32)*1) -> 3 | I32: =IF(I18=$A18,"",RIGHT(I18,LEN(I18)-$B32)*1) -> 4 | J32: =IF(J18=$A18,"",RIGHT(J18,LEN(J18)-$B32)*1) -> 3 | ... V32: =IF(V18=$A18,"",RIGHT(V18,LEN(V18)-$B32)*1) -> 4
A33: =LEFT(A19,FIND(":",A19)) -> regroupPerm: | B33: =LEN(A33)+1 -> 13 | C33: =IF(C19=$A19,"",RIGHT(C19,LEN(C19)-$B33)*1) | D33: =IF(D19=$A19,"",RIGHT(D19,LEN(D19)-$B33)*1) | E33: =IF(E19=$A19,"",RIGHT(E19,LEN(E19)-$B33)*1) | F33: =IF(F19=$A19,"",RIGHT(F19,LEN(F19)-$B33)*1) | G33: =IF(G19=$A19,"",RIGHT(G19,LEN(G19)-$B33)*1) | J33: =IF(J19=$A19,"",RIGHT(J19,LEN(J19)-$B33)*1) | K33: =IF(K19=$A19,"",RIGHT(K19,LEN(K19)-$B33)*1) | L33: =IF(L19=$A19,"",RIGHT(L19,LEN(L19)-$B33)*1) | M33: =IF(M19=$A19,"",RIGHT(M19,LEN(M19)-$B33)*1) | N33: =IF(N19=$A19,"",RIGHT(N19,LEN(N19)-$B33)*1) | O33: =IF(O19=$A19,"",RIGHT(O19,LEN(O19)-$B33)*1) | P33: =IF(P19=$A19,"",RIGHT(P19,LEN(P19)-$B33)*1) | Q33: =IF(Q19=$A19,"",RIGHT(Q19,LEN(Q19)-$B33)*1) -> 0 | ... V33: =IF(V19=$A19,"",RIGHT(V19,LEN(V19)-$B33)*1)
A34: count | C34: =COUNTIF(O49:O169,">0") -> 51 | D34: =COUNTIF(P49:P169,">0") -> 43 | E34: =COUNTIF(H49:H169,">0") -> 44 | F34: =COUNTIF(I49:I169,">0") -> 49 | G34: =COUNTIF(J49:J169,">0") -> 49 | H34: =COUNTIF(K49:K169,">0") -> 33 | I34: =COUNTIF(L49:L169,">0") -> 14 | J34: =COUNTIF(M49:M169,">0") -> 121 | K34: =COUNTIF(C49:C169,">0") -> 121 | L34: =COUNTIF(D49:D169,">0") -> 121 | M34: =COUNTIF(N49:N169,">0") -> 121 | N34: =COUNTIF(Q49:Q169,">0") -> 121 | O34: =COUNTIF(R49:R169,">0") -> 121 | P34: =COUNTIF(S49:S169,">0") -> 121 | Q34: =COUNTIF(T49:T169,">0") -> 121 | R34: =COUNTIF(U49:U169,">0") -> 121 | S34: =COUNTIF(V49:V169,">0") -> 121 | T34: =COUNTIF(W49:W169,">0") -> 121 | U34: =COUNTIF(X49:X169,">0") -> 121 | V34: =COUNTIF(Y49:Y169,">0") -> 121
A35: dTot | C35: =SUM(O49:O169) -> 331 | D35: =SUM(P49:P169) -> 257 | E35: =SUM(H49:H169) -> 266 | F35: =SUM(I49:I169) -> 309 | G35: =SUM(J49:J169) -> 310 | H35: =SUM(K49:K169) -> 163 | I35: =SUM(L49:L169) -> 48 | J35: =SUM(M49:M169) -> 1505 | K35: =SUM(C49:C169) -> 1511 | L35: =SUM(D49:D169) -> 1513 | M35: =SUM(N49:N169) -> 1493 | N35: =SUM(Q49:Q169) -> 1481 | O35: =SUM(R49:R169) -> 1480 | P35: =SUM(S49:S169) -> 1480 | Q35: =SUM(T49:T169) -> 1508 | R35: =SUM(U49:U169) -> 1474 | S35: =SUM(V49:V169) -> 1503 | T35: =SUM(W49:W169) -> 1481 | U35: =SUM(X49:X169) -> 1499 | V35: =SUM(Y49:Y169) -> 1472
A36: dTot Actual | C36: =SUMIF(O$49:O$169,">0",$F$49:$F$169) -> 331 | D36: =SUMIF(P$49:P$169,">0",$F$49:$F$169) -> 257 | E36: =SUMIF(H$49:H$169,">0",$F$49:$F$169) -> 266 | F36: =SUMIF(I$49:I$169,">0",$F$49:$F$169) -> 309 | G36: =SUMIF(J$49:J$169,">0",$F$49:$F$169) -> 309 | H36: =SUMIF(K$49:K$169,">0",$F$49:$F$169) -> 163 | I36: =SUMIF(L$49:L$169,">0",$F$49:$F$169) -> 48 | J36: =SUMIF(M$49:M$169,">0",$F$49:$F$169) -> 1466 | K36: =SUMIF(C$49:C$169,">0",$F$49:$F$169) -> 1466 | L36: =SUMIF(D$49:D$169,">0",$F$49:$F$169) -> 1466 | M36: =SUMIF(N$49:N$169,">0",$F$49:$F$169) -> 1466 | N36: =SUMIF(Q$49:Q$169,">0",$F$49:$F$169) -> 1466 | O36: =SUMIF(R$49:R$169,">0",$F$49:$F$169) -> 1466 | P36: =SUMIF(S$49:S$169,">0",$F$49:$F$169) -> 1466 | Q36: =SUMIF(T$49:T$169,">0",$F$49:$F$169) -> 1466 | R36: =SUMIF(U$49:U$169,">0",$F$49:$F$169) -> 1466 | S36: =SUMIF(V$49:V$169,">0",$F$49:$F$169) -> 1466 | T36: =SUMIF(W$49:W$169,">0",$F$49:$F$169) -> 1466 | U36: =SUMIF(X$49:X$169,">0",$F$49:$F$169) -> 1466 | V36: =SUMIF(Y$49:Y$169,">0",$F$49:$F$169) -> 1466
A37: delta d | C37: =(C35-C36) -> 0 | D37: =(D35-D36) -> 0 | E37: =(E35-E36) -> 0 | F37: =(F35-F36) -> 0 | G37: =(G35-G36) -> 1 | H37: =(H35-H36) -> 0 | I37: =(I35-I36) -> 0 | J37: =(J35-J36) -> 39 | ... V37: =(V35-V36) -> 6
A38: delta d Avg | C38: =C37/C36 -> 0 | D38: =D37/D36 -> 0 | E38: =E37/E36 -> 0 | F38: =F37/F36 -> 0 | G38: =G37/G36 -> 0.003236246 | H38: =H37/H36 -> 0 | I38: =I37/I36 -> 0 | J38: =J37/J36 -> 0.026603001 | ... V38: =V37/V36 -> 0.0040927694
A39: processing time | C39: =SUM(AK49:AK169) -> 143552.61 | D39: =SUM(AL49:AL169) -> 90319.877 | E39: =SUM(AB49:AB169) -> 94506.103 | F39: =SUM(AC49:AC169) -> 32630.694 | G39: =SUM(AD49:AD169) -> 47862.477 | H39: =SUM(AE49:AE169) -> 1325022 | I39: =SUM(AF49:AF169) -> 1850176.3 | J39: =SUM(AG49:AG169) -> 146.6416 | K39: =SUM(AH49:AH169) -> 129.90131 | L39: =SUM(AI49:AI169) -> 129.85665 | M39: =SUM(AJ49:AJ169) -> 208.53508 | N39: =SUM(AM49:AM169) -> 1438.3752 | O39: =SUM(AN49:AN169) -> 2584.8158 | P39: =SUM(AO49:AO169) -> 4151.2178 | Q39: =SUM(AP49:AP169) -> 1006.473 | R39: =SUM(AQ49:AQ169) -> 1306.9914 | S39: =SUM(AR49:AR169) -> 2365.5888 | T39: =SUM(AS49:AS169) -> 2452.3667 | U39: =SUM(AT49:AT169) -> 3572.9461 | V39: =SUM(AU49:AU169) -> 3926.8898
B48: n | E48: k | F48: dActual | G48: offset | H48: dMin | AB48: time | AX48: R
A49: =Sheet3!A33 -> [[3,1,1]] | B49: 3 | C49: {=OFFSET(INDIRECT("Sheet"&K$2&"!d1"),$G49-1,)} -> 1 | D49: {=OFFSET(INDIRECT("Sheet"&L$2&"!d1"),$G49-1,)} -> 1 | E49: 1 | F49: 1 | G49: 33 | H49: {=OFFSET(INDIRECT("Sheet"&E$2&"!d1"),$G49-1,)} -> 1 | I49: {=OFFSET(INDIRECT("Sheet"&F$2&"!d1"),$G49-1,)} -> 1 | J49: {=OFFSET(INDIRECT("Sheet"&G$2&"!d1"),$G49-1,)} -> 1 | K49: {=OFFSET(INDIRECT("Sheet"&H$2&"!d1"),$G49-1,)} -> 1 | L49: {=OFFSET(INDIRECT("Sheet"&I$2&"!d1"),$G49-1,)} -> 1 | M49: {=OFFSET(INDIRECT("Sheet"&J$2&"!d1"),$G49-1,)} -> 1 | N49: {=OFFSET(INDIRECT("Sheet"&M$2&"!d1"),$G49-1,)} -> 1 | O49: {=OFFSET(INDIRECT("Sheet"&C$2&"!d1"),$G49-1,)} -> 1 | P49: {=OFFSET(INDIRECT("Sheet"&D$2&"!d1"),$G49-1,)} -> 1 | Q49: {=OFFSET(INDIRECT("Sheet"&N$2&"!d1"),$G49-1,)} -> 1 | R49: {=OFFSET(INDIRECT("Sheet"&O$2&"!d1"),$G49-1,)} -> 1 | S49: {=OFFSET(INDIRECT("Sheet"&P$2&"!d1"),$G49-1,)} -> 1 | T49: {=OFFSET(INDIRECT("Sheet"&Q$2&"!d1"),$G49-1,)} -> 1 | U49: {=OFFSET(INDIRECT("Sheet"&R$2&"!d1"),$G49-1,)} -> 1 | V49: {=OFFSET(INDIRECT("Sheet"&S$2&"!d1"),$G49-1,)} -> 1 | W49: {=OFFSET(INDIRECT("Sheet"&T$2&"!d1"),$G49-1,)} -> 1 | X49: {=OFFSET(INDIRECT("Sheet"&U$2&"!d1"),$G49-1,)} -> 1 | Y49: {=OFFSET(INDIRECT("Sheet"&V$2&"!d1"),$G49-1,)} -> 1 | AB49: {=OFFSET(INDIRECT("Sheet"&E$2&"!f1"),$G49-1,)} -> 0.0023525115 | AC49: {=OFFSET(INDIRECT("Sheet"&F$2&"!f1"),$G49-1,)} -> 0.0020386642 | AD49: {=OFFSET(INDIRECT("Sheet"&G$2&"!f1"),$G49-1,)} -> 0.0021212352 | AE49: {=OFFSET(INDIRECT("Sheet"&H$2&"!f1"),$G49-1,)} -> 0.020189436 | AF49: {=OFFSET(INDIRECT("Sheet"&I$2&"!f1"),$G49-1,)} -> 0.12274851 | AG49: {=OFFSET(INDIRECT("Sheet"&J$2&"!f1"),$G49-1,)} -> 0.14657406 | AH49: {=OFFSET(INDIRECT("Sheet"&K$2&"!f1"),$G49-1,)} -> 0.23518173 | AI49: {=OFFSET(INDIRECT("Sheet"&L$2&"!f1"),$G49-1,)} -> 0.23527895 | AJ49: {=OFFSET(INDIRECT("Sheet"&M$2&"!f1"),$G49-1,)} -> 0.15588869 | AK49: {=OFFSET(INDIRECT("Sheet"&C$2&"!f1"),$G49-1,)} -> 0.39045962 | AL49: {=OFFSET(INDIRECT("Sheet"&D$2&"!f1"),$G49-1,)} -> 0.21553472 | AM49: {=OFFSET(INDIRECT("Sheet"&N$2&"!f1"),$G49-1,)} -> 1.8435296 | AN49: {=OFFSET(INDIRECT("Sheet"&O$2&"!f1"),$G49-1,)} -> 1.601399 | AO49: {=OFFSET(INDIRECT("Sheet"&P$2&"!f1"),$G49-1,)} -> 1.779852 | AP49: {=OFFSET(INDIRECT("Sheet"&Q$2&"!f1"),$G49-1,)} -> 0.65199387 | AQ49: {=OFFSET(INDIRECT("Sheet"&R$2&"!f1"),$G49-1,)} -> 0.9625604 | AR49: {=OFFSET(INDIRECT("Sheet"&S$2&"!f1"),$G49-1,)} -> 0.70681783 | AS49: {=OFFSET(INDIRECT("Sheet"&T$2&"!f1"),$G49-1,)} -> 1.0375478 | AT49: {=OFFSET(INDIRECT("Sheet"&U$2&"!f1"),$G49-1,)} -> 0.75857067 | AU49: {=OFFSET(INDIRECT("Sheet"&V$2&"!f1"),$G49-1,)} -> 1.1251608 | AX49: =IF(H49=$F49,1,0) -> 1 | AY49: =IF(I49=$F49,1,0) -> 1 | AZ49: =IF(J49=$F49,1,0) -> 1 | BA49: =IF(K49=$F49,1,0) -> 1 | BB49: =IF(L49=$F49,1,0) -> 1 | BC49: =IF(M49=$F49,1,0) -> 1 | BD49: =IF(C49=$F49,1,0) -> 1 | BE49: =IF(D49=$F49,1,0) -> 1 | BF49: =IF(N49=$F49,1,0) -> 1 | BG49: =IF(O49=$F49,1,0) -> 1 | BH49: =IF(P49=$F49,1,0) -> 1 | BI49: =IF(Q49=$F49,1,0) -> 1 | BJ49: =IF(R49=$F49,1,0) -> 1 | BK49: =IF(S49=$F49,1,0) -> 1 | BL49: =IF(T49=$F49,1,0) -> 1 | BM49: =IF(U49=$F49,1,0) -> 1 | ... BQ49: =IF(Y49=$F49,1,0) -> 1
A50: =Sheet3!A34 -> [[4,1,2]] | B50: 4 | C50: {=OFFSET(INDIRECT("Sheet"&K$2&"!d1"),$G50-1,)} -> 2 | D50: {=OFFSET(INDIRECT("Sheet"&L$2&"!d1"),$G50-1,)} -> 2 | E50: 1 | F50: 2 | G50: =G49+1 -> 34 | H50: {=OFFSET(INDIRECT("Sheet"&E$2&"!d1"),$G50-1,)} -> 2 | I50: {=OFFSET(INDIRECT("Sheet"&F$2&"!d1"),$G50-1,)} -> 2 | J50: {=OFFSET(INDIRECT("Sheet"&G$2&"!d1"),$G50-1,)} -> 2 | K50: {=OFFSET(INDIRECT("Sheet"&H$2&"!d1"),$G50-1,)} -> 2 | L50: {=OFFSET(INDIRECT("Sheet"&I$2&"!d1"),$G50-1,)} -> 2 | M50: {=OFFSET(INDIRECT("Sheet"&J$2&"!d1"),$G50-1,)} -> 2 | N50: {=OFFSET(INDIRECT("Sheet"&M$2&"!d1"),$G50-1,)} -> 2 | O50: {=OFFSET(INDIRECT("Sheet"&C$2&"!d1"),$G50-1,)} -> 2 | P50: {=OFFSET(INDIRECT("Sheet"&D$2&"!d1"),$G50-1,)} -> 2 | Q50: {=OFFSET(INDIRECT("Sheet"&N$2&"!d1"),$G50-1,)} -> 2 | R50: {=OFFSET(INDIRECT("Sheet"&O$2&"!d1"),$G50-1,)} -> 2 | S50: {=OFFSET(INDIRECT("Sheet"&P$2&"!d1"),$G50-1,)} -> 2 | T50: {=OFFSET(INDIRECT("Sheet"&Q$2&"!d1"),$G50-1,)} -> 2 | U50: {=OFFSET(INDIRECT("Sheet"&R$2&"!d1"),$G50-1,)} -> 2 | V50: {=OFFSET(INDIRECT("Sheet"&S$2&"!d1"),$G50-1,)} -> 2 | W50: {=OFFSET(INDIRECT("Sheet"&T$2&"!d1"),$G50-1,)} -> 2 | X50: {=OFFSET(INDIRECT("Sheet"&U$2&"!d1"),$G50-1,)} -> 2 | Y50: {=OFFSET(INDIRECT("Sheet"&V$2&"!d1"),$G50-1,)} -> 2 | AB50: {=OFFSET(INDIRECT("Sheet"&E$2&"!f1"),$G50-1,)} -> 0.0022834716 | AC50: {=OFFSET(INDIRECT("Sheet"&F$2&"!f1"),$G50-1,)} -> 0.0024125641 | AD50: {=OFFSET(INDIRECT("Sheet"&G$2&"!f1"),$G50-1,)} -> 0.0024783537 | AE50: {=OFFSET(INDIRECT("Sheet"&H$2&"!f1"),$G50-1,)} -> 0.014716212 | AF50: {=OFFSET(INDIRECT("Sheet"&I$2&"!f1"),$G50-1,)} -> 0.076097789 | AG50: {=OFFSET(INDIRECT("Sheet"&J$2&"!f1"),$G50-1,)} -> 0.022678964 | AH50: {=OFFSET(INDIRECT("Sheet"&K$2&"!f1"),$G50-1,)} -> 0.021372838 | AI50: {=OFFSET(INDIRECT("Sheet"&L$2&"!f1"),$G50-1,)} -> 0.021631127 | AJ50: {=OFFSET(INDIRECT("Sheet"&M$2&"!f1"),$G50-1,)} -> 0.024490772 | AK50: {=OFFSET(INDIRECT("Sheet"&C$2&"!f1"),$G50-1,)} -> 0.023931606 | AL50: {=OFFSET(INDIRECT("Sheet"&D$2&"!f1"),$G50-1,)} -> 0.024412269 | AM50: {=OFFSET(INDIRECT("Sheet"&N$2&"!f1"),$G50-1,)} -> 1.9342992 | AN50: {=OFFSET(INDIRECT("Sheet"&O$2&"!f1"),$G50-1,)} -> 1.730892 | AO50: {=OFFSET(INDIRECT("Sheet"&P$2&"!f1"),$G50-1,)} -> 1.9598941 | AP50: {=OFFSET(INDIRECT("Sheet"&Q$2&"!f1"),$G50-1,)} -> 0.70980944 | AQ50: {=OFFSET(INDIRECT("Sheet"&R$2&"!f1"),$G50-1,)} -> 1.0637384 | AR50: {=OFFSET(INDIRECT("Sheet"&S$2&"!f1"),$G50-1,)} -> 0.78430194 | AS50: {=OFFSET(INDIRECT("Sheet"&T$2&"!f1"),$G50-1,)} -> 1.1694715 | AT50: {=OFFSET(INDIRECT("Sheet"&U$2&"!f1"),$G50-1,)} -> 0.88872979 | AU50: {=OFFSET(INDIRECT("Sheet"&V$2&"!f1"),$G50-1,)} -> 1.3240071 | AX50: =IF(H50=$F50,1,0) -> 1 | AY50: =IF(I50=$F50,1,0) -> 1 | AZ50: =IF(J50=$F50,1,0) -> 1 | BA50: =IF(K50=$F50,1,0) -> 1 | BB50: =IF(L50=$F50,1,0) -> 1 | BC50: =IF(M50=$F50,1,0) -> 1 | BD50: =IF(C50=$F50,1,0) -> 1 | BE50: =IF(D50=$F50,1,0) -> 1 | BF50: =IF(N50=$F50,1,0) -> 1 | BG50: =IF(O50=$F50,1,0) -> 1 | BH50: =IF(P50=$F50,1,0) -> 1 | BI50: =IF(Q50=$F50,1,0) -> 1 | BJ50: =IF(R50=$F50,1,0) -> 1 | BK50: =IF(S50=$F50,1,0) -> 1 | BL50: =IF(T50=$F50,1,0) -> 1 | BM50: =IF(U50=$F50,1,0) -> 1 | ... BQ50: =IF(Y50=$F50,1,0) -> 1
...

Sheet charts
B1: Match | K1: Time | U1: Time Adj
A2: Sheet | B2: 1 | C2: 2 | D2: 9 | E2: 11 | F2: 10 | G2: 13 | H2: 12
A3: Method | B3: GurobiDist | C3: GurobiDist | D3: BZDistMW | E3: BZDistMW | F3: BZDistMW | G3: dist_m4ri_CC | H3: dist_m4ri_CC | I3: Magma | K3: GurobiDist | L3: GurobiDist | M3: BZDistMW | N3: BZDistMW | O3: BZDistMW | P3: dist_m4ri_CC | Q3: dist_m4ri_CC | R3: Magma | AD3: Gurobi
A4: GF4BlockEncoding | B4: 2 | C4: 3 | D4: 2 | E4: 3 | F4: 4 | G4: 3 | H4: 4 | I4: 2 | T4: n | U4: =B3&" "&B4&" Block" -> GurobiDist 2 Block | V4: =C3&" "&C4&" Block" -> GurobiDist 3 Block | W4: =D3&" "&D4&" Block" -> BZDistMW 2 Block | X4: =E3&" "&E4&" Block" -> BZDistMW 3 Block | Y4: =F3&" "&F4&" Block" -> BZDistMW 4 Block | Z4: =G3&" "&G4&" Block" -> dist_m4ri_CC 3 Block | AA4: =H3&" "&H4&" Block" -> dist_m4ri_CC 4 Block | AB4: =I3&" "&I4&" Block" -> Magma 2 Block
A5: =Sheet1!A33 -> [[3,1,1]] | B5: =MATCH($A5,INDIRECT("Sheet"&B$2&"!A:A"),) -> 33 | C5: =MATCH($A5,INDIRECT("Sheet"&C$2&"!A:A"),) -> 33 | D5: =MATCH($A5,INDIRECT("Sheet"&D$2&"!A:A"),) -> 33 | E5: =MATCH($A5,INDIRECT("Sheet"&E$2&"!A:A"),) -> 33 | F5: =MATCH($A5,INDIRECT("Sheet"&F$2&"!A:A"),) -> 33 | G5: =MATCH($A5,INDIRECT("Sheet"&G$2&"!A:A"),) -> 33 | H5: =MATCH($A5,INDIRECT("Sheet"&H$2&"!A:A"),) -> 33 | I5: =MATCH($A5,magma!A:A,) -> 28 | K5: {=OFFSET(INDIRECT("Sheet"&B$2&"!f1"),B5-1,)} -> 0.39045962 | L5: {=OFFSET(INDIRECT("Sheet"&C$2&"!f1"),C5-1,)} -> 0.21553472 | M5: {=OFFSET(INDIRECT("Sheet"&D$2&"!f1"),D5-1,)} -> 0.0023525115 | N5: {=OFFSET(INDIRECT("Sheet"&E$2&"!f1"),E5-1,)} -> 0.0020386642 | O5: {=OFFSET(INDIRECT("Sheet"&F$2&"!f1"),F5-1,)} -> 0.0021212352 | P5: {=OFFSET(INDIRECT("Sheet"&G$2&"!f1"),G5-1,)} -> 0.020189436 | Q5: {=OFFSET(INDIRECT("Sheet"&H$2&"!f1"),H5-1,)} -> 0.12274851 | R5: =OFFSET(magma!$F$1,I5-1,)*1 -> 0.86791575 | T5: =Sheet1!B33 -> 3 | U5: =IF(AND(K5>0,K5<28800),K5,NA()) -> 0.39045962 | V5: =IF(AND(L5>0,L5<28800),L5,NA()) -> 0.21553472 | W5: =IF(AND(M5>0,M5<28800),M5,NA()) -> 0.0023525115 | X5: =IF(AND(N5>0,N5<28800),N5,NA()) -> 0.0020386642 | Y5: =IF(AND(O5>0,O5<28800),O5,NA()) -> 0.0021212352 | Z5: =IF(AND(P5>0,P5<28800),P5,NA()) -> 0.020189436 | AA5: =IF(AND(Q5>0,Q5<28800),Q5,NA()) -> 0.12274851 | AB5: =IF(AND(R5>0,R5<28800),R5,NA()) -> 0.86791575
A6: =Sheet1!A34 -> [[4,1,2]] | B6: =MATCH($A6,INDIRECT("Sheet"&B$2&"!A:A"),) -> 34 | C6: =MATCH($A6,INDIRECT("Sheet"&C$2&"!A:A"),) -> 34 | D6: =MATCH($A6,INDIRECT("Sheet"&D$2&"!A:A"),) -> 34 | E6: =MATCH($A6,INDIRECT("Sheet"&E$2&"!A:A"),) -> 34 | F6: =MATCH($A6,INDIRECT("Sheet"&F$2&"!A:A"),) -> 34 | G6: =MATCH($A6,INDIRECT("Sheet"&G$2&"!A:A"),) -> 34 | H6: =MATCH($A6,INDIRECT("Sheet"&H$2&"!A:A"),) -> 34 | I6: =MATCH($A6,magma!A:A,) -> 29 | K6: {=OFFSET(INDIRECT("Sheet"&B$2&"!f1"),B6-1,)} -> 0.023931606 | L6: {=OFFSET(INDIRECT("Sheet"&C$2&"!f1"),C6-1,)} -> 0.024412269 | M6: {=OFFSET(INDIRECT("Sheet"&D$2&"!f1"),D6-1,)} -> 0.0022834716 | N6: {=OFFSET(INDIRECT("Sheet"&E$2&"!f1"),E6-1,)} -> 0.0024125641 | O6: {=OFFSET(INDIRECT("Sheet"&F$2&"!f1"),F6-1,)} -> 0.0024783537 | P6: {=OFFSET(INDIRECT("Sheet"&G$2&"!f1"),G6-1,)} -> 0.014716212 | Q6: {=OFFSET(INDIRECT("Sheet"&H$2&"!f1"),H6-1,)} -> 0.076097789 | R6: =OFFSET(magma!$F$1,I6-1,)*1 -> 0.057046084 | T6: =Sheet1!B34 -> 4 | U6: =IF(AND(K6>0,K6<28800),K6,NA()) -> 0.023931606 | V6: =IF(AND(L6>0,L6<28800),L6,NA()) -> 0.024412269 | W6: =IF(AND(M6>0,M6<28800),M6,NA()) -> 0.0022834716 | X6: =IF(AND(N6>0,N6<28800),N6,NA()) -> 0.0024125641 | Y6: =IF(AND(O6>0,O6<28800),O6,NA()) -> 0.0024783537 | Z6: =IF(AND(P6>0,P6<28800),P6,NA()) -> 0.014716212 | AA6: =IF(AND(Q6>0,Q6<28800),Q6,NA()) -> 0.076097789 | AB6: =IF(AND(R6>0,R6<28800),R6,NA()) -> 0.057046084
A7: =Sheet1!A35 -> [[5,1,3]] | B7: =MATCH($A7,INDIRECT("Sheet"&B$2&"!A:A"),) -> 35 | C7: =MATCH($A7,INDIRECT("Sheet"&C$2&"!A:A"),) -> 35 | D7: =MATCH($A7,INDIRECT("Sheet"&D$2&"!A:A"),) -> 35 | E7: =MATCH($A7,INDIRECT("Sheet"&E$2&"!A:A"),) -> 35 | F7: =MATCH($A7,INDIRECT("Sheet"&F$2&"!A:A"),) -> 35 | G7: =MATCH($A7,INDIRECT("Sheet"&G$2&"!A:A"),) -> 35 | H7: =MATCH($A7,INDIRECT("Sheet"&H$2&"!A:A"),) -> 35 | I7: =MATCH($A7,magma!A:A,) -> 30 | K7: {=OFFSET(INDIRECT("Sheet"&B$2&"!f1"),B7-1,)} -> 0.043407256 | L7: {=OFFSET(INDIRECT("Sheet"&C$2&"!f1"),C7-1,)} -> 0.044245872 | M7: {=OFFSET(INDIRECT("Sheet"&D$2&"!f1"),D7-1,)} -> 0.0027798004 | N7: {=OFFSET(INDIRECT("Sheet"&E$2&"!f1"),E7-1,)} -> 0.0025062477 | O7: {=OFFSET(INDIRECT("Sheet"&F$2&"!f1"),F7-1,)} -> 0.0027241353 | P7: {=OFFSET(INDIRECT("Sheet"&G$2&"!f1"),G7-1,)} -> 0.016103351 | Q7: {=OFFSET(INDIRECT("Sheet"&H$2&"!f1"),H7-1,)} -> 0.077310103 | R7: =OFFSET(magma!$F$1,I7-1,)*1 -> 0.057239333 | T7: =Sheet1!B35 -> 5 | U7: =IF(AND(K7>0,K7<28800),K7,NA()) -> 0.043407256 | V7: =IF(AND(L7>0,L7<28800),L7,NA()) -> 0.044245872 | W7: =IF(AND(M7>0,M7<28800),M7,NA()) -> 0.0027798004 | X7: =IF(AND(N7>0,N7<28800),N7,NA()) -> 0.0025062477 | Y7: =IF(AND(O7>0,O7<28800),O7,NA()) -> 0.0027241353 | Z7: =IF(AND(P7>0,P7<28800),P7,NA()) -> 0.016103351 | AA7: =IF(AND(Q7>0,Q7<28800),Q7,NA()) -> 0.077310103 | AB7: =IF(AND(R7>0,R7<28800),R7,NA()) -> 0.057239333
A8: =Sheet1!A36 -> [[6,1,3]] | B8: =MATCH($A8,INDIRECT("Sheet"&B$2&"!A:A"),) -> 36 | C8: =MATCH($A8,INDIRECT("Sheet"&C$2&"!A:A"),) -> 36 | D8: =MATCH($A8,INDIRECT("Sheet"&D$2&"!A:A"),) -> 36 | E8: =MATCH($A8,INDIRECT("Sheet"&E$2&"!A:A"),) -> 36 | F8: =MATCH($A8,INDIRECT("Sheet"&F$2&"!A:A"),) -> 36 | G8: =MATCH($A8,INDIRECT("Sheet"&G$2&"!A:A"),) -> 36 | H8: =MATCH($A8,INDIRECT("Sheet"&H$2&"!A:A"),) -> 36 | I8: =MATCH($A8,magma!A:A,) -> 31 | K8: {=OFFSET(INDIRECT("Sheet"&B$2&"!f1"),B8-1,)} -> 0.033346392 | L8: {=OFFSET(INDIRECT("Sheet"&C$2&"!f1"),C8-1,)} -> 0.034327878 | M8: {=OFFSET(INDIRECT("Sheet"&D$2&"!f1"),D8-1,)} -> 0.0029675681 | N8: {=OFFSET(INDIRECT("Sheet"&E$2&"!f1"),E8-1,)} -> 0.0027871896 | O8: {=OFFSET(INDIRECT("Sheet"&F$2&"!f1"),F8-1,)} -> 0.0028956905 | P8: {=OFFSET(INDIRECT("Sheet"&G$2&"!f1"),G8-1,)} -> 0.014352234 | Q8: {=OFFSET(INDIRECT("Sheet"&H$2&"!f1"),H8-1,)} -> 0.064857103 | R8: =OFFSET(magma!$F$1,I8-1,)*1 -> 0.057163917 | T8: =Sheet1!B36 -> 6 | U8: =IF(AND(K8>0,K8<28800),K8,NA()) -> 0.033346392 | V8: =IF(AND(L8>0,L8<28800),L8,NA()) -> 0.034327878 | W8: =IF(AND(M8>0,M8<28800),M8,NA()) -> 0.0029675681 | X8: =IF(AND(N8>0,N8<28800),N8,NA()) -> 0.0027871896 | Y8: =IF(AND(O8>0,O8<28800),O8,NA()) -> 0.0028956905 | Z8: =IF(AND(P8>0,P8<28800),P8,NA()) -> 0.014352234 | AA8: =IF(AND(Q8>0,Q8<28800),Q8,NA()) -> 0.064857103 | AB8: =IF(AND(R8>0,R8<28800),R8,NA()) -> 0.057163917
A9: =Sheet1!A37 -> [[7,1,3]] | B9: =MATCH($A9,INDIRECT("Sheet"&B$2&"!A:A"),) -> 37 | C9: =MATCH($A9,INDIRECT("Sheet"&C$2&"!A:A"),) -> 37 | D9: =MATCH($A9,INDIRECT("Sheet"&D$2&"!A:A"),) -> 37 | E9: =MATCH($A9,INDIRECT("Sheet"&E$2&"!A:A"),) -> 37 | F9: =MATCH($A9,INDIRECT("Sheet"&F$2&"!A:A"),) -> 37 | G9: =MATCH($A9,INDIRECT("Sheet"&G$2&"!A:A"),) -> 37 | H9: =MATCH($A9,INDIRECT("Sheet"&H$2&"!A:A"),) -> 37 | I9: =MATCH($A9,magma!A:A,) -> 32 | K9: {=OFFSET(INDIRECT("Sheet"&B$2&"!f1"),B9-1,)} -> 0.033478545 | L9: {=OFFSET(INDIRECT("Sheet"&C$2&"!f1"),C9-1,)} -> 0.033910339 | M9: {=OFFSET(INDIRECT("Sheet"&D$2&"!f1"),D9-1,)} -> 0.0030723251 | N9: {=OFFSET(INDIRECT("Sheet"&E$2&"!f1"),E9-1,)} -> 0.0031640138 | O9: {=OFFSET(INDIRECT("Sheet"&F$2&"!f1"),F9-1,)} -> 0.0032005841 | P9: {=OFFSET(INDIRECT("Sheet"&G$2&"!f1"),G9-1,)} -> 0.017970439 | Q9: {=OFFSET(INDIRECT("Sheet"&H$2&"!f1"),H9-1,)} -> 0.042328706 | R9: =OFFSET(magma!$F$1,I9-1,)*1 -> 0.055149333 | T9: =Sheet1!B37 -> 7 | U9: =IF(AND(K9>0,K9<28800),K9,NA()) -> 0.033478545 | V9: =IF(AND(L9>0,L9<28800),L9,NA()) -> 0.033910339 | W9: =IF(AND(M9>0,M9<28800),M9,NA()) -> 0.0030723251 | X9: =IF(AND(N9>0,N9<28800),N9,NA()) -> 0.0031640138 | Y9: =IF(AND(O9>0,O9<28800),O9,NA()) -> 0.0032005841 | Z9: =IF(AND(P9>0,P9<28800),P9,NA()) -> 0.017970439 | AA9: =IF(AND(Q9>0,Q9<28800),Q9,NA()) -> 0.042328706 | AB9: =IF(AND(R9>0,R9<28800),R9,NA()) -> 0.055149333
A10: =Sheet1!A38 -> [[8,1,3]] | B10: =MATCH($A10,INDIRECT("Sheet"&B$2&"!A:A"),) -> 38 | C10: =MATCH($A10,INDIRECT("Sheet"&C$2&"!A:A"),) -> 38 | D10: =MATCH($A10,INDIRECT("Sheet"&D$2&"!A:A"),) -> 38 | E10: =MATCH($A10,INDIRECT("Sheet"&E$2&"!A:A"),) -> 38 | F10: =MATCH($A10,INDIRECT("Sheet"&F$2&"!A:A"),) -> 38 | G10: =MATCH($A10,INDIRECT("Sheet"&G$2&"!A:A"),) -> 38 | H10: =MATCH($A10,INDIRECT("Sheet"&H$2&"!A:A"),) -> 38 | I10: =MATCH($A10,magma!A:A,) -> 33 | K10: {=OFFSET(INDIRECT("Sheet"&B$2&"!f1"),B10-1,)} -> 0.033332959 | L10: {=OFFSET(INDIRECT("Sheet"&C$2&"!f1"),C10-1,)} -> 0.034905137 | M10: {=OFFSET(INDIRECT("Sheet"&D$2&"!f1"),D10-1,)} -> 0.0031412924 | N10: {=OFFSET(INDIRECT("Sheet"&E$2&"!f1"),E10-1,)} -> 0.0031682951 | O10: {=OFFSET(INDIRECT("Sheet"&F$2&"!f1"),F10-1,)} -> 0.0035904888 | P10: {=OFFSET(INDIRECT("Sheet"&G$2&"!f1"),G10-1,)} -> 0.07468291 | Q10: {=OFFSET(INDIRECT("Sheet"&H$2&"!f1"),H10-1,)} -> 0.022826961 | R10: =OFFSET(magma!$F$1,I10-1,)*1 -> 0.0527205 | T10: =Sheet1!B38 -> 8 | U10: =IF(AND(K10>0,K10<28800),K10,NA()) -> 0.033332959 | V10: =IF(AND(L10>0,L10<28800),L10,NA()) -> 0.034905137 | W10: =IF(AND(M10>0,M10<28800),M10,NA()) -> 0.0031412924 | X10: =IF(AND(N10>0,N10<28800),N10,NA()) -> 0.0031682951 | Y10: =IF(AND(O10>0,O10<28800),O10,NA()) -> 0.0035904888 | Z10: =IF(AND(P10>0,P10<28800),P10,NA()) -> 0.07468291 | AA10: =IF(AND(Q10>0,Q10<28800),Q10,NA()) -> 0.022826961 | AB10: =IF(AND(R10>0,R10<28800),R10,NA()) -> 0.0527205
A11: =Sheet1!A39 -> [[9,1,3]] | B11: =MATCH($A11,INDIRECT("Sheet"&B$2&"!A:A"),) -> 39 | C11: =MATCH($A11,INDIRECT("Sheet"&C$2&"!A:A"),) -> 39 | D11: =MATCH($A11,INDIRECT("Sheet"&D$2&"!A:A"),) -> 39 | E11: =MATCH($A11,INDIRECT("Sheet"&E$2&"!A:A"),) -> 39 | F11: =MATCH($A11,INDIRECT("Sheet"&F$2&"!A:A"),) -> 39 | G11: =MATCH($A11,INDIRECT("Sheet"&G$2&"!A:A"),) -> 39 | H11: =MATCH($A11,INDIRECT("Sheet"&H$2&"!A:A"),) -> 39 | I11: =MATCH($A11,magma!A:A,) -> 34 | K11: {=OFFSET(INDIRECT("Sheet"&B$2&"!f1"),B11-1,)} -> 0.033219593 | L11: {=OFFSET(INDIRECT("Sheet"&C$2&"!f1"),C11-1,)} -> 0.034337542 | M11: {=OFFSET(INDIRECT("Sheet"&D$2&"!f1"),D11-1,)} -> 0.0033542551 | N11: {=OFFSET(INDIRECT("Sheet"&E$2&"!f1"),E11-1,)} -> 0.0033251988 | O11: {=OFFSET(INDIRECT("Sheet"&F$2&"!f1"),F11-1,)} -> 0.0035833623 | P11: {=OFFSET(INDIRECT("Sheet"&G$2&"!f1"),G11-1,)} -> 0.013759532 | Q11: {=OFFSET(INDIRECT("Sheet"&H$2&"!f1"),H11-1,)} -> 0.025137001 | R11: =OFFSET(magma!$F$1,I11-1,)*1 -> 0.052406625 | T11: =Sheet1!B39 -> 9 | U11: =IF(AND(K11>0,K11<28800),K11,NA()) -> 0.033219593 | V11: =IF(AND(L11>0,L11<28800),L11,NA()) -> 0.034337542 | W11: =IF(AND(M11>0,M11<28800),M11,NA()) -> 0.0033542551 | X11: =IF(AND(N11>0,N11<28800),N11,NA()) -> 0.0033251988 | Y11: =IF(AND(O11>0,O11<28800),O11,NA()) -> 0.0035833623 | Z11: =IF(AND(P11>0,P11<28800),P11,NA()) -> 0.013759532 | AA11: =IF(AND(Q11>0,Q11<28800),Q11,NA()) -> 0.025137001 | AB11: =IF(AND(R11>0,R11<28800),R11,NA()) -> 0.052406625
A12: =Sheet1!A40 -> [[10,1,4]] | B12: =MATCH($A12,INDIRECT("Sheet"&B$2&"!A:A"),) -> 40 | C12: =MATCH($A12,INDIRECT("Sheet"&C$2&"!A:A"),) -> 40 | D12: =MATCH($A12,INDIRECT("Sheet"&D$2&"!A:A"),) -> 40 | E12: =MATCH($A12,INDIRECT("Sheet"&E$2&"!A:A"),) -> 40 | F12: =MATCH($A12,INDIRECT("Sheet"&F$2&"!A:A"),) -> 40 | G12: =MATCH($A12,INDIRECT("Sheet"&G$2&"!A:A"),) -> 40 | H12: =MATCH($A12,INDIRECT("Sheet"&H$2&"!A:A"),) -> 40 | I12: =MATCH($A12,magma!A:A,) -> 35 | K12: {=OFFSET(INDIRECT("Sheet"&B$2&"!f1"),B12-1,)} -> 0.063495385 | L12: {=OFFSET(INDIRECT("Sheet"&C$2&"!f1"),C12-1,)} -> 0.064393464 | M12: {=OFFSET(INDIRECT("Sheet"&D$2&"!f1"),D12-1,)} -> 0.0040917462 | N12: {=OFFSET(INDIRECT("Sheet"&E$2&"!f1"),E12-1,)} -> 0.0043107951 | O12: {=OFFSET(INDIRECT("Sheet"&F$2&"!f1"),F12-1,)} -> 0.0045743091 | P12: {=OFFSET(INDIRECT("Sheet"&G$2&"!f1"),G12-1,)} -> 0.014279019 | Q12: {=OFFSET(INDIRECT("Sheet"&H$2&"!f1"),H12-1,)} -> 1.2007472 | R12: =OFFSET(magma!$F$1,I12-1,)*1 -> 0.052589167 | T12: =Sheet1!B40 -> 10 | U12: =IF(AND(K12>0,K12<28800),K12,NA()) -> 0.063495385 | V12: =IF(AND(L12>0,L12<28800),L12,NA()) -> 0.064393464 | W12: =IF(AND(M12>0,M12<28800),M12,NA()) -> 0.0040917462 | X12: =IF(AND(N12>0,N12<28800),N12,NA()) -> 0.0043107951 | Y12: =IF(AND(O12>0,O12<28800),O12,NA()) -> 0.0045743091 | Z12: =IF(AND(P12>0,P12<28800),P12,NA()) -> 0.014279019 | AA12: =IF(AND(Q12>0,Q12<28800),Q12,NA()) -> 1.2007472 | AB12: =IF(AND(R12>0,R12<28800),R12,NA()) -> 0.052589167
A13: =Sheet1!A41 -> [[11,1,5]] | B13: =MATCH($A13,INDIRECT("Sheet"&B$2&"!A:A"),) -> 41 | C13: =MATCH($A13,INDIRECT("Sheet"&C$2&"!A:A"),) -> 41 | D13: =MATCH($A13,INDIRECT("Sheet"&D$2&"!A:A"),) -> 41 | E13: =MATCH($A13,INDIRECT("Sheet"&E$2&"!A:A"),) -> 41 | F13: =MATCH($A13,INDIRECT("Sheet"&F$2&"!A:A"),) -> 41 | G13: =MATCH($A13,INDIRECT("Sheet"&G$2&"!A:A"),) -> 41 | H13: =MATCH($A13,INDIRECT("Sheet"&H$2&"!A:A"),) -> 41 | I13: =MATCH($A13,magma!A:A,) -> 36 | K13: {=OFFSET(INDIRECT("Sheet"&B$2&"!f1"),B13-1,)} -> 0.095066388 | L13: {=OFFSET(INDIRECT("Sheet"&C$2&"!f1"),C13-1,)} -> 0.11473478 | M13: {=OFFSET(INDIRECT("Sheet"&D$2&"!f1"),D13-1,)} -> 0.0043507665 | N13: {=OFFSET(INDIRECT("Sheet"&E$2&"!f1"),E13-1,)} -> 0.0048825424 | O13: {=OFFSET(INDIRECT("Sheet"&F$2&"!f1"),F13-1,)} -> 0.0050013242 | P13: {=OFFSET(INDIRECT("Sheet"&G$2&"!f1"),G13-1,)} -> 0.01594353 | Q13: {=OFFSET(INDIRECT("Sheet"&H$2&"!f1"),H13-1,)} -> 109.5644 | R13: =OFFSET(magma!$F$1,I13-1,)*1 -> 0.052994916 | T13: =Sheet1!B41 -> 11 | U13: =IF(AND(K13>0,K13<28800),K13,NA()) -> 0.095066388 | V13: =IF(AND(L13>0,L13<28800),L13,NA()) -> 0.11473478 | W13: =IF(AND(M13>0,M13<28800),M13,NA()) -> 0.0043507665 | X13: =IF(AND(N13>0,N13<28800),N13,NA()) -> 0.0048825424 | Y13: =IF(AND(O13>0,O13<28800),O13,NA()) -> 0.0050013242 | Z13: =IF(AND(P13>0,P13<28800),P13,NA()) -> 0.01594353 | AA13: =IF(AND(Q13>0,Q13<28800),Q13,NA()) -> 109.5644 | AB13: =IF(AND(R13>0,R13<28800),R13,NA()) -> 0.052994916
A14: =Sheet1!A42 -> [[12,6,3]] | B14: =MATCH($A14,INDIRECT("Sheet"&B$2&"!A:A"),) -> 42 | C14: =MATCH($A14,INDIRECT("Sheet"&C$2&"!A:A"),) -> 42 | D14: =MATCH($A14,INDIRECT("Sheet"&D$2&"!A:A"),) -> 42 | E14: =MATCH($A14,INDIRECT("Sheet"&E$2&"!A:A"),) -> 42 | F14: =MATCH($A14,INDIRECT("Sheet"&F$2&"!A:A"),) -> 42 | G14: =MATCH($A14,INDIRECT("Sheet"&G$2&"!A:A"),) -> 42 | H14: =MATCH($A14,INDIRECT("Sheet"&H$2&"!A:A"),) -> 42 | I14: =MATCH($A14,magma!A:A,) -> 37 | K14: {=OFFSET(INDIRECT("Sheet"&B$2&"!f1"),B14-1,)} -> 0.06354958 | L14: {=OFFSET(INDIRECT("Sheet"&C$2&"!f1"),C14-1,)} -> 0.05448499 | M14: {=OFFSET(INDIRECT("Sheet"&D$2&"!f1"),D14-1,)} -> 0.0054580048 | N14: {=OFFSET(INDIRECT("Sheet"&E$2&"!f1"),E14-1,)} -> 0.0063266307 | O14: {=OFFSET(INDIRECT("Sheet"&F$2&"!f1"),F14-1,)} -> 0.0061778883 | P14: {=OFFSET(INDIRECT("Sheet"&G$2&"!f1"),G14-1,)} -> 0.013633458 | Q14: {=OFFSET(INDIRECT("Sheet"&H$2&"!f1"),H14-1,)} -> 0.10105666 | R14: =OFFSET(magma!$F$1,I14-1,)*1 -> 0.052198792 | T14: =Sheet1!B42 -> 12 | U14: =IF(AND(K14>0,K14<28800),K14,NA()) -> 0.06354958 | V14: =IF(AND(L14>0,L14<28800),L14,NA()) -> 0.05448499 | W14: =IF(AND(M14>0,M14<28800),M14,NA()) -> 0.0054580048 | X14: =IF(AND(N14>0,N14<28800),N14,NA()) -> 0.0063266307 | Y14: =IF(AND(O14>0,O14<28800),O14,NA()) -> 0.0061778883 | Z14: =IF(AND(P14>0,P14<28800),P14,NA()) -> 0.013633458 | AA14: =IF(AND(Q14>0,Q14<28800),Q14,NA()) -> 0.10105666 | AB14: =IF(AND(R14>0,R14<28800),R14,NA()) -> 0.052198792
A15: =Sheet1!A43 -> [[13,6,3]] | B15: =MATCH($A15,INDIRECT("Sheet"&B$2&"!A:A"),) -> 43 | C15: =MATCH($A15,INDIRECT("Sheet"&C$2&"!A:A"),) -> 43 | D15: =MATCH($A15,INDIRECT("Sheet"&D$2&"!A:A"),) -> 43 | E15: =MATCH($A15,INDIRECT("Sheet"&E$2&"!A:A"),) -> 43 | F15: =MATCH($A15,INDIRECT("Sheet"&F$2&"!A:A"),) -> 43 | G15: =MATCH($A15,INDIRECT("Sheet"&G$2&"!A:A"),) -> 43 | H15: =MATCH($A15,INDIRECT("Sheet"&H$2&"!A:A"),) -> 43 | I15: =MATCH($A15,magma!A:A,) -> 38 | K15: {=OFFSET(INDIRECT("Sheet"&B$2&"!f1"),B15-1,)} -> 0.053781667 | L15: {=OFFSET(INDIRECT("Sheet"&C$2&"!f1"),C15-1,)} -> 0.075968705 | M15: {=OFFSET(INDIRECT("Sheet"&D$2&"!f1"),D15-1,)} -> 0.0057930769 | N15: {=OFFSET(INDIRECT("Sheet"&E$2&"!f1"),E15-1,)} -> 0.0055834502 | O15: {=OFFSET(INDIRECT("Sheet"&F$2&"!f1"),F15-1,)} -> 0.0066611217 | P15: {=OFFSET(INDIRECT("Sheet"&G$2&"!f1"),G15-1,)} -> 0.013476771 | Q15: {=OFFSET(INDIRECT("Sheet"&H$2&"!f1"),H15-1,)} -> 0.10254574 | R15: =OFFSET(magma!$F$1,I15-1,)*1 -> 0.053350833 | T15: =Sheet1!B43 -> 13 | U15: =IF(AND(K15>0,K15<28800),K15,NA()) -> 0.053781667 | V15: =IF(AND(L15>0,L15<28800),L15,NA()) -> 0.075968705 | W15: =IF(AND(M15>0,M15<28800),M15,NA()) -> 0.0057930769 | X15: =IF(AND(N15>0,N15<28800),N15,NA()) -> 0.0055834502 | Y15: =IF(AND(O15>0,O15<28800),O15,NA()) -> 0.0066611217 | Z15: =IF(AND(P15>0,P15<28800),P15,NA()) -> 0.013476771 | AA15: =IF(AND(Q15>0,Q15<28800),Q15,NA()) -> 0.10254574 | AB15: =IF(AND(R15>0,R15<28800),R15,NA()) -> 0.053350833
A16: =Sheet1!A44 -> [[14,2,5]] | B16: =MATCH($A16,INDIRECT("Sheet"&B$2&"!A:A"),) -> 44 | C16: =MATCH($A16,INDIRECT("Sheet"&C$2&"!A:A"),) -> 44 | D16: =MATCH($A16,INDIRECT("Sheet"&D$2&"!A:A"),) -> 44 | E16: =MATCH($A16,INDIRECT("Sheet"&E$2&"!A:A"),) -> 44 | F16: =MATCH($A16,INDIRECT("Sheet"&F$2&"!A:A"),) -> 44 | G16: =MATCH($A16,INDIRECT("Sheet"&G$2&"!A:A"),) -> 44 | H16: =MATCH($A16,INDIRECT("Sheet"&H$2&"!A:A"),) -> 44 | I16: =MATCH($A16,magma!A:A,) -> 39 | K16: {=OFFSET(INDIRECT("Sheet"&B$2&"!f1"),B16-1,)} -> 0.11395475 | L16: {=OFFSET(INDIRECT("Sheet"&C$2&"!f1"),C16-1,)} -> 0.18532494 | M16: {=OFFSET(INDIRECT("Sheet"&D$2&"!f1"),D16-1,)} -> 0.0049773864 | N16: {=OFFSET(INDIRECT("Sheet"&E$2&"!f1"),E16-1,)} -> 0.007937409 | O16: {=OFFSET(INDIRECT("Sheet"&F$2&"!f1"),F16-1,)} -> 0.0085715689 | P16: {=OFFSET(INDIRECT("Sheet"&G$2&"!f1"),G16-1,)} -> 0.020579899 | Q16: {=OFFSET(INDIRECT("Sheet"&H$2&"!f1"),H16-1,)} -> 1785.6139 | R16: =OFFSET(magma!$F$1,I16-1,)*1 -> 0.053272625 | T16: =Sheet1!B44 -> 14 | U16: =IF(AND(K16>0,K16<28800),K16,NA()) -> 0.11395475 | V16: =IF(AND(L16>0,L16<28800),L16,NA()) -> 0.18532494 | W16: =IF(AND(M16>0,M16<28800),M16,NA()) -> 0.0049773864 | X16: =IF(AND(N16>0,N16<28800),N16,NA()) -> 0.007937409 | Y16: =IF(AND(O16>0,O16<28800),O16,NA()) -> 0.0085715689 | Z16: =IF(AND(P16>0,P16<28800),P16,NA()) -> 0.020579899 | AA16: =IF(AND(Q16>0,Q16<28800),Q16,NA()) -> 1785.6139 | AB16: =IF(AND(R16>0,R16<28800),R16,NA()) -> 0.053272625
... A23: =Sheet1!A51 -> [[21,3,6]] | B23: =MATCH($A23,INDIRECT("Sheet"&B$2&"!A:A"),) -> 51 | C23: =MATCH($A23,INDIRECT("Sheet"&C$2&"!A:A"),) -> 51 | D23: =MATCH($A23,INDIRECT("Sheet"&D$2&"!A:A"),) -> 51 | E23: =MATCH($A23,INDIRECT("Sheet"&E$2&"!A:A"),) -> 51 | F23: =MATCH($A23,INDIRECT("Sheet"&F$2&"!A:A"),) -> 51 | G23: =MATCH($A23,INDIRECT("Sheet"&G$2&"!A:A"),) -> 51 | H23: =MATCH($A23,INDIRECT("Sheet"&H$2&"!A:A"),) -> 51 | I23: =MATCH($A23,magma!A:A,) -> 46 | K23: {=OFFSET(INDIRECT("Sheet"&B$2&"!f1"),B23-1,)} -> 1.7838281 | L23: {=OFFSET(INDIRECT("Sheet"&C$2&"!f1"),C23-1,)} -> 1.1712529 | M23: {=OFFSET(INDIRECT("Sheet"&D$2&"!f1"),D23-1,)} -> 0.5710855 | N23: {=OFFSET(INDIRECT("Sheet"&E$2&"!f1"),E23-1,)} -> 0.06370308 | O23: {=OFFSET(INDIRECT("Sheet"&F$2&"!f1"),F23-1,)} -> 0.069716023 | P23: {=OFFSET(INDIRECT("Sheet"&G$2&"!f1"),G23-1,)} -> 0.44258954 | Q23: {=OFFSET(INDIRECT("Sheet"&H$2&"!f1"),H23-1,)} -> 28800.162 | R23: =OFFSET(magma!$F$1,I23-1,)*1 -> 0.083966417 | T23: =Sheet1!B51 -> 21 | U23: =IF(AND(K23>0,K23<28800),K23,NA()) -> 1.7838281 | V23: =IF(AND(L23>0,L23<28800),L23,NA()) -> 1.1712529 | W23: =IF(AND(M23>0,M23<28800),M23,NA()) -> 0.5710855 | X23: =IF(AND(N23>0,N23<28800),N23,NA()) -> 0.06370308 | Y23: =IF(AND(O23>0,O23<28800),O23,NA()) -> 0.069716023 | Z23: =IF(AND(P23>0,P23<28800),P23,NA()) -> 0.44258954 | AA23: =IF(AND(Q23>0,Q23<28800),Q23,NA()) -> #N/A | AB23: =IF(AND(R23>0,R23<28800),R23,NA()) -> 0.083966417
A24: =Sheet1!A52 -> [[22,7,5]] | B24: =MATCH($A24,INDIRECT("Sheet"&B$2&"!A:A"),) -> 52 | C24: =MATCH($A24,INDIRECT("Sheet"&C$2&"!A:A"),) -> 52 | D24: =MATCH($A24,INDIRECT("Sheet"&D$2&"!A:A"),) -> 52 | E24: =MATCH($A24,INDIRECT("Sheet"&E$2&"!A:A"),) -> 52 | F24: =MATCH($A24,INDIRECT("Sheet"&F$2&"!A:A"),) -> 52 | G24: =MATCH($A24,INDIRECT("Sheet"&G$2&"!A:A"),) -> 52 | H24: =MATCH($A24,INDIRECT("Sheet"&H$2&"!A:A"),) -> 52 | I24: =MATCH($A24,magma!A:A,) -> 47 | K24: {=OFFSET(INDIRECT("Sheet"&B$2&"!f1"),B24-1,)} -> 1.1300711 | L24: {=OFFSET(INDIRECT("Sheet"&C$2&"!f1"),C24-1,)} -> 0.57773448 | M24: {=OFFSET(INDIRECT("Sheet"&D$2&"!f1"),D24-1,)} -> 0.32848217 | N24: {=OFFSET(INDIRECT("Sheet"&E$2&"!f1"),E24-1,)} -> 0.050369615 | O24: {=OFFSET(INDIRECT("Sheet"&F$2&"!f1"),F24-1,)} -> 0.058332029 | P24: {=OFFSET(INDIRECT("Sheet"&G$2&"!f1"),G24-1,)} -> 0.053945272 | Q24: {=OFFSET(INDIRECT("Sheet"&H$2&"!f1"),H24-1,)} -> 28803.429 | R24: =OFFSET(magma!$F$1,I24-1,)*1 -> 0.058356875 | T24: =Sheet1!B52 -> 22 | U24: =IF(AND(K24>0,K24<28800),K24,NA()) -> 1.1300711 | V24: =IF(AND(L24>0,L24<28800),L24,NA()) -> 0.57773448 | W24: =IF(AND(M24>0,M24<28800),M24,NA()) -> 0.32848217 | X24: =IF(AND(N24>0,N24<28800),N24,NA()) -> 0.050369615 | Y24: =IF(AND(O24>0,O24<28800),O24,NA()) -> 0.058332029 | Z24: =IF(AND(P24>0,P24<28800),P24,NA()) -> 0.053945272 | AA24: =IF(AND(Q24>0,Q24<28800),Q24,NA()) -> #N/A | AB24: =IF(AND(R24>0,R24<28800),R24,NA()) -> 0.058356875 | AD24: BZDist
A25: =Sheet1!A53 -> [[23,2,7]] | B25: =MATCH($A25,INDIRECT("Sheet"&B$2&"!A:A"),) -> 53 | C25: =MATCH($A25,INDIRECT("Sheet"&C$2&"!A:A"),) -> 53 | D25: =MATCH($A25,INDIRECT("Sheet"&D$2&"!A:A"),) -> 53 | E25: =MATCH($A25,INDIRECT("Sheet"&E$2&"!A:A"),) -> 53 | F25: =MATCH($A25,INDIRECT("Sheet"&F$2&"!A:A"),) -> 53 | G25: =MATCH($A25,INDIRECT("Sheet"&G$2&"!A:A"),) -> 53 | H25: =MATCH($A25,INDIRECT("Sheet"&H$2&"!A:A"),) -> 53 | I25: =MATCH($A25,magma!A:A,) -> 48 | K25: {=OFFSET(INDIRECT("Sheet"&B$2&"!f1"),B25-1,)} -> 4.318391 | L25: {=OFFSET(INDIRECT("Sheet"&C$2&"!f1"),C25-1,)} -> 8.7959128 | M25: {=OFFSET(INDIRECT("Sheet"&D$2&"!f1"),D25-1,)} -> 0.16740688 | N25: {=OFFSET(INDIRECT("Sheet"&E$2&"!f1"),E25-1,)} -> 0.22472984 | O25: {=OFFSET(INDIRECT("Sheet"&F$2&"!f1"),F25-1,)} -> 0.037588599 | P25: {=OFFSET(INDIRECT("Sheet"&G$2&"!f1"),G25-1,)} -> 25.449987 | Q25: {=OFFSET(INDIRECT("Sheet"&H$2&"!f1"),H25-1,)} -> 28800.111 | R25: =OFFSET(magma!$F$1,I25-1,)*1 -> 0.055515542 | T25: =Sheet1!B53 -> 23 | U25: =IF(AND(K25>0,K25<28800),K25,NA()) -> 4.318391 | V25: =IF(AND(L25>0,L25<28800),L25,NA()) -> 8.7959128 | W25: =IF(AND(M25>0,M25<28800),M25,NA()) -> 0.16740688 | X25: =IF(AND(N25>0,N25<28800),N25,NA()) -> 0.22472984 | Y25: =IF(AND(O25>0,O25<28800),O25,NA()) -> 0.037588599 | Z25: =IF(AND(P25>0,P25<28800),P25,NA()) -> 25.449987 | AA25: =IF(AND(Q25>0,Q25<28800),Q25,NA()) -> #N/A | AB25: =IF(AND(R25>0,R25<28800),R25,NA()) -> 0.055515542
A26: =Sheet1!A54 -> [[24,8,5]] | B26: =MATCH($A26,INDIRECT("Sheet"&B$2&"!A:A"),) -> 54 | C26: =MATCH($A26,INDIRECT("Sheet"&C$2&"!A:A"),) -> 54 | D26: =MATCH($A26,INDIRECT("Sheet"&D$2&"!A:A"),) -> 54 | E26: =MATCH($A26,INDIRECT("Sheet"&E$2&"!A:A"),) -> 54 | F26: =MATCH($A26,INDIRECT("Sheet"&F$2&"!A:A"),) -> 54 | G26: =MATCH($A26,INDIRECT("Sheet"&G$2&"!A:A"),) -> 54 | H26: =MATCH($A26,INDIRECT("Sheet"&H$2&"!A:A"),) -> 54 | I26: =MATCH($A26,magma!A:A,) -> 49 | K26: {=OFFSET(INDIRECT("Sheet"&B$2&"!f1"),B26-1,)} -> 1.6631247 | L26: {=OFFSET(INDIRECT("Sheet"&C$2&"!f1"),C26-1,)} -> 0.92048697 | M26: {=OFFSET(INDIRECT("Sheet"&D$2&"!f1"),D26-1,)} -> 0.56945125 | N26: {=OFFSET(INDIRECT("Sheet"&E$2&"!f1"),E26-1,)} -> 0.08409851 | O26: {=OFFSET(INDIRECT("Sheet"&F$2&"!f1"),F26-1,)} -> 0.089682543 | P26: {=OFFSET(INDIRECT("Sheet"&G$2&"!f1"),G26-1,)} -> 0.065455301 | Q26: {=OFFSET(INDIRECT("Sheet"&H$2&"!f1"),H26-1,)} -> 28800.112 | R26: =OFFSET(magma!$F$1,I26-1,)*1 -> 0.055191625 | T26: =Sheet1!B54 -> 24 | U26: =IF(AND(K26>0,K26<28800),K26,NA()) -> 1.6631247 | V26: =IF(AND(L26>0,L26<28800),L26,NA()) -> 0.92048697 | W26: =IF(AND(M26>0,M26<28800),M26,NA()) -> 0.56945125 | X26: =IF(AND(N26>0,N26<28800),N26,NA()) -> 0.08409851 | Y26: =IF(AND(O26>0,O26<28800),O26,NA()) -> 0.089682543 | Z26: =IF(AND(P26>0,P26<28800),P26,NA()) -> 0.065455301 | AA26: =IF(AND(Q26>0,Q26<28800),Q26,NA()) -> #N/A | AB26: =IF(AND(R26>0,R26<28800),R26,NA()) -> 0.055191625
A27: =Sheet1!A55 -> [[25,8,5]] | B27: =MATCH($A27,INDIRECT("Sheet"&B$2&"!A:A"),) -> 55 | C27: =MATCH($A27,INDIRECT("Sheet"&C$2&"!A:A"),) -> 55 | D27: =MATCH($A27,INDIRECT("Sheet"&D$2&"!A:A"),) -> 55 | E27: =MATCH($A27,INDIRECT("Sheet"&E$2&"!A:A"),) -> 55 | F27: =MATCH($A27,INDIRECT("Sheet"&F$2&"!A:A"),) -> 55 | G27: =MATCH($A27,INDIRECT("Sheet"&G$2&"!A:A"),) -> 55 | H27: =MATCH($A27,INDIRECT("Sheet"&H$2&"!A:A"),) -> 55 | I27: =MATCH($A27,magma!A:A,) -> 50 | K27: {=OFFSET(INDIRECT("Sheet"&B$2&"!f1"),B27-1,)} -> 1.9549418 | L27: {=OFFSET(INDIRECT("Sheet"&C$2&"!f1"),C27-1,)} -> 0.85945142 | M27: {=OFFSET(INDIRECT("Sheet"&D$2&"!f1"),D27-1,)} -> 0.64561058 | N27: {=OFFSET(INDIRECT("Sheet"&E$2&"!f1"),E27-1,)} -> 0.10301293 | O27: {=OFFSET(INDIRECT("Sheet"&F$2&"!f1"),F27-1,)} -> 0.10717582 | P27: {=OFFSET(INDIRECT("Sheet"&G$2&"!f1"),G27-1,)} -> 0.064647969 | Q27: {=OFFSET(INDIRECT("Sheet"&H$2&"!f1"),H27-1,)} -> 28800.114 | R27: =OFFSET(magma!$F$1,I27-1,)*1 -> 0.055713708 | T27: =Sheet1!B55 -> 25 | U27: =IF(AND(K27>0,K27<28800),K27,NA()) -> 1.9549418 | V27: =IF(AND(L27>0,L27<28800),L27,NA()) -> 0.85945142 | W27: =IF(AND(M27>0,M27<28800),M27,NA()) -> 0.64561058 | X27: =IF(AND(N27>0,N27<28800),N27,NA()) -> 0.10301293 | Y27: =IF(AND(O27>0,O27<28800),O27,NA()) -> 0.10717582 | Z27: =IF(AND(P27>0,P27<28800),P27,NA()) -> 0.064647969 | AA27: =IF(AND(Q27>0,Q27<28800),Q27,NA()) -> #N/A | AB27: =IF(AND(R27>0,R27<28800),R27,NA()) -> 0.055713708
A28: =Sheet1!A56 -> [[26,6,6]] | B28: =MATCH($A28,INDIRECT("Sheet"&B$2&"!A:A"),) -> 56 | C28: =MATCH($A28,INDIRECT("Sheet"&C$2&"!A:A"),) -> 56 | D28: =MATCH($A28,INDIRECT("Sheet"&D$2&"!A:A"),) -> 56 | E28: =MATCH($A28,INDIRECT("Sheet"&E$2&"!A:A"),) -> 56 | F28: =MATCH($A28,INDIRECT("Sheet"&F$2&"!A:A"),) -> 56 | G28: =MATCH($A28,INDIRECT("Sheet"&G$2&"!A:A"),) -> 56 | H28: =MATCH($A28,INDIRECT("Sheet"&H$2&"!A:A"),) -> 56 | I28: =MATCH($A28,magma!A:A,) -> 51 | K28: {=OFFSET(INDIRECT("Sheet"&B$2&"!f1"),B28-1,)} -> 4.8920487 | L28: {=OFFSET(INDIRECT("Sheet"&C$2&"!f1"),C28-1,)} -> 3.4845666 | M28: {=OFFSET(INDIRECT("Sheet"&D$2&"!f1"),D28-1,)} -> 3.6392468 | N28: {=OFFSET(INDIRECT("Sheet"&E$2&"!f1"),E28-1,)} -> 0.36420888 | O28: {=OFFSET(INDIRECT("Sheet"&F$2&"!f1"),F28-1,)} -> 0.40039759 | P28: {=OFFSET(INDIRECT("Sheet"&G$2&"!f1"),G28-1,)} -> 2.2800811 | Q28: {=OFFSET(INDIRECT("Sheet"&H$2&"!f1"),H28-1,)} -> 28802.74 | R28: =OFFSET(magma!$F$1,I28-1,)*1 -> 0.06090825 | T28: =Sheet1!B56 -> 26 | U28: =IF(AND(K28>0,K28<28800),K28,NA()) -> 4.8920487 | V28: =IF(AND(L28>0,L28<28800),L28,NA()) -> 3.4845666 | W28: =IF(AND(M28>0,M28<28800),M28,NA()) -> 3.6392468 | X28: =IF(AND(N28>0,N28<28800),N28,NA()) -> 0.36420888 | Y28: =IF(AND(O28>0,O28<28800),O28,NA()) -> 0.40039759 | Z28: =IF(AND(P28>0,P28<28800),P28,NA()) -> 2.2800811 | AA28: =IF(AND(Q28>0,Q28<28800),Q28,NA()) -> #N/A | AB28: =IF(AND(R28>0,R28<28800),R28,NA()) -> 0.06090825
A29: =Sheet1!A57 -> [[27,6,6]] | B29: =MATCH($A29,INDIRECT("Sheet"&B$2&"!A:A"),) -> 57 | C29: =MATCH($A29,INDIRECT("Sheet"&C$2&"!A:A"),) -> 57 | D29: =MATCH($A29,INDIRECT("Sheet"&D$2&"!A:A"),) -> 57 | E29: =MATCH($A29,INDIRECT("Sheet"&E$2&"!A:A"),) -> 57 | F29: =MATCH($A29,INDIRECT("Sheet"&F$2&"!A:A"),) -> 57 | G29: =MATCH($A29,INDIRECT("Sheet"&G$2&"!A:A"),) -> 57 | H29: =MATCH($A29,INDIRECT("Sheet"&H$2&"!A:A"),) -> 57 | I29: =MATCH($A29,magma!A:A,) -> 52 | K29: {=OFFSET(INDIRECT("Sheet"&B$2&"!f1"),B29-1,)} -> 4.7106815 | L29: {=OFFSET(INDIRECT("Sheet"&C$2&"!f1"),C29-1,)} -> 3.4948352 | M29: {=OFFSET(INDIRECT("Sheet"&D$2&"!f1"),D29-1,)} -> 4.2119374 | N29: {=OFFSET(INDIRECT("Sheet"&E$2&"!f1"),E29-1,)} -> 0.43110879 | O29: {=OFFSET(INDIRECT("Sheet"&F$2&"!f1"),F29-1,)} -> 0.48181313 | P29: {=OFFSET(INDIRECT("Sheet"&G$2&"!f1"),G29-1,)} -> 2.2713823 | Q29: {=OFFSET(INDIRECT("Sheet"&H$2&"!f1"),H29-1,)} -> 28800.109 | R29: =OFFSET(magma!$F$1,I29-1,)*1 -> 0.063612167 | T29: =Sheet1!B57 -> 27 | U29: =IF(AND(K29>0,K29<28800),K29,NA()) -> 4.7106815 | V29: =IF(AND(L29>0,L29<28800),L29,NA()) -> 3.4948352 | W29: =IF(AND(M29>0,M29<28800),M29,NA()) -> 4.2119374 | X29: =IF(AND(N29>0,N29<28800),N29,NA()) -> 0.43110879 | Y29: =IF(AND(O29>0,O29<28800),O29,NA()) -> 0.48181313 | Z29: =IF(AND(P29>0,P29<28800),P29,NA()) -> 2.2713823 | AA29: =IF(AND(Q29>0,Q29<28800),Q29,NA()) -> #N/A | AB29: =IF(AND(R29>0,R29<28800),R29,NA()) -> 0.063612167
