Workbook

Sheet benchmark-HSC
D12: Brouwer-Zimmermann | G12: Meet-in-the-Middle
A13: Code | B13: n | C13: m4riCC | D13: Magma | E13: BZDistMW | F13: QubitserfBZ | G13: MeetMiddleMW | H13: qubitserfMM
A14: =BZmagma!O30 -> [[6,1,2]] | B14: 6 | C14: =m4riCC!F25 -> 0.028568936 | D14: =BZmagma!F30*1 -> 0.23239242 | E14: =BZMW!F30 -> 0.002468083 | F14: =BZqubitserf!F30 -> 0.016261833 | G14: =MMMW!F30 -> 0.00010316703 | H14: =MMqubitserf!F30 -> 0.03228575
A15: =BZmagma!O31 -> [[24,4,2]] | B15: 24 | C15: =m4riCC!F26 -> 0.03350593 | D15: =BZmagma!F31*1 -> 0.056989875 | E15: =BZMW!F31 -> 0.001391625 | F15: =BZqubitserf!F31 -> 0.009921625 | G15: =MMMW!F31 -> 0.000302375 | H15: =MMqubitserf!F31 -> 0.015158625
A16: =BZmagma!O32 -> [[48,6,3]] | B16: 48 | C16: =m4riCC!F27 -> 0.037549334 | D16: =BZmagma!F32*1 -> 0.066720375 | E16: =BZMW!F32 -> 0.00510725 | F16: =BZqubitserf!F32 -> 0.023522583 | G16: =MMMW!F32 -> 0.001312167 | H16: =MMqubitserf!F32 -> 0.016607584
A17: =BZmagma!O33 -> [[84,9,4]] | B17: 84 | C17: =m4riCC!F28 -> 0.045564964 | D17: =BZmagma!F33*1 -> 0.090328792 | E17: =BZMW!F33 -> 0.020930833 | F17: =BZqubitserf!F33 -> 2.3085713 | G17: =MMMW!F33 -> 0.081129666 | H17: =MMqubitserf!F33 -> 0.24576271
A18: =BZmagma!O34 -> [[84,9,3]] | B18: 84 | C18: =m4riCC!F29 -> 0.050560005 | D18: =BZmagma!F34*1 -> 0.082497333 | E18: =BZMW!F34 -> 0.008438625 | F18: =BZqubitserf!F34 -> 0.34688604 | G18: =MMMW!F34 -> 0.003699959 | H18: =MMqubitserf!F34 -> 2.8263113
A19: =BZmagma!O35 -> [[96,10,4]] | B19: 96 | C19: =m4riCC!F30 -> 0.050963901 | D19: =BZmagma!F35*1 -> 0.0984935 | E19: =BZMW!F35 -> 0.029560209 | F19: =BZqubitserf!F35 -> 4.8447533 | G19: =MMMW!F35 -> 0.087833625 | H19: =MMqubitserf!F35 -> 21.738639
A20: =BZmagma!O36 -> [[168,16,4]] | B20: 168 | C20: =m4riCC!F31 -> 0.054005231 | D20: =BZmagma!F36*1 -> 0.21884367 | E20: =BZMW!F36 -> 0.18817967 | F20: =BZqubitserf!F36 -> 1372.1519 | G20: =MMMW!F36 -> 0.52567079
A21: =BZmagma!O37 -> [[168,16,4]] | B21: 168 | C21: =m4riCC!F32 -> 0.050963958 | D21: =BZmagma!F37*1 -> 0.20785829 | E21: =BZMW!F37 -> 0.21046837 | F21: =BZqubitserf!F37 -> 30.303628 | G21: =MMMW!F37 -> 0.55925087
A22: =BZmagma!O38 -> [[180,17,5]] | B22: 180 | C22: =m4riCC!F33 -> 0.033827712 | D22: =BZmagma!F38*1 -> 2.1629083 | E22: =BZMW!F38 -> 6.8946658 | F22: =BZqubitserf!F38 -> 1583.0654 | G22: =MMMW!F38 -> 5.185617
A23: =BZmagma!O39 -> [[252,23,4]] | B23: 252 | C23: =m4riCC!F34 -> 0.016204288 | D23: =BZmagma!F39*1 -> 0.47531608 | E23: =BZMW!F39 -> 0.79571179 | G23: =MMMW!F39 -> 2.747183
A24: =BZmagma!O40 -> [[360,32,5]] | B24: 360 | C24: =m4riCC!F35 -> 0.019555664 | D24: =BZmagma!F40*1 -> 51.643607 | E24: =BZMW!F40 -> 188.38387 | G24: =MMMW!F40 -> 195.11355
A25: =BZmagma!O41 -> [[384,34,4]] | B25: 384 | C25: =m4riCC!F36 -> 0.018986203 | D25: =BZmagma!F41*1 -> 1.822319 | E25: =BZMW!F41 -> 3.7596173 | G25: =MMMW!F41 -> 162.60462
A27: Overall | C27: =SUM(C14:C26) -> 0.44025613 | D27: =SUM(D14:D26) -> 57.158274 | E27: =SUM(E14:E26) -> 200.30041 | F27: =SUM(F14:F26) -> 2993.0708 | G27: =SUM(G14:G26) -> 366.91027 | H27: =SUM(H14:H26) -> 24.874765

Sheet BZMW
A1: runMode: serial
A2: maxCount: 10000
A3: repeat: 1
A4: dataset: hyperbolic_surface_code
A5: datafile: RG-3-8.txt
A6: method: BZDistMW
A7: ignoreTrivialCodes: 1
A8: resume: 0
A9: nMin: 1
A10: nMax: 100000
A11: iterCount: 10000
A12: maxTime: 28800
... A28: #########################################
A29: name | B29: n | C29: k | D29: d | E29: delta d | F29: Time | G29: R | H29: T | I29: Progress
A30: [[6,1,0]] | B30: 6 | C30: 1 | D30: 2 | E30: 2 | F30: 0.002468083 | G30: 1 | H30: 1 | I30: Constructing information sets: Block structure [4 2]; Generating combinations of t=1 rows; Found w:2; Completed matrix 0,dU:2,dL:2,vCount:4; Terminating: dU:2 <= dL:2,vCount:4
A31: [[24,4,0]] | B31: 24 | C31: 4 | D31: 2 | E31: 2 | F31: 0.001391625 | G31: 1 | H31: 1 | I31: Constructing information sets: Block structure [19 5]; Generating combinations of t=1 rows; Found w:2; Completed matrix 0,dU:2,dL:2,vCount:19; Terminating: dU:2 <= dL:2,vCount:19
A32: [[48,6,0]] | B32: 48 | C32: 6 | D32: 3 | E32: 3 | F32: 0.00510725 | G32: 1 | H32: 1 | I32: Constructing information sets: Block structure [37 11]; Generating combinations of t=1 rows; Found w:3; Completed matrix 0,dU:3,dL:2,vCount:37; Completed matrix 1,dU:3,dL:2,vCount:74; tMax:3; Discarding 1 non-contributing matrix, new block structure [37]; Generating combinations of t=2 rows; Completed matrix 0,dU:3,dL:3,vCount:740; Terminating: dU:3 <= dL:3,vCount:740
A33: [[84,9,0]] | B33: 84 | C33: 9 | D33: 4 | E33: 4 | F33: 0.020930833 | G33: 1 | H33: 1 | I33: Constructing information sets: Block structure [64 20]; Generating combinations of t=1 rows; Found w:4; Completed matrix 0,dU:4,dL:2,vCount:64; Completed matrix 1,dU:4,dL:2,vCount:128; tMax:4; Discarding 1 non-contributing matrix, new block structure [64]; Generating combinations of t=2 rows; Completed matrix 0,dU:4,dL:3,vCount:2144; Generating combinations of t=3 rows; Completed matrix 0,dU:4,dL:4,vCount:43807; Terminating: dU:4 <= dL:4,vCount:43807
A34: [[84,9,0]] | B34: 84 | C34: 9 | D34: 3 | E34: 3 | F34: 0.008438625 | G34: 1 | H34: 1 | I34: Constructing information sets: Block structure [64 20]; Generating combinations of t=1 rows; Found w:3; Completed matrix 0,dU:3,dL:2,vCount:64; Completed matrix 1,dU:3,dL:2,vCount:128; tMax:3; Discarding 1 non-contributing matrix, new block structure [64]; Generating combinations of t=2 rows; Completed matrix 0,dU:3,dL:3,vCount:2144; Terminating: dU:3 <= dL:3,vCount:2144
A35: [[96,10,0]] | B35: 96 | C35: 10 | D35: 4 | E35: 4 | F35: 0.029560209 | G35: 1 | H35: 1 | I35: Constructing information sets: Block structure [73 23]; Generating combinations of t=1 rows; Found w:4; Completed matrix 0,dU:4,dL:2,vCount:73; Completed matrix 1,dU:4,dL:2,vCount:146; tMax:4; Discarding 1 non-contributing matrix, new block structure [73]; Generating combinations of t=2 rows; Completed matrix 0,dU:4,dL:3,vCount:2774; Generating combinations of t=3 rows; Completed matrix 0,dU:4,dL:4,vCount:64969; Terminating: dU:4 <= dL:4,vCount:64969
A36: [[168,16,0]] | B36: 168 | C36: 16 | D36: 4 | E36: 4 | F36: 0.18817967 | G36: 1 | H36: 1 | I36: Constructing information sets: Block structure [127 41]; Generating combinations of t=1 rows; Found w:4; Completed matrix 0,dU:4,dL:2,vCount:127; Completed matrix 1,dU:4,dL:2,vCount:254; tMax:4; Discarding 1 non-contributing matrix, new block structure [127]; Generating combinations of t=2 rows; Completed matrix 0,dU:4,dL:3,vCount:8255; Generating combinations of t=3 rows; Completed matrix 0,dU:4,dL:4,vCount:341629; Terminating: dU:4 <= dL:4,vCount:341629
A37: [[168,16,0]] | B37: 168 | C37: 16 | D37: 4 | E37: 4 | F37: 0.21046837 | G37: 1 | H37: 1 | I37: Constructing information sets: Block structure [127 41]; Generating combinations of t=1 rows; Found w:4; Completed matrix 0,dU:4,dL:2,vCount:127; Completed matrix 1,dU:4,dL:2,vCount:254; tMax:4; Discarding 1 non-contributing matrix, new block structure [127]; Generating combinations of t=2 rows; Completed matrix 0,dU:4,dL:3,vCount:8255; Generating combinations of t=3 rows; Completed matrix 0,dU:4,dL:4,vCount:341629; Terminating: dU:4 <= dL:4,vCount:341629
A38: [[180,17,0]] | B38: 180 | C38: 17 | D38: 5 | E38: 5 | F38: 6.8946658 | G38: 1 | H38: 1 | I38: Constructing information sets: Block structure [136 44]; Generating combinations of t=1 rows; Found w:5; Completed matrix 0,dU:5,dL:2,vCount:136; Completed matrix 1,dU:5,dL:2,vCount:272; tMax:5; Discarding 1 non-contributing matrix, new block structure [136]; Generating combinations of t=2 rows; Completed matrix 0,dU:5,dL:3,vCount:9452; Generating combinations of t=3 rows; Completed matrix 0,dU:5,dL:4,vCount:419491; Generating combinations of t=4 rows; Completed matrix 0,dU:5,dL:5,vCount:14053320; Terminating: dU:5 <= dL:5,vCount:14053320
A39: [[252,23,0]] | B39: 252 | C39: 23 | D39: 4 | E39: 4 | F39: 0.79571179 | G39: 1 | H39: 1 | I39: Constructing information sets: Block structure [190 62]; Generating combinations of t=1 rows; Found w:5; Completed matrix 0,dU:5,dL:2,vCount:190; Completed matrix 1,dU:5,dL:2,vCount:380; tMax:5; Discarding 1 non-contributing matrix, new block structure [190]; Generating combinations of t=2 rows; Found w:4; Completed matrix 0,dU:4,dL:3,vCount:18335; tMax:4; Generating combinations of t=3 rows; Completed matrix 0,dU:4,dL:4,vCount:1143514; Terminating: dU:4 <= dL:4,vCount:1143514
A40: [[360,32,0]] | B40: 360 | C40: 32 | D40: 5 | E40: 5 | F40: 188.38387 | G40: 1 | H40: 1 | I40: Constructing information sets: Block structure [271 89]; Generating combinations of t=1 rows; Found w:5; Completed matrix 0,dU:5,dL:2,vCount:271; Completed matrix 1,dU:5,dL:2,vCount:542; tMax:5; Discarding 1 non-contributing matrix, new block structure [271]; Generating combinations of t=2 rows; Completed matrix 0,dU:5,dL:3,vCount:37127; Generating combinations of t=3 rows; Completed matrix 0,dU:5,dL:4,vCount:3317581; Generating combinations of t=4 rows; Completed matrix 0,dU:5,dL:5,vCount:223108065; Terminating: dU:5 <= dL:5,vCount:223108065
A41: [[384,34,0]] | B41: 384 | C41: 34 | D41: 4 | E41: 4 | F41: 3.7596173 | G41: 1 | H41: 1 | I41: Constructing information sets: Block structure [289 95]; Generating combinations of t=1 rows; Found w:4; Completed matrix 0,dU:4,dL:2,vCount:289; Completed matrix 1,dU:4,dL:2,vCount:578; tMax:4; Discarding 1 non-contributing matrix, new block structure [289]; Generating combinations of t=2 rows; Completed matrix 0,dU:4,dL:3,vCount:42194; Generating combinations of t=3 rows; Completed matrix 0,dU:4,dL:4,vCount:4023457; Terminating: dU:4 <= dL:4,vCount:4023457

Sheet BZmagma
A1: runMode: serial
A2: maxCount: 10000
A3: repeat: 1
A4: dataset: hyperbolic_surface_code
A5: datafile: RG-3-8.txt
A6: method: magmaMinWeight
A7: ignoreTrivialCodes: 1
A8: resume: 0
A9: nMin: 1
A10: nMax: 100000
A11: iterCount: 10000
A12: maxTime: 28800
... A27: outfile: /Users/markwebster/Dropbox/QuantumComputing/dev/codeDistance/results/hyperbolic_surface_code-RG-3-8.txt-magmaMinWeight-20260115_090606.063364_85062422.txt
A28: ######################################### | P28: Processing Time
A29: name | B29: n | C29: k | D29: d | E29: delta d | F29: Time | G29: R | H29: T | I29: Progress | O29: Code | P29: Magma | Q29: BZMW | R29: BZMW/Magma
A30: [[6,1,0]] | B30: 6 | C30: 1 | D30: 2 | E30: 2 | F30: 0.2323924160155002 | G30: 1 | H30: 1 | I30: Magma V2.28-26 Thu Jan 15 2026 09:06:07 on Marks-MacBook-Air-2 [Seed = \n3183245326]\nType ? for help. Type <Ctrl>-D to quit.\n[[6, 1]] quantum code over GF(2^2), stabilised by:\n[[[[[Quantum GF(2)-Additive code over GF(4) of length 6 with 7 generators.\nLower Bound: 1, Upper Bound: 4\nConstructed 2 distinct generator matrices\nTotal Ranks: 4 4 \nRelative Ranks: 4 2 \n(4 4 4 2 )\n(4 4 2 4 )\nTime Taken: 0.00\nStarting search for low weight codewords... (reset timings)\nEnumerating using 1 generator at a time:\n New codeword identified of weight 3, time 0.00\n New codeword identified of weight 2, time 0.00\n Discarding non-contributing rank 2 matrix\n New Total Ranks: 4 \n New Relative Ranks: 4 \n Completed Matrix 1: lower = 2, upper = 2. Elapsed: 0.00s\nComputation complete \nFinal Results: lower = 2, upper = 2,\nTotal CPU time: 0.00, real time: 0.005\n2\n\nTotal time: 0.020 seconds, Total memory usage: 32.09MB\n | O30: ="[["&B30&","&C30&","&D30&"]]" -> [[6,1,2]] | P30: =F30*1 -> 0.23239242 | Q30: =BZMW!F30 -> 0.002468083 | R30: =Q30/P30 -> 0.010620325
A31: [[24,4,0]] | B31: 24 | C31: 4 | D31: 2 | E31: 2 | F31: 0.056989875 | G31: 1 | H31: 1 | I31: Magma V2.28-26 Thu Jan 15 2026 09:06:07 on Marks-MacBook-Air-2 [Seed = \n3048501254]\nType ? for help. Type <Ctrl>-D to quit.\n[[24, 4]] quantum code over GF(2^2), stabilised by:\nQuantum GF(2)-Additive code over GF(4) of length 24 with 28 generators.\nLower Bound: 1, Upper Bound: 11\nConstructed 2 distinct generator matrices\nTotal Ranks: 19 19 \nRelative Ranks: 19 5 \n(4 4 4 4 4 4 4 2 4 2 2 2 4 2 2 2 2 2 2 )\n(4 4 4 4 4 4 2 2 4 4 4 2 2 2 2 2 2 2 2 )\n Discarding non-contributing rank 5 matrix\n New Total Ranks: 19 \n New Relative Ranks: 19 \nTime Taken: 0.00\nStarting search for low weight codewords... (reset timings)\nEnumerating using 1 generator at a time:\n New codeword identified of weight 6, time 0.00\n New codeword identified of weight 3, time 0.00\n New codeword identified of weight 2, time 0.00\n Completed Matrix 1: lower = 2, upper = 2. Elapsed: 0.00s\nComputation complete \nFinal Results: lower = 2, upper = 2,\nTotal CPU time: 0.00, real time: 0.003\n2\n\nTotal time: 0.010 seconds, Total memory usage: 32.09MB\n | O31: ="[["&B31&","&C31&","&D31&"]]" -> [[24,4,2]] | P31: =F31*1 -> 0.056989875 | Q31: =BZMW!F31 -> 0.001391625 | R31: =Q31/P31 -> 0.024418811
A32: [[48,6,0]] | B32: 48 | C32: 6 | D32: 3 | E32: 3 | F32: 0.066720375 | G32: 1 | H32: 1 | I32: Magma V2.28-26 Thu Jan 15 2026 09:06:07 on Marks-MacBook-Air-2 [Seed = \n3014817280]\nType ? for help. Type <Ctrl>-D to quit.\n[[48, 6]] quantum code over GF(2^2), stabilised by:\nQuantum GF(2)-Additive code over GF(4) of length 48 with 54 generators.\nLower Bound: 1, Upper Bound: 22\nConstructed 2 distinct generator matrices\nTotal Ranks: 37 37 \nRelative Ranks: 37 11 \n(4 4 4 4 4 4 4 4 4 2 4 4 4 4 2 2 2 4 4 2 2 4 4 2 2 2 2 2 2 2 2 2 2 2 2 2 2 )\n(4 4 4 4 4 4 4 4 4 4 4 4 2 4 2 4 4 2 4 2 2 2 2 4 2 2 2 2 2 2 2 2 2 2 2 2 2 )\n Discarding non-contributing rank 11 matrix\n New Total Ranks: 37 \n New Relative Ranks: 37 \nTime Taken: 0.01\nStarting search for low weight codewords... (reset timings)\nEnumerating using 1 generator at a time:\n New codeword identified of weight 14, time 0.00\n New codeword identified of weight 5, time 0.00\n Impurity detected of weight 3, time 0.00\n New codeword identified of weight 4, time 0.00\n New codeword identified of weight 3, time 0.00\n Completed Matrix 1: lower = 2, upper = 3. Elapsed: 0.00s\nTermination predicted with 2 generators at matrixEnumerating using 2 generators at a time:\n Completed Matrix 1: lower = 3, upper = 3. Elapsed: 0.00s\nComputation complete \nFinal Results: lower = 3, upper = 3,\nTotal CPU time: 0.00, real time: 0.007\n3\n\nTotal time: 0.030 seconds, Total memory usage: 32.09MB\n | O32: ="[["&B32&","&C32&","&D32&"]]" -> [[48,6,3]] | P32: =F32*1 -> 0.066720375 | Q32: =BZMW!F32 -> 0.00510725 | R32: =Q32/P32 -> 0.076547081
A33: [[84,9,0]] | B33: 84 | C33: 9 | D33: 4 | E33: 4 | F33: 0.090328792 | G33: 1 | H33: 1 | I33: Magma V2.28-26 Thu Jan 15 2026 09:06:07 on Marks-MacBook-Air-2 [Seed = \n1212780026]\nType ? for help. Type <Ctrl>-D to quit.\n[[84, 9]] quantum code over GF(2^2), stabilised by:\nQuantum GF(2)-Additive code over GF(4) of length 84 with 93 generators.\nLower Bound: 1, Upper Bound: 39\nConstructed 2 distinct generator matrices\nTotal Ranks: 64 64 \nRelative Ranks: 64 20 \n(4 4 4 4 4 4 4 4 4 4 4 4 4 4 4 4 4 4 4 4 4 4 2 4 4 4 2 4 4 2 2 4 2 2 2 2 2 2 4 2\n2 2 2 2 2 2 2 2 2 2 2 2 2 2 2 2 2 2 2 2 2 2 2 2 )\n(4 4 4 4 4 4 4 4 4 4 4 4 4 4 4 4 4 4 4 4 4 4 4 4 4 4 2 2 4 2 4 2 2 2 4 2 2 2 2 2\n2 2 2 2 2 2 2 2 2 2 2 2 2 2 2 2 2 2 2 2 2 2 2 2 )\n Discarding non-contributing rank 20 matrix\n New Total Ranks: 64 \n New Relative Ranks: 64 \nTime Taken: 0.01\nStarting search for low weight codewords... (reset timings)\nEnumerating using 1 generator at a time:\n New codeword identified of weight 11, time 0.00\n New codeword identified of weight 6, time 0.00\n New codeword identified of weight 5, time 0.00\n Impurity detected of weight 3, time 0.00\n New codeword identified of weight 4, time 0.00\n Completed Matrix 1: lower = 2, upper = 4. Elapsed: 0.00s\nTermination predicted with 3 generators at matrixEnumerating using 2 generators at a time:\n Completed Matrix 1: lower = 3, upper = 4. Elapsed: 0.00s\nTermination predicted with 3 generators at matrixEnumerating using 3 generators at a time:\n Completed Matrix 1: lower = 4, upper = 4. Elapsed: 0.00s\nComputation complete \nFinal Results: lower = 4, upper = 4,\nTotal CPU time: 0.00, real time: 0.021\n4\n\nTotal time: 0.049 seconds, Total memory usage: 32.09MB\n | O33: ="[["&B33&","&C33&","&D33&"]]" -> [[84,9,4]] | P33: =F33*1 -> 0.090328792 | Q33: =BZMW!F33 -> 0.020930833 | R33: =Q33/P33 -> 0.23171829
A34: [[84,9,0]] | B34: 84 | C34: 9 | D34: 3 | E34: 3 | F34: 0.082497333 | G34: 1 | H34: 1 | I34: Magma V2.28-26 Thu Jan 15 2026 09:06:07 on Marks-MacBook-Air-2 [Seed = \n1179091956]\nType ? for help. Type <Ctrl>-D to quit.\n[[84, 9]] quantum code over GF(2^2), stabilised by:\nQuantum GF(2)-Additive code over GF(4) of length 84 with 93 generators.\nLower Bound: 1, Upper Bound: 39\nConstructed 2 distinct generator matrices\nTotal Ranks: 64 64 \nRelative Ranks: 64 20 \n(4 4 4 4 4 4 4 4 4 4 4 4 4 4 4 4 4 4 4 4 4 4 4 4 4 4 4 4 2 2 2 2 2 2 2 2 2 2 2 4\n2 2 2 2 2 2 2 2 2 2 2 2 2 2 2 2 2 2 2 2 2 2 2 2 )\n(4 4 4 4 4 4 4 4 4 4 4 4 4 4 4 4 4 4 4 4 4 4 4 2 2 4 4 4 2 2 4 4 4 2 2 2 2 2 2 2\n2 2 2 2 2 2 2 2 2 2 2 2 2 2 2 2 2 2 2 2 2 2 2 2 )\n Discarding non-contributing rank 20 matrix\n New Total Ranks: 64 \n New Relative Ranks: 64 \nTime Taken: 0.01\nStarting search for low weight codewords... (reset timings)\nEnumerating using 1 generator at a time:\n New codeword identified of weight 10, time 0.00\n New codeword identified of weight 7, time 0.00\n New codeword identified of weight 4, time 0.00\n Impurity detected of weight 3, time 0.00\n New codeword identified of weight 3, time 0.00\n Completed Matrix 1: lower = 2, upper = 3. Elapsed: 0.00s\nTermination predicted with 2 generators at matrixEnumerating using 2 generators at a time:\n Completed Matrix 1: lower = 3, upper = 3. Elapsed: 0.00s\nComputation complete \nFinal Results: lower = 3, upper = 3,\nTotal CPU time: 0.00, real time: 0.017\n3\n\nTotal time: 0.049 seconds, Total memory usage: 32.09MB\n | O34: ="[["&B34&","&C34&","&D34&"]]" -> [[84,9,3]] | P34: =F34*1 -> 0.082497333 | Q34: =BZMW!F34 -> 0.008438625 | R34: =Q34/P34 -> 0.10228967
A35: [[96,10,0]] | B35: 96 | C35: 10 | D35: 4 | E35: 4 | F35: 0.0984935 | G35: 1 | H35: 1 | I35: Magma V2.28-26 Thu Jan 15 2026 09:06:07 on Marks-MacBook-Air-2 [Seed = \n1549638126]\nType ? for help. Type <Ctrl>-D to quit.\n[[96, 10]] quantum code over GF(2^2), stabilised by:\nQuantum GF(2)-Additive code over GF(4) of length 96 with 106 generators.\nLower Bound: 1, Upper Bound: 44\nConstructed 2 distinct generator matrices\nTotal Ranks: 73 73 \nRelative Ranks: 73 23 \n(4 4 4 4 4 4 4 4 4 4 4 4 2 4 4 4 2 4 4 4 4 4 4 4 4 2 4 4 4 2 2 4 4 4 2 4 2 2 2 2\n2 2 4 4 4 2 2 2 2 2 2 2 2 2 2 2 2 2 2 2 2 2 2 2 2 2 2 2 2 2 2 2 2 )\n(4 4 4 4 4 4 4 4 4 4 4 4 4 4 4 4 4 4 4 4 4 4 4 4 4 4 4 2 2 4 4 4 4 4 2 2 2 2 2 2\n4 2 2 2 2 2 2 2 2 2 2 2 2 2 2 2 2 2 2 2 2 2 2 2 2 2 2 2 2 2 2 2 2 )\n Discarding non-contributing rank 23 matrix\n New Total Ranks: 73 \n New Relative Ranks: 73 \nTime Taken: 0.01\nStarting search for low weight codewords... (reset timings)\nEnumerating using 1 generator at a time:\n New codeword identified of weight 34, time 0.00\n New codeword identified of weight 5, time 0.00\n Impurity detected of weight 3, time 0.00\n New codeword identified of weight 4, time 0.00\n Completed Matrix 1: lower = 2, upper = 4. Elapsed: 0.00s\nTermination predicted with 3 generators at matrixEnumerating using 2 generators at a time:\n Completed Matrix 1: lower = 3, upper = 4. Elapsed: 0.00s\nTermination predicted with 3 generators at matrixEnumerating using 3 generators at a time:\n Completed Matrix 1: lower = 4, upper = 4. Elapsed: 0.01s\nComputation complete \nFinal Results: lower = 4, upper = 4,\nTotal CPU time: 0.01, real time: 0.027\n4\n\nTotal time: 0.060 seconds, Total memory usage: 32.09MB\n | O35: ="[["&B35&","&C35&","&D35&"]]" -> [[96,10,4]] | P35: =F35*1 -> 0.0984935 | Q35: =BZMW!F35 -> 0.029560209 | R35: =Q35/P35 -> 0.30012345
A36: [[168,16,0]] | B36: 168 | C36: 16 | D36: 4 | E36: 4 | F36: 0.21884366701124236 | G36: 1 | H36: 1 | I36: Magma V2.28-26 Thu Jan 15 2026 09:06:07 on Marks-MacBook-Air-2 [Seed = \n1515954152]\nType ? for help. Type <Ctrl>-D to quit.\n[[168, 16]] quantum code over GF(2^2), stabilised by:\nQuantum GF(2)-Additive code over GF(4) of length 168 with 184 generators.\nLower Bound: 1, Upper Bound: 77\nConstructed 2 distinct generator matrices\nTotal Ranks: 127 127 \nRelative Ranks: 127 41 \n(4 4 4 4 4 4 4 4 4 4 4 4 4 4 4 4 4 4 4 4 2 4 4 4 4 4 4 4 4 4 2 4 4 4 4 4 2 4 4 4\n4 4 2 4 4 2 2 4 4 4 2 4 4 2 2 4 4 4 4 4 4 2 4 2 4 2 2 4 2 4 2 2 2 2 4 2 2 2 2 2 \n2 2 2 2 2 2 2 2 2 2 2 2 2 2 2 2 2 2 2 2 2 2 2 2 2 2 2 2 2 2 2 2 2 2 2 2 2 2 2 2 \n2 2 2 2 2 2 2 )\n(4 4 4 4 4 4 4 4 4 4 4 4 4 4 4 4 4 4 4 4 4 4 4 4 4 4 4 4 4 4 4 4 4 4 4 4 4 4 4 4\n4 4 4 4 4 2 4 4 4 4 4 2 4 4 4 2 4 2 2 2 2 2 4 4 2 2 2 2 2 4 2 2 2 2 2 2 2 2 2 2 \n2 2 2 2 2 2 2 2 2 2 2 2 2 2 2 2 2 2 2 2 2 2 2 2 2 2 2 2 2 2 2 2 2 2 2 2 2 2 2 2 \n2 2 2 2 2 2 2 )\n Discarding non-contributing rank 41 matrix\n New Total Ranks: 127 \n New Relative Ranks: 127 \nTime Taken: 0.07\nStarting search for low weight codewords... (reset timings)\nEnumerating using 1 generator at a time:\n Impurity detected of weight 14, time 0.00\n New codeword identified of weight 5, time 0.00\n Impurity detected of weight 3, time 0.00\n New codeword identified of weight 4, time 0.00\n Completed Matrix 1: lower = 2, upper = 4. Elapsed: 0.00s\nTermination predicted with 3 generators at matrixEnumerating using 2 generators at a time:\n Completed Matrix 1: lower = 3, upper = 4. Elapsed: 0.00s\nTermination predicted with 3 generators at matrixEnumerating using 3 generators at a time:\n Completed Matrix 1: lower = 4, upper = 4. Elapsed: 0.03s\nComputation complete \nFinal Results: lower = 4, upper = 4,\nTotal CPU time: 0.03, real time: 0.109\n4\n\nTotal time: 0.169 seconds, Total memory usage: 32.09MB\n | O36: ="[["&B36&","&C36&","&D36&"]]" -> [[168,16,4]] | P36: =F36*1 -> 0.21884367 | Q36: =BZMW!F36 -> 0.18817967 | R36: =Q36/P36 -> 0.85988171
A37: [[168,16,0]] | B37: 168 | C37: 16 | D37: 4 | E37: 4 | F37: 0.20785829 | G37: 1 | H37: 1 | I37: Magma V2.28-26 Thu Jan 15 2026 09:06:07 on Marks-MacBook-Air-2 [Seed = \n1347524066]\nType ? for help. Type <Ctrl>-D to quit.\n[[168, 16]] quantum code over GF(2^2), stabilised by:\nQuantum GF(2)-Additive code over GF(4) of length 168 with 184 generators.\nLower Bound: 1, Upper Bound: 77\nConstructed 2 distinct generator matrices\nTotal Ranks: 127 127 \nRelative Ranks: 127 41 \n(4 4 4 4 4 4 4 4 4 4 4 4 4 4 4 4 4 4 4 4 4 4 4 4 4 4 4 4 4 4 4 4 4 4 4 4 4 2 4 4\n4 4 4 2 4 4 2 4 2 4 4 4 4 2 2 2 4 4 4 4 4 2 2 2 2 2 2 4 2 4 2 2 2 2 2 2 2 2 2 2 \n2 2 2 2 2 4 2 2 2 2 2 2 2 2 2 2 2 2 2 2 2 2 2 2 2 2 2 2 2 2 2 2 2 2 2 2 2 2 2 2 \n2 2 2 2 2 2 2 )\n(4 4 4 4 4 4 4 4 4 4 4 4 4 4 4 4 4 4 4 4 4 4 4 4 4 4 4 4 4 4 4 4 4 4 4 4 4 4 4 4\n4 4 4 4 2 4 2 2 2 4 4 4 4 4 4 4 4 4 4 2 4 2 2 2 2 2 2 2 2 2 2 2 2 2 4 2 2 2 2 2 \n2 2 2 2 2 2 2 2 2 2 2 2 2 2 2 2 2 2 2 2 2 2 2 2 2 2 2 2 2 2 2 2 2 2 2 2 2 2 2 2 \n2 2 2 2 2 2 2 )\n Discarding non-contributing rank 41 matrix\n New Total Ranks: 127 \n New Relative Ranks: 127 \nTime Taken: 0.07\nStarting search for low weight codewords... (reset timings)\nEnumerating using 1 generator at a time:\n New codeword identified of weight 8, time 0.00\n New codeword identified of weight 6, time 0.00\n Impurity detected of weight 3, time 0.00\n New codeword identified of weight 5, time 0.00\n New codeword identified of weight 4, time 0.00\n Completed Matrix 1: lower = 2, upper = 4. Elapsed: 0.00s\nTermination predicted with 3 generators at matrixEnumerating using 2 generators at a time:\n Completed Matrix 1: lower = 3, upper = 4. Elapsed: 0.00s\nTermination predicted with 3 generators at matrixEnumerating using 3 generators at a time:\n Completed Matrix 1: lower = 4, upper = 4. Elapsed: 0.01s\nComputation complete \nFinal Results: lower = 4, upper = 4,\nTotal CPU time: 0.01, real time: 0.101\n4\n\nTotal time: 0.150 seconds, Total memory usage: 32.09MB\n | O37: ="[["&B37&","&C37&","&D37&"]]" -> [[168,16,4]] | P37: =F37*1 -> 0.20785829 | Q37: =BZMW!F37 -> 0.21046837 | R37: =Q37/P37 -> 1.012557
A38: [[180,17,0]] | B38: 180 | C38: 17 | D38: 5 | E38: 5 | F38: 2.162908290978521 | G38: 1 | H38: 1 | I38: Magma V2.28-26 Thu Jan 15 2026 09:06:08 on Marks-MacBook-Air-2 [Seed = \n1852811299]\nType ? for help. Type <Ctrl>-D to quit.\n[[180, 17]] quantum code over GF(2^2), stabilised by:\nQuantum GF(2)-Additive code over GF(4) of length 180 with 197 generators.\nLower Bound: 1, Upper Bound: 83\nConstructed 2 distinct generator matrices\nTotal Ranks: 136 136 \nRelative Ranks: 136 44 \n(4 4 4 4 4 4 4 4 4 4 4 4 4 4 4 4 4 4 4 4 4 4 4 4 4 4 4 4 4 4 4 4 2 4 4 2 4 4 2 4\n4 2 4 4 2 2 2 2 2 2 2 2 2 2 2 2 2 2 2 2 4 4 4 4 4 4 4 4 4 4 4 4 4 2 2 4 2 2 4 2 \n2 4 2 2 4 2 2 2 2 4 2 2 2 2 2 2 2 2 2 2 4 2 2 4 2 2 4 2 2 2 2 2 2 2 2 2 2 2 2 2 \n2 2 2 2 2 2 2 2 2 2 2 2 2 2 2 2 )\n(4 4 4 4 4 4 4 4 4 4 4 4 4 4 4 4 4 4 4 4 4 4 4 4 4 4 4 4 4 4 4 4 4 4 4 4 4 4 4 4\n4 4 4 4 4 4 4 4 4 2 4 2 2 2 2 2 4 4 2 4 2 4 2 4 2 2 2 2 2 4 4 2 4 2 4 2 2 2 2 2 \n2 4 2 2 2 2 2 2 2 2 2 2 2 2 2 2 2 2 2 2 2 2 4 2 2 2 2 2 2 2 2 2 2 2 2 2 2 2 2 2 \n2 2 2 2 2 2 2 2 2 2 2 2 2 2 2 2 )\n Discarding non-contributing rank 44 matrix\n New Total Ranks: 136 \n New Relative Ranks: 136 \nTime Taken: 0.07\nStarting search for low weight codewords... (reset timings)\nEnumerating using 1 generator at a time:\n New codeword identified of weight 20, time 0.00\n New codeword identified of weight 5, time 0.00\n Impurity detected of weight 3, time 0.00\n Completed Matrix 1: lower = 2, upper = 5. Elapsed: 0.00s\nTermination predicted with 4 generators at matrixEnumerating using 2 generators at a time:\n Completed Matrix 1: lower = 3, upper = 5. Elapsed: 0.00s\nTermination predicted with 4 generators at matrixEnumerating using 3 generators at a time:\n Completed Matrix 1: lower = 4, upper = 5. Elapsed: 0.03s\nTermination predicted with 4 generators at matrixEnumerating using 4 generators at a time:\n Completed Matrix 1: lower = 5, upper = 5. Elapsed: 1.96s\nComputation complete \nFinal Results: lower = 5, upper = 5,\nTotal CPU time: 1.96, real time: 2.050\n5\n\nTotal time: 2.100 seconds, Total memory usage: 32.09MB\n | O38: ="[["&B38&","&C38&","&D38&"]]" -> [[180,17,5]] | P38: =F38*1 -> 2.1629083 | Q38: =BZMW!F38 -> 6.8946658 | R38: =Q38/P38 -> 3.1876829
A39: [[252,23,0]] | B39: 252 | C39: 23 | D39: 4 | E39: 4 | F39: 0.47531608401914127 | G39: 1 | H39: 1 | I39: Magma V2.28-26 Thu Jan 15 2026 09:06:10 on Marks-MacBook-Air-2 [Seed = \n1734779176]\nType ? for help. Type <Ctrl>-D to quit.\n[[252, 23]] quantum code over GF(2^2), stabilised by:\nQuantum GF(2)-Additive code over GF(4) of length 252 with 275 generators.\nLower Bound: 1, Upper Bound: 116\nConstructed 2 distinct generator matrices\nTotal Ranks: 190 190 \nRelative Ranks: 190 62 \n(4 4 4 4 4 4 4 4 4 4 4 4 4 4 4 4 4 4 4 4 4 4 4 4 4 4 4 4 4 4 4 4 4 4 4 4 4 4 4 4\n4 4 4 4 4 4 4 4 4 4 4 4 4 4 4 4 4 4 4 4 4 4 4 4 4 4 2 2 2 4 4 4 4 4 4 4 4 4 2 2 \n2 4 4 4 4 4 4 2 2 2 2 2 2 4 2 2 2 2 2 2 2 2 2 2 2 2 2 2 2 2 2 2 2 2 2 2 4 4 4 2 \n2 2 2 2 2 2 2 2 2 2 2 2 2 2 2 2 2 2 2 2 2 2 2 2 2 2 2 2 2 2 2 2 2 2 2 2 2 2 2 2 \n2 2 2 2 2 2 2 2 2 2 2 2 2 2 2 2 2 2 2 2 2 2 2 2 2 2 2 2 2 2 )\n(4 4 4 4 4 4 4 4 4 4 4 4 4 4 4 4 4 4 4 4 4 4 4 4 4 4 4 4 4 4 4 4 4 4 4 4 4 4 4 4\n4 4 4 4 4 4 4 4 4 4 4 4 4 4 4 4 4 4 4 4 4 4 4 4 4 4 4 4 4 4 4 4 4 4 2 4 4 4 2 2 \n2 4 4 2 2 2 4 4 4 2 2 2 4 4 4 2 2 2 2 2 2 2 2 2 2 2 2 2 2 2 2 2 2 2 2 2 2 2 2 2 \n2 2 2 2 2 2 2 2 2 2 2 2 2 2 2 2 2 2 2 2 2 2 2 2 2 2 2 2 2 2 2 2 2 2 2 2 2 2 2 2 \n2 2 2 2 2 2 2 2 2 2 2 2 2 2 2 2 2 2 2 2 2 2 2 2 2 2 2 2 2 2 )\n Discarding non-contributing rank 62 matrix\n New Total Ranks: 190 \n New Relative Ranks: 190 \nTime Taken: 0.21\nStarting search for low weight codewords... (reset timings)\nEnumerating using 1 generator at a time:\n New codeword identified of weight 13, time 0.00\n New codeword identified of weight 6, time 0.00\n New codeword identified of weight 5, time 0.00\n Impurity detected of weight 3, time 0.00\n Completed Matrix 1: lower = 2, upper = 5. Elapsed: 0.00s\nTermination predicted with 4 generators at matrixEnumerating using 2 generators at a time:\n New codeword identified of weight 4, time 0.00\n Completed Matrix 1: lower = 3, upper = 4. Elapsed: 0.00s\nTermination predicted with 3 generators at matrixEnumerating using 3 generators at a time:\n Completed Matrix 1: lower = 4, upper = 4. Elapsed: 0.09s\nComputation complete \nFinal Results: lower = 4, upper = 4,\nTotal CPU time: 0.09, real time: 0.302\n4\n\nTotal time: 0.410 seconds, Total memory usage: 32.09MB\n | O39: ="[["&B39&","&C39&","&D39&"]]" -> [[252,23,4]] | P39: =F39*1 -> 0.47531608 | Q39: =BZMW!F39 -> 0.79571179 | R39: =Q39/P39 -> 1.6740687
A40: [[360,32,0]] | B40: 360 | C40: 32 | D40: 5 | E40: 5 | F40: 51.643607 | G40: 1 | H40: 1 | I40: Magma V2.28-26 Thu Jan 15 2026 09:06:10 on Marks-MacBook-Air-2 [Seed = \n2105326386]\nType ? for help. Type <Ctrl>-D to quit.\n[[360, 32]] quantum code over GF(2^2), stabilised by:\nQuantum GF(2)-Additive code over GF(4) of length 360 with 392 generators.\nLower Bound: 1, Upper Bound: 165\nConstructed 2 distinct generator matrices\nTotal Ranks: 271 271 \nRelative Ranks: 271 89 \n(4 4 4 4 4 4 4 4 4 4 4 4 4 4 4 4 4 4 4 4 4 4 4 4 4 4 4 4 4 4 4 4 4 4 4 4 4 4 4 4\n4 4 4 4 4 4 4 4 4 4 4 4 4 4 4 4 2 4 4 4 4 4 4 4 4 4 4 4 4 4 4 4 4 4 4 4 4 4 4 2 \n2 4 4 4 4 4 4 4 2 2 4 4 4 2 2 2 4 4 4 4 2 4 4 4 4 2 2 4 2 4 2 4 4 4 4 4 4 2 2 2 \n4 4 2 4 4 4 4 2 4 4 2 4 2 2 2 4 2 2 2 4 2 2 2 2 2 2 4 2 2 2 2 2 2 2 2 2 4 2 2 2 \n2 2 2 2 2 4 2 2 2 2 2 2 2 2 2 2 2 4 4 2 2 2 2 2 2 2 2 2 2 2 2 2 2 4 2 2 2 2 2 2 \n2 2 2 2 2 2 2 2 2 2 2 2 2 2 2 2 2 2 2 2 2 2 2 2 2 2 2 2 2 2 2 2 2 2 2 2 2 2 2 2 \n2 2 2 2 2 2 2 2 2 2 2 2 2 2 2 2 2 2 2 2 2 2 2 2 2 2 2 2 2 2 2 )\n(4 4 4 4 4 4 4 4 4 4 4 4 4 4 4 4 4 4 4 4 4 4 4 4 4 4 4 4 4 4 4 4 4 4 4 4 4 4 4 4\n4 4 4 4 4 4 4 4 4 4 4 4 4 4 4 4 4 4 4 4 4 4 4 4 4 4 4 4 4 4 4 4 4 4 4 4 4 4 4 4 \n4 4 4 4 4 4 4 4 4 4 4 2 2 4 2 4 4 4 4 2 4 4 2 2 4 4 4 4 4 4 2 4 4 2 2 4 2 2 2 4 \n4 2 4 2 4 2 4 2 4 2 2 2 4 2 4 4 2 2 2 4 2 2 2 2 2 2 2 2 2 2 4 2 4 2 2 2 2 2 2 2 \n2 2 2 2 2 4 2 2 2 4 2 2 2 2 2 2 2 2 2 2 2 2 2 2 2 2 2 2 2 2 2 2 2 2 2 2 2 2 2 2 \n2 2 2 2 2 2 2 2 2 2 2 2 2 2 2 2 2 2 2 2 2 2 2 2 2 2 2 2 2 2 2 2 2 2 2 2 2 2 2 2 \n2 2 2 2 2 2 2 2 2 2 2 2 2 2 2 2 2 2 2 2 2 2 2 2 2 2 2 2 2 2 2 )\n Discarding non-contributing rank 89 matrix\n New Total Ranks: 271 \n New Relative Ranks: 271 \nTime Taken: 0.57\nStarting search for low weight codewords... (reset timings)\nEnumerating using 1 generator at a time:\n New codeword identified of weight 10, time 0.00\n Impurity detected of weight 4, time 0.00\n Impurity detected of weight 3, time 0.00\n New codeword identified of weight 6, time 0.00\n New codeword identified of weight 5, time 0.01\n Completed Matrix 1: lower = 2, upper = 5. Elapsed: 0.01s\nTermination predicted with 4 generators at matrixEnumerating using 2 generators at a time:\n Completed Matrix 1: lower = 3, upper = 5. Elapsed: 0.01s\nTermination predicted with 4 generators at matrixEnumerating using 3 generators at a time:\n Completed Matrix 1: lower = 4, upper = 5. Elapsed: 0.38s\nTermination predicted at 52 s with 4 generators at matrixEnumerating using 4 generators at a time:\n Completed Matrix 1: lower = 5, upper = 5. Elapsed: 49.64s\nComputation complete \nFinal Results: lower = 5, upper = 5,\nTotal CPU time: 49.65, real time: 51.319\n5\n\nTotal time: 50.440 seconds, Total memory usage: 77.84MB\n | O40: ="[["&B40&","&C40&","&D40&"]]" -> [[360,32,5]] | P40: =F40*1 -> 51.643607 | Q40: =BZMW!F40 -> 188.38387 | R40: =Q40/P40 -> 3.6477675
A41: [[384,34,0]] | B41: 384 | C41: 34 | D41: 4 | E41: 4 | F41: 1.8223190420249011 | G41: 1 | H41: 1 | I41: Magma V2.28-26 Thu Jan 15 2026 09:07:02 on Marks-MacBook-Air-2 [Seed = \n977009729]\nType ? for help. Type <Ctrl>-D to quit.\n[[384, 34]] quantum code over GF(2^2), stabilised by:\nQuantum GF(2)-Additive code over GF(4) of length 384 with 418 generators.\nLower Bound: 1, Upper Bound: 176\nConstructed 2 distinct generator matrices\nTotal Ranks: 289 289 \nRelative Ranks: 289 95 \n(4 4 4 4 4 4 4 4 4 4 4 4 4 4 4 4 4 4 4 4 4 4 4 4 4 4 4 4 4 4 4 4 4 4 4 4 4 4 4 4\n2 4 4 4 4 4 4 4 4 4 2 4 4 4 4 4 4 4 4 4 4 4 4 4 4 2 4 4 4 4 4 4 4 4 4 4 2 4 4 4 \n4 4 2 2 4 4 4 4 4 4 4 4 4 4 4 4 4 2 4 4 4 4 4 2 4 2 4 4 4 4 4 4 4 2 4 4 4 2 4 4 \n4 4 2 4 2 4 2 4 4 2 4 4 2 2 4 2 2 4 2 4 2 2 4 2 2 2 2 4 4 2 2 4 2 2 2 2 2 2 2 4 \n2 2 4 4 2 2 2 2 2 2 2 2 2 2 2 2 2 2 2 2 2 2 2 2 4 2 2 2 2 2 2 2 2 2 2 2 2 2 2 2 \n2 2 2 2 2 2 2 4 2 2 2 2 2 2 2 2 2 2 2 2 2 2 2 2 2 2 2 2 2 2 2 2 2 2 2 2 2 2 2 2 \n2 2 2 2 2 2 2 2 2 2 2 2 2 2 2 2 2 2 2 2 2 2 2 2 2 2 2 2 2 2 2 2 2 2 2 2 2 2 2 2 \n2 2 2 2 2 2 2 2 2 )\n(4 4 4 4 4 4 4 4 4 4 4 4 4 4 4 4 4 4 4 4 4 4 4 4 4 4 4 4 4 4 4 4 4 4 4 4 4 4 4 4\n4 4 4 4 4 4 4 4 4 4 4 4 4 4 4 4 4 4 4 4 4 4 4 4 4 4 4 4 4 4 4 4 4 4 4 4 4 4 4 4 \n4 4 4 4 4 4 4 4 4 4 4 4 4 4 4 4 4 2 4 2 2 4 2 4 4 4 2 4 4 2 4 4 4 4 2 4 2 2 2 4 \n2 2 2 4 2 4 2 2 2 2 2 2 4 4 2 2 4 4 4 2 2 2 4 2 4 2 4 2 2 4 4 2 2 2 4 2 4 4 4 4 \n2 2 2 2 2 2 2 2 2 2 2 2 2 2 2 4 2 2 2 2 2 2 4 2 2 2 2 2 2 2 2 2 2 2 2 2 2 2 2 2 \n2 2 2 2 2 2 2 2 2 2 2 2 2 2 2 2 2 2 2 2 2 2 2 2 2 2 2 2 2 2 2 2 2 2 2 2 2 2 2 2 \n2 2 2 2 2 2 2 2 2 2 2 2 2 2 2 2 2 2 2 2 2 2 2 2 2 2 2 2 2 2 2 2 2 2 2 2 2 2 2 2 \n2 2 2 2 2 2 2 2 2 )\n Discarding non-contributing rank 95 matrix\n New Total Ranks: 289 \n New Relative Ranks: 289 \nTime Taken: 0.74\nStarting search for low weight codewords... (reset timings)\nEnumerating using 1 generator at a time:\n New codeword identified of weight 32, time 0.00\n New codeword identified of weight 28, time 0.00\n New codeword identified of weight 20, time 0.00\n Impurity detected of weight 3, time 0.00\n New codeword identified of weight 12, time 0.00\n New codeword identified of weight 6, time 0.00\n New codeword identified of weight 5, time 0.00\n New codeword identified of weight 4, time 0.00\n Completed Matrix 1: lower = 2, upper = 4. Elapsed: 0.00s\nTermination predicted with 3 generators at matrixEnumerating using 2 generators at a time:\n Completed Matrix 1: lower = 3, upper = 4. Elapsed: 0.01s\nTermination predicted with 3 generators at matrixEnumerating using 3 generators at a time:\n Completed Matrix 1: lower = 4, upper = 4. Elapsed: 0.48s\nComputation complete \nFinal Results: lower = 4, upper = 4,\nTotal CPU time: 0.48, real time: 1.279\n4\n\nTotal time: 1.459 seconds, Total memory usage: 79.72MB\n | O41: ="[["&B41&","&C41&","&D41&"]]" -> [[384,34,4]] | P41: =F41*1 -> 1.822319 | Q41: =BZMW!F41 -> 3.7596173 | R41: =Q41/P41 -> 2.063095
O43: Overall | P43: =SUM(P30:P42) -> 57.158274 | Q43: =SUM(Q30:Q42) -> 200.30041 | R43: =Q43/P43 -> 3.5043117

Sheet BZqubitserf
A1: runMode: serial
A2: maxCount: 10000
A3: repeat: 1
A4: dataset: hyperbolic_surface_code
A5: datafile: RG-3-8.txt
A6: method: qubitserfBZ
A7: ignoreTrivialCodes: 1
A8: resume: 0
A9: nMin: 1
A10: nMax: 100000
A11: iterCount: 10000
A12: maxTime: 28800
... A28: #########################################
A29: name | B29: n | C29: k | D29: d | E29: delta d | F29: Time | G29: R | H29: T | I29: Progress
A30: [[6,1,0]] | B30: 6 | C30: 1 | D30: 2 | E30: 2 | F30: 0.016261833 | G30: 1 | H30: 1
A31: [[24,4,0]] | B31: 24 | C31: 4 | D31: 2 | E31: 2 | F31: 0.009921625 | G31: 1 | H31: 1
A32: [[48,6,0]] | B32: 48 | C32: 6 | D32: 3 | E32: 3 | F32: 0.023522583 | G32: 1 | H32: 1
A33: [[84,9,0]] | B33: 84 | C33: 9 | D33: 4 | E33: 4 | F33: 2.3085713 | G33: 1 | H33: 1
A34: [[84,9,0]] | B34: 84 | C34: 9 | D34: 3 | E34: 3 | F34: 0.34688604 | G34: 1 | H34: 1
A35: [[96,10,0]] | B35: 96 | C35: 10 | D35: 4 | E35: 4 | F35: 4.8447533 | G35: 1 | H35: 1
A36: [[168,16,0]] | B36: 168 | C36: 16 | D36: 4 | E36: 4 | F36: 1372.1519 | G36: 1 | H36: 1
A37: [[168,16,0]] | B37: 168 | C37: 16 | D37: 4 | E37: 4 | F37: 30.303628 | G37: 1 | H37: 1
A38: [[180,17,0]] | B38: 180 | C38: 17 | D38: 5 | E38: 5 | F38: 1583.0654 | G38: 1 | H38: 1
A39: [[252,23,0]] | B39: 252 | C39: 23 | D39: 0 | E39: 0 | F39: 28800.046 | G39: 1 | H39: 1

Sheet MMMW
A1: runMode: serial
A2: maxCount: 10000
A3: repeat: 1
A4: dataset: hyperbolic_surface_code
A5: datafile: RG-3-8.txt
A6: method: MeetMiddleMW
A7: ignoreTrivialCodes: 1
A8: resume: 0
A9: nMin: 1
A10: nMax: 100000
A11: iterCount: 10000
A12: maxTime: 28800
... A28: #########################################
A29: name | B29: n | C29: k | D29: d | E29: delta d | F29: Time | G29: R | H29: T | I29: Progress
A30: [[6,1,0]] | B30: 6 | C30: 1 | D30: 2 | E30: 2 | F30: 0.00010316703 | G30: 1 | H30: 1
A31: [[24,4,0]] | B31: 24 | C31: 4 | D31: 2 | E31: 2 | F31: 0.000302375 | G31: 1 | H31: 1
A32: [[48,6,0]] | B32: 48 | C32: 6 | D32: 3 | E32: 3 | F32: 0.001312167 | G32: 1 | H32: 1
A33: [[84,9,0]] | B33: 84 | C33: 9 | D33: 4 | E33: 4 | F33: 0.081129666 | G33: 1 | H33: 1
A34: [[84,9,0]] | B34: 84 | C34: 9 | D34: 3 | E34: 3 | F34: 0.003699959 | G34: 1 | H34: 1
A35: [[96,10,0]] | B35: 96 | C35: 10 | D35: 4 | E35: 4 | F35: 0.087833625 | G35: 1 | H35: 1
A36: [[168,16,0]] | B36: 168 | C36: 16 | D36: 4 | E36: 4 | F36: 0.52567079 | G36: 1 | H36: 1
A37: [[168,16,0]] | B37: 168 | C37: 16 | D37: 4 | E37: 4 | F37: 0.55925087 | G37: 1 | H37: 1
A38: [[180,17,0]] | B38: 180 | C38: 17 | D38: 5 | E38: 5 | F38: 5.185617 | G38: 1 | H38: 1
A39: [[252,23,0]] | B39: 252 | C39: 23 | D39: 4 | E39: 4 | F39: 2.747183 | G39: 1 | H39: 1
A40: [[360,32,0]] | B40: 360 | C40: 32 | D40: 5 | E40: 5 | F40: 195.11355 | G40: 1 | H40: 1
A41: [[384,34,0]] | B41: 384 | C41: 34 | D41: 4 | E41: 4 | F41: 162.60462 | G41: 1 | H41: 1

Sheet MMqubitserf
A1: runMode: serial
A2: maxCount: 10000
A3: repeat: 1
A4: dataset: hyperbolic_surface_code
A5: datafile: RG-3-8.txt
A6: method: qubitserfMM
A7: ignoreTrivialCodes: 1
A8: resume: 0
A9: nMin: 1
A10: nMax: 100000
A11: iterCount: 10000
A12: maxTime: 28800
... A28: #########################################
A29: name | B29: n | C29: k | D29: d | E29: delta d | F29: Time | G29: R | H29: T | I29: Progress
A30: [[6,1,0]] | B30: 6 | C30: 1 | D30: 2 | E30: 2 | F30: 0.03228575 | G30: 1 | H30: 1
A31: [[24,4,0]] | B31: 24 | C31: 4 | D31: 2 | E31: 2 | F31: 0.015158625 | G31: 1 | H31: 1
A32: [[48,6,0]] | B32: 48 | C32: 6 | D32: 3 | E32: 3 | F32: 0.016607584 | G32: 1 | H32: 1
A33: [[84,9,0]] | B33: 84 | C33: 9 | D33: 4 | E33: 4 | F33: 0.24576271 | G33: 1 | H33: 1
A34: [[84,9,0]] | B34: 84 | C34: 9 | D34: 3 | E34: 3 | F34: 2.8263113 | G34: 1 | H34: 1
A35: [[96,10,0]] | B35: 96 | C35: 10 | D35: 4 | E35: 4 | F35: 21.738639 | G35: 1 | H35: 1

Sheet m4riCC
A1: runMode: serial
A2: maxCount: 10000
A3: dataset: hyperbolic_surface_code
A4: datafile: RG-3-8.txt
A5: method: dist_m4ri_CC
A6: ignoreTrivialCodes: 1
A7: resume: 0
A8: iterCount: 10000
A9: maxTime: 28800
A10: nThreads: 1
A11: verbose: False
A12: maxErr: -1
... A23: #########################################
A24: name | B24: n | C24: k | D24: d | E24: delta d | F24: Time | G24: R | H24: T | I24: Progress
A25: [[6,1,0]] | B25: 6 | C25: 1 | D25: 2 | E25: 2 | F25: 0.028568936 | G25: 1 | H25: 1 | I25: # wmax=99 found cw of weight 2: [0 1]\n2\n
A26: [[24,4,0]] | B26: 24 | C26: 4 | D26: 2 | E26: 2 | F26: 0.03350593 | G26: 1 | H26: 1 | I26: # wmax=99 found cw of weight 2: [0 1]\n2\n
A27: [[48,6,0]] | B27: 48 | C27: 6 | D27: 3 | E27: 3 | F27: 0.037549334 | G27: 1 | H27: 1 | I27: # wmax=99 found cw of weight 3: [0 2 35]\n3\n
A28: [[84,9,0]] | B28: 84 | C28: 9 | D28: 4 | E28: 4 | F28: 0.045564964 | G28: 1 | H28: 1 | I28: # wmax=99 found cw of weight 4: [0 39 73 75]\n4\n
A29: [[84,9,0]] | B29: 84 | C29: 9 | D29: 3 | E29: 3 | F29: 0.050560005 | G29: 1 | H29: 1 | I29: # wmax=99 found cw of weight 3: [0 1 2]\n3\n
A30: [[96,10,0]] | B30: 96 | C30: 10 | D30: 4 | E30: 4 | F30: 0.050963901 | G30: 1 | H30: 1 | I30: # wmax=99 found cw of weight 4: [0 3 22 25]\n4\n
A31: [[168,16,0]] | B31: 168 | C31: 16 | D31: 4 | E31: 4 | F31: 0.054005231 | G31: 1 | H31: 1 | I31: # wmax=99 found cw of weight 4: [0 30 32 48]\n4\n
A32: [[168,16,0]] | B32: 168 | C32: 16 | D32: 4 | E32: 4 | F32: 0.050963958 | G32: 1 | H32: 1 | I32: # wmax=99 found cw of weight 4: [0 26 43 53]\n4\n
A33: [[180,17,0]] | B33: 180 | C33: 17 | D33: 5 | E33: 5 | F33: 0.033827712 | G33: 1 | H33: 1 | I33: # wmax=99 found cw of weight 5: [0 17 35 36 57]\n5\n
A34: [[252,23,0]] | B34: 252 | C34: 23 | D34: 4 | E34: 4 | F34: 0.016204288 | G34: 1 | H34: 1 | I34: # wmax=99 found cw of weight 4: [0 117 219 225]\n4\n
A35: [[360,32,0]] | B35: 360 | C35: 32 | D35: 5 | E35: 5 | F35: 0.019555664 | G35: 1 | H35: 1 | I35: # wmax=99 found cw of weight 5: [0 107 171 177 334]\n5\n
A36: [[384,34,0]] | B36: 384 | C36: 34 | D36: 4 | E36: 4 | F36: 0.018986203 | G36: 1 | H36: 1 | I36: # wmax=99 found cw of weight 4: [0 3 48 181]\n4\n
... A45: [[1224,104,0]] | B45: 1224 | C45: 104 | D45: 6 | E45: 6 | F45: 0.091798936 | G45: 1 | H45: 1 | I45: # wmax=99 found cw of weight 6: [0 202 388 427 514 720]\n6\n

Sheet codetables-GF2
A2: Gray Code | E2: Matrix Method | K2: Magma
A3: [[4, 3, 2]] | B3: 0 | C3: 0.001372917 | D3: Even weight code; Constructing information sets: Block structure [3 1] iter 1: kList optimal; Generating combinations of t=1 rows; Found w:2; Terminating: dU:2 <= dL:2,vCount:3 | E3: [[4, 3, 2]] | F3: 2 | G3: 0.00019250001 | H3: Even weight code; Constructing information sets: Block structure (3, 1) iter 1: kList optimal; Terminating: dU:2 <= dL:2,vCount:0 | I3: =C3-G3 -> 0.001180417 | K3: name | L3: n | M3: k | N3: d | O3: delta d | P3: Time | Q3: R | R3: T | S3: Progress
A4: [[5, 3, 2]] | B4: 0 | C4: 0.00010141601 | D4: Even weight code; Constructing information sets: Block structure [3 1] iter 1: kList optimal; Generating combinations of t=1 rows; Found w:2; Terminating: dU:2 <= dL:2,vCount:3 | E4: [[5, 3, 2]] | F4: 0 | G4: 5.2708987e-05 | H4: Even weight code; Constructing information sets: Block structure (3, 1) iter 1: kList optimal; Generating combinations of t=1 rows; Terminating: dU:2 == dL:2,vCount:3 | I4: =C4-G4 -> 4.8707021e-05 | K4: [[5,3,2]] | L4: 5 | M4: 3 | N4: 2 | O4: 0 | P4: 0.92031004 | Q4: 1 | R4: 1 | S4: Magma V2.28-26 Tue Dec 30 2025 09:50:16 on Marks-MacBook-Air-2 [Seed = \n355458188]\nType ? for help. Type <Ctrl>-D to quit.\n[1 1 0 0 0]\n[1 0 1 0 0]\n[1 0 0 0 1]\nLinear Code over GF(2) of length 5 with 3 generators.\nLower Bound: 1, Upper Bound: 3\nUsing congruence d mod 2 = 0\nConstructed 2 distinct generator matrices\nRelative Ranks: 3 1 \n Discarding non-contributing rank 1 matrix\n New Relative Ranks: 3 \nTime Taken: 0.00\nStarting search for low weight codewords... (reset timings)\nEnumerating using 1 generator at a time:\n New codeword identified of weight 2, time 0.00\nComputation complete 0 vectors enumerated in total\n (0.000000% of 5 3 code)\nFinal Results: lower = 2, upper = 2,\nTotal CPU time: 0.00, real time: 0.003\n[5, 3, 2] Linear Code over GF(2)\nGenerator matrix:\n[1 0 0 0 1]\n[0 1 0 0 1]\n[0 0 1 0 1]\nLinear Code over GF(2) of length 5 with 3 generators.\nLower Bound: 1, Upper Bound: 3\nUsing congruence d mod 2 = 0\nConstructed 2 distinct generator matrices\nRelative Ranks: 3 1 \n Discarding non-contributing rank 1 matrix\n New Relative Ranks: 3 \nTime Taken: 0.00\nStarting search for low weight codewords... (reset timings)\nEnumerating using 1 generator at a time:\n New codeword identified of weight 2, time 0.00\nComputation complete 0 vectors enumerated in total\n (0.000000% of 5 3 code)\nFinal Results: lower = 2, upper = 2,\nTotal CPU time: 0.00, real time: 0.000\n2\n\nTotal time: 0.010 seconds, Total memory usage: 32.09MB\n
A5: [[6, 3, 3]] | B5: 0 | C5: 9.2916991e-05 | D5: Constructing information sets: Block structure [3 3] iter 1: kList optimal; Generating combinations of t=1 rows; Found w:3; Completed matrix 0,dU:3,dL:2,vCount:3; Completed matrix 1,dU:3,dL:4,vCount:6; Terminating: dU:3 <= dL:4,vCount:6 | E5: [[6, 3, 3]] | F5: 0 | G5: 4.8665999e-05 | H5: Constructing information sets: Block structure (3, 3) iter 1: kList optimal; Generating combinations of t=1 rows; Completed matrix 0,dU:3,dL:2,vCount:3; Completed matrix 1,dU:3,dL:2,vCount:6; tMax:2; Terminating: dU:3 <= dL:4,vCount:6 | I5: =C5-G5 -> 4.4250992e-05 | K5: [[6,3,3]] | L5: 6 | M5: 3 | N5: 3 | O5: 0 | P5: 0.059132041 | Q5: 1 | R5: 1 | S5: Magma V2.28-26 Tue Dec 30 2025 09:50:16 on Marks-MacBook-Air-2 [Seed = \n438358915]\nType ? for help. Type <Ctrl>-D to quit.\n[1 1 1 1 0 0]\n[1 0 1 0 1 0]\n[0 1 1 0 0 1]\nLinear Code over GF(2) of length 6 with 3 generators.\nLower Bound: 1, Upper Bound: 4\nConstructed 2 distinct generator matrices\nRelative Ranks: 3 3 \nTime Taken: 0.00\nStarting search for low weight codewords... (reset timings)\nEnumerating using 1 generator at a time:\n New codeword identified of weight 3, time 0.00\n Completed Matrix 1: lower = 3, upper = 3. Elapsed: 0.00s\nComputation complete 3 vectors enumerated in total\n (37.500000% of 6 3 code)\nFinal Results: lower = 3, upper = 3,\nTotal CPU time: 0.00, real time: 0.001\n[6, 3, 3] Linear Code over GF(2)\nGenerator matrix:\n[1 0 0 1 0 1]\n[0 1 0 1 1 0]\n[0 0 1 1 1 1]\nLinear Code over GF(2) of length 6 with 3 generators.\nLower Bound: 1, Upper Bound: 4\nConstructed 2 distinct generator matrices\nRelative Ranks: 3 3 \nTime Taken: 0.00\nStarting search for low weight codewords... (reset timings)\nEnumerating using 1 generator at a time:\n New codeword identified of weight 3, time 0.00\n Completed Matrix 1: lower = 3, upper = 3. Elapsed: 0.00s\nComputation complete 3 vectors enumerated in total\n (37.500000% of 6 3 code)\nFinal Results: lower = 3, upper = 3,\nTotal CPU time: 0.00, real time: 0.000\n3\n\nTotal time: 0.010 seconds, Total memory usage: 32.09MB\n
A6: [[7, 3, 4]] | B6: 0 | C6: 8.8083005e-05 | D6: Even weight code; Constructing information sets: Block structure [3 3 1] iter 1: kList optimal; Generating combinations of t=1 rows; Found w:4; Completed matrix 0,dU:4,dL:2,vCount:3; Completed matrix 1,dU:4,dL:4,vCount:6; Terminating: dU:4 <= dL:4,vCount:6 | E6: [[7, 3, 4]] | F6: 0 | G6: 4.6959001e-05 | H6: Even weight code; Constructing information sets: Block structure (3, 3, 1) iter 1: kList optimal; Generating combinations of t=1 rows; Completed matrix 0,dU:4,dL:2,vCount:3; Completed matrix 1,dU:4,dL:2,vCount:6; Completed matrix 2,dU:4,dL:2,vCount:9; tMax:2; Terminating: dU:4 <= dL:4,vCount:9 | I6: =C6-G6 -> 4.1124003e-05 | K6: [[7,3,4]] | L6: 7 | M6: 3 | N6: 4 | O6: 0 | P6: 0.059731417 | Q6: 1 | R6: 1 | S6: Magma V2.28-26 Tue Dec 30 2025 09:50:16 on Marks-MacBook-Air-2 [Seed = \n538634681]\nType ? for help. Type <Ctrl>-D to quit.\n[0 1 1 1 1 0 0]\n[1 0 1 1 0 1 0]\n[1 1 0 1 0 0 1]\nLinear Code over GF(2) of length 7 with 3 generators.\nLower Bound: 1, Upper Bound: 5\nUsing congruence d mod 4 = 0\nConstructed 3 distinct generator matrices\nRelative Ranks: 3 3 1 \n Discarding non-contributing rank 1 matrix\n New Relative Ranks: 3 3 \nTime Taken: 0.00\nStarting search for low weight codewords... (reset timings)\nEnumerating using 1 generator at a time:\n New codeword identified of weight 4, time 0.00\nComputation complete 0 vectors enumerated in total\n (0.000000% of 7 3 code)\nFinal Results: lower = 4, upper = 4,\nTotal CPU time: 0.00, real time: 0.001\n[7, 3, 4] Linear Code over GF(2)\nGenerator matrix:\n[1 0 1 0 1 0 1]\n[0 1 1 0 0 1 1]\n[0 0 0 1 1 1 1]\nLinear Code over GF(2) of length 7 with 3 generators.\nLower Bound: 1, Upper Bound: 5\nUsing congruence d mod 4 = 0\nConstructed 3 distinct generator matrices\nRelative Ranks: 3 3 1 \n Discarding non-contributing rank 1 matrix\n New Relative Ranks: 3 3 \nTime Taken: 0.00\nStarting search for low weight codewords... (reset timings)\nEnumerating using 1 generator at a time:\n New codeword identified of weight 4, time 0.00\nComputation complete 0 vectors enumerated in total\n (0.000000% of 7 3 code)\nFinal Results: lower = 4, upper = 4,\nTotal CPU time: 0.00, real time: 0.000\n4\n\nTotal time: 0.019 seconds, Total memory usage: 32.09MB\n
A7: [[8, 3, 4]] | B7: 0 | C7: 8.3250008e-05 | D7: Even weight code; Constructing information sets: Block structure [3 3 1] iter 1: kList optimal; Generating combinations of t=1 rows; Found w:4; Completed matrix 0,dU:4,dL:2,vCount:3; Completed matrix 1,dU:4,dL:4,vCount:6; Terminating: dU:4 <= dL:4,vCount:6 | E7: [[8, 3, 4]] | F7: 0 | G7: 5.0208007e-05 | H7: Even weight code; Constructing information sets: Block structure (3, 3, 1) iter 1: kList optimal; Generating combinations of t=1 rows; Completed matrix 0,dU:4,dL:2,vCount:3; Completed matrix 1,dU:4,dL:2,vCount:6; Completed matrix 2,dU:4,dL:2,vCount:9; tMax:2; Terminating: dU:4 <= dL:4,vCount:9 | I7: =C7-G7 -> 3.3042001e-05 | K7: [[8,3,4]] | L7: 8 | M7: 3 | N7: 4 | O7: 0 | P7: 0.061138917 | Q7: 1 | R7: 1 | S7: Magma V2.28-26 Tue Dec 30 2025 09:50:16 on Marks-MacBook-Air-2 [Seed = \n639430591]\nType ? for help. Type <Ctrl>-D to quit.\n[1 1 1 1 0 0 0 0]\n[0 1 1 0 0 1 1 0]\n[1 0 1 0 0 1 0 1]\nLinear Code over GF(2) of length 8 with 3 generators.\nLower Bound: 1, Upper Bound: 6\nUsing congruence d mod 4 = 0\nConstructed 3 distinct generator matrices\nRelative Ranks: 3 3 1 \n Discarding non-contributing rank 1 matrix\n New Relative Ranks: 3 3 \nTime Taken: 0.00\nStarting search for low weight codewords... (reset timings)\nEnumerating using 1 generator at a time:\n New codeword identified of weight 4, time 0.00\nComputation complete 0 vectors enumerated in total\n (0.000000% of 8 3 code)\nFinal Results: lower = 4, upper = 4,\nTotal CPU time: 0.00, real time: 0.001\n[8, 3, 4] Linear Code over GF(2)\nGenerator matrix:\n[1 0 0 1 0 1 1 0]\n[0 1 0 1 0 1 0 1]\n[0 0 1 1 0 0 1 1]\nLinear Code over GF(2) of length 8 with 3 generators.\nLower Bound: 1, Upper Bound: 6\nUsing congruence d mod 4 = 0\nConstructed 3 distinct generator matrices\nRelative Ranks: 3 3 1 \n Discarding non-contributing rank 1 matrix\n New Relative Ranks: 3 3 \nTime Taken: 0.00\nStarting search for low weight codewords... (reset timings)\nEnumerating using 1 generator at a time:\n New codeword identified of weight 4, time 0.00\nComputation complete 0 vectors enumerated in total\n (0.000000% of 8 3 code)\nFinal Results: lower = 4, upper = 4,\nTotal CPU time: 0.00, real time: 0.000\n4\n\nTotal time: 0.019 seconds, Total memory usage: 32.09MB\n
A8: [[9, 5, 3]] | B8: 0 | C8: 8.0124999e-05 | D8: Constructing information sets: Block structure [5 4] iter 1: kList optimal; Generating combinations of t=1 rows; Found w:4; Completed matrix 0,dU:4,dL:2,vCount:5; Found w:3; Completed matrix 1,dU:3,dL:3,vCount:10; Terminating: dU:3 <= dL:3,vCount:10 | E8: [[9, 5, 3]] | F8: 0 | G8: 4.2625004e-05 | H8: Constructing information sets: Block structure (5, 4) iter 1: kList optimal; Generating combinations of t=1 rows; Completed matrix 0,dU:4,dL:1,vCount:5; Completed matrix 1,dU:3,dL:1,vCount:10; tMax:2; Terminating: dU:3 <= dL:3,vCount:10 | I8: =C8-G8 -> 3.7499995e-05 | K8: [[9,5,3]] | L8: 9 | M8: 5 | N8: 3 | O8: 0 | P8: 0.058100541 | Q8: 1 | R8: 1 | S8: Magma V2.28-26 Tue Dec 30 2025 09:50:16 on Marks-MacBook-Air-2 [Seed = \n739698101]\nType ? for help. Type <Ctrl>-D to quit.\n[0 1 1 1 1 0 0 0 0]\n[1 1 1 1 0 1 0 0 0]\n[1 0 0 1 0 0 1 0 0]\n[1 0 1 0 0 0 0 1 0]\n[1 1 0 0 0 0 0 0 1]\nLinear Code over GF(2) of length 9 with 5 generators.\nLower Bound: 1, Upper Bound: 5\nConstructed 2 distinct generator matrices\nRelative Ranks: 5 4 \nTime Taken: 0.00\nStarting search for low weight codewords... (reset timings)\nEnumerating using 1 generator at a time:\n New codeword identified of weight 4, time 0.00\n Completed Matrix 1: lower = 2, upper = 4. Elapsed: 0.00s\n Completed Matrix 2: lower = 3, upper = 4. Elapsed: 0.00s\nTermination predicted with 2 generators at matrix 1\nEnumerating using 2 generators at a time:\n New codeword identified of weight 3, time 0.00\nComputation complete 10 vectors enumerated in total\n (31.250000% of 9 5 code)\nFinal Results: lower = 3, upper = 3,\nTotal CPU time: 0.00, real time: 0.001\n[9, 5, 3] Linear Code over GF(2)\nGenerator matrix:\n[1 0 0 0 1 0 1 1 1]\n[0 1 0 0 1 0 1 1 0]\n[0 0 1 0 1 0 1 0 1]\n[0 0 0 1 1 0 0 1 1]\n[0 0 0 0 0 1 1 1 1]\nLinear Code over GF(2) of length 9 with 5 generators.\nLower Bound: 1, Upper Bound: 5\nConstructed 2 distinct generator matrices\nRelative Ranks: 5 4 \nTime Taken: 0.00\nStarting search for low weight codewords... (reset timings)\nEnumerating using 1 generator at a time:\n New codeword identified of weight 4, time 0.00\n Completed Matrix 1: lower = 2, upper = 4. Elapsed: 0.00s\n Completed Matrix 2: lower = 3, upper = 4. Elapsed: 0.00s\nTermination predicted with 2 generators at matrix 1\nEnumerating using 2 generators at a time:\n New codeword identified of weight 3, time 0.00\nComputation complete 10 vectors enumerated in total\n (31.250000% of 9 5 code)\nFinal Results: lower = 3, upper = 3,\nTotal CPU time: 0.00, real time: 0.000\n3\n\nTotal time: 0.010 seconds, Total memory usage: 32.09MB\n
A9: [[10, 3, 5]] | B9: 0 | C9: 9.2749993e-05 | D9: Constructing information sets: Block structure [3 3 3 1] iter 1: kList optimal; Generating combinations of t=1 rows; Found w:5; Completed matrix 0,dU:5,dL:2,vCount:3; Completed matrix 1,dU:5,dL:4,vCount:6; Completed matrix 2,dU:5,dL:6,vCount:9; Terminating: dU:5 <= dL:6,vCount:9 | E9: [[10, 3, 5]] | F9: 0 | G9: 7.2833005e-05 | H9: Constructing information sets: Block structure (3, 3, 3, 1) iter 1: kList optimal; Generating combinations of t=1 rows; Completed matrix 0,dU:5,dL:3,vCount:3; Completed matrix 1,dU:5,dL:3,vCount:6; Completed matrix 2,dU:5,dL:3,vCount:9; Completed matrix 3,dU:5,dL:3,vCount:12; tMax:2; Terminating: dU:5 <= dL:6,vCount:12 | I9: =C9-G9 -> 1.9916988e-05 | K9: [[10,3,5]] | L9: 10 | M9: 3 | N9: 5 | O9: 0 | P9: 0.054936 | Q9: 1 | R9: 1 | S9: Magma V2.28-26 Tue Dec 30 2025 09:50:16 on Marks-MacBook-Air-2 [Seed = \n839449515]\nType ? for help. Type <Ctrl>-D to quit.\n[0 0 1 1 1 1 1 1 0 0]\n[0 1 0 1 1 0 1 0 1 0]\n[1 0 0 1 0 1 1 0 0 1]\nLinear Code over GF(2) of length 10 with 3 generators.\nLower Bound: 1, Upper Bound: 8\nConstructed 4 distinct generator matrices\nRelative Ranks: 3 3 3 1 \n Discarding non-contributing rank 1 matrix\n New Relative Ranks: 3 3 3 \nTime Taken: 0.00\nStarting search for low weight codewords... (reset timings)\nEnumerating using 1 generator at a time:\n New codeword identified of weight 5, time 0.00\n Completed Matrix 1: lower = 4, upper = 5. Elapsed: 0.00s\n Completed Matrix 2: lower = 5, upper = 5. Elapsed: 0.00s\nComputation complete 6 vectors enumerated in total\n (75.000000% of 10 3 code)\nFinal Results: lower = 5, upper = 5,\nTotal CPU time: 0.00, real time: 0.001\n[10, 3, 5] Linear Code over GF(2)\nGenerator matrix:\n[1 0 0 1 0 1 1 0 0 1]\n[0 1 0 1 1 0 1 0 1 0]\n[0 0 1 1 1 1 1 1 0 0]\nLinear Code over GF(2) of length 10 with 3 generators.\nLower Bound: 1, Upper Bound: 8\nConstructed 4 distinct generator matrices\nRelative Ranks: 3 3 3 1 \n Discarding non-contributing rank 1 matrix\n New Relative Ranks: 3 3 3 \nTime Taken: 0.00\nStarting search for low weight codewords... (reset timings)\nEnumerating using 1 generator at a time:\n New codeword identified of weight 5, time 0.00\n Completed Matrix 1: lower = 4, upper = 5. Elapsed: 0.00s\n Completed Matrix 2: lower = 5, upper = 5. Elapsed: 0.00s\nComputation complete 6 vectors enumerated in total\n (75.000000% of 10 3 code)\nFinal Results: lower = 5, upper = 5,\nTotal CPU time: 0.00, real time: 0.000\n5\n\nTotal time: 0.010 seconds, Total memory usage: 32.09MB\n
A10: [[11, 3, 6]] | B10: 0 | C10: 9.5833995e-05 | D10: Even weight code; Constructing information sets: Block structure [3 3 3 2] iter 1: kList optimal; Generating combinations of t=1 rows; Found w:6; Completed matrix 0,dU:6,dL:2,vCount:3; Completed matrix 1,dU:6,dL:4,vCount:6; Completed matrix 2,dU:6,dL:6,vCount:9; Terminating: dU:6 <= dL:6,vCount:9 | E10: [[11, 3, 6]] | F10: 0 | G10: 6.9249974e-05 | H10: Even weight code; Constructing information sets: Block structure (3, 3, 3, 2) iter 1: kList optimal; Generating combinations of t=1 rows; Completed matrix 0,dU:6,dL:4,vCount:3; Completed matrix 1,dU:6,dL:4,vCount:6; Completed matrix 2,dU:6,dL:4,vCount:9; Completed matrix 3,dU:6,dL:4,vCount:12; tMax:2; Terminating: dU:6 <= dL:8,vCount:12 | I10: =C10-G10 -> 2.6584021e-05 | K10: [[11,3,6]] | L10: 11 | M10: 3 | N10: 6 | O10: 0 | P10: 0.058254709 | Q10: 1 | R10: 1 | S10: Magma V2.28-26 Tue Dec 30 2025 09:50:16 on Marks-MacBook-Air-2 [Seed = \n939717025]\nType ? for help. Type <Ctrl>-D to quit.\n[0 0 1 1 1 1 1 1 0 0 0]\n[1 1 0 0 1 1 0 0 1 1 0]\n[1 0 1 0 1 0 1 0 1 0 1]\nLinear Code over GF(2) of length 11 with 3 generators.\nLower Bound: 1, Upper Bound: 9\nUsing congruence d mod 2 = 0\nConstructed 4 distinct generator matrices\nRelative Ranks: 3 3 3 2 \nTime Taken: 0.00\nStarting search for low weight codewords... (reset timings)\nEnumerating using 1 generator at a time:\n New codeword identified of weight 6, time 0.00\n Completed Matrix 1: lower = 4, upper = 6. Elapsed: 0.00s\n Completed Matrix 2: lower = 6, upper = 6. Elapsed: 0.00s\nComputation complete 6 vectors enumerated in total\n (75.000000% of 11 3 code)\nFinal Results: lower = 6, upper = 6,\nTotal CPU time: 0.00, real time: 0.001\n[11, 3, 6] Linear Code over GF(2)\nGenerator matrix:\n[1 0 0 1 0 1 0 1 1 0 1]\n[0 1 0 1 1 0 0 1 0 1 1]\n[0 0 1 1 1 1 1 1 0 0 0]\nLinear Code over GF(2) of length 11 with 3 generators.\nLower Bound: 1, Upper Bound: 9\nUsing congruence d mod 2 = 0\nConstructed 4 distinct generator matrices\nRelative Ranks: 3 3 3 2 \nTime Taken: 0.00\nStarting search for low weight codewords... (reset timings)\nEnumerating using 1 generator at a time:\n New codeword identified of weight 6, time 0.00\n Completed Matrix 1: lower = 4, upper = 6. Elapsed: 0.00s\n Completed Matrix 2: lower = 6, upper = 6. Elapsed: 0.00s\nComputation complete 6 vectors enumerated in total\n (75.000000% of 11 3 code)\nFinal Results: lower = 6, upper = 6,\nTotal CPU time: 0.00, real time: 0.000\n6\n\nTotal time: 0.010 seconds, Total memory usage: 32.09MB\n
